<mujoco model="g1_29dof_inspire_hand">
  <!--
    Unitree G1 (29 DOF body) with Inspire Hands (6 actuated DOF per hand).
    Inspire hand meshes from: https://github.com/dexsuite/dex-urdf
    Mimic joints are handled via MuJoCo equality constraints.

    Hand attachment frame (both sides):
      euler="0 0 1.5708" places hand so fingers point along wrist +X (forward).
      Adjust wrist_roll/pitch/yaw to orient palm as desired.
  -->
  <compiler angle="radian" meshdir="meshes" />

  <default>
    <default class="torso_motor">
      <joint damping="0.05" armature="0.01" frictionloss="0.2"/>
    </default>
    <default class="leg_motor">
      <joint damping="0.05" armature="0.01" frictionloss="0.2"/>
    </default>
    <default class="ankle_motor">
      <joint damping="0.05" armature="0.01" frictionloss="0.2"/>
    </default>
    <default class="arm_motor">
      <joint damping="0.05" armature="0.01" frictionloss="0.2"/>
    </default>
    <default class="wrist_motor">
      <joint damping="0.05" armature="0.01" frictionloss="0.1"/>
    </default>
    <default class="finger_motor">
      <joint damping="0.02" armature="0.005" frictionloss="0.05"/>
    </default>
  </default>

  <asset>
    <!-- G1 body meshes -->
    <mesh name="pelvis" file="pelvis.STL" />
    <mesh name="pelvis_contour_link" file="pelvis_contour_link.STL" />
    <mesh name="left_hip_pitch_link" file="left_hip_pitch_link.STL" />
    <mesh name="left_hip_roll_link" file="left_hip_roll_link.STL" />
    <mesh name="left_hip_yaw_link" file="left_hip_yaw_link.STL" />
    <mesh name="left_knee_link" file="left_knee_link.STL" />
    <mesh name="left_ankle_pitch_link" file="left_ankle_pitch_link.STL" />
    <mesh name="left_ankle_roll_link" file="left_ankle_roll_link.STL" />
    <mesh name="right_hip_pitch_link" file="right_hip_pitch_link.STL" />
    <mesh name="right_hip_roll_link" file="right_hip_roll_link.STL" />
    <mesh name="right_hip_yaw_link" file="right_hip_yaw_link.STL" />
    <mesh name="right_knee_link" file="right_knee_link.STL" />
    <mesh name="right_ankle_pitch_link" file="right_ankle_pitch_link.STL" />
    <mesh name="right_ankle_roll_link" file="right_ankle_roll_link.STL" />
    <mesh name="waist_yaw_link" file="waist_yaw_link.STL" />
    <mesh name="waist_roll_link" file="waist_roll_link.STL" />
    <mesh name="torso_link" file="torso_link.STL" />
    <mesh name="logo_link" file="logo_link.STL" />
    <mesh name="head_link" file="head_link.STL" />
    <mesh name="waist_support_link" file="waist_support_link.STL" />
    <mesh name="left_shoulder_pitch_link" file="left_shoulder_pitch_link.STL" />
    <mesh name="left_shoulder_roll_link" file="left_shoulder_roll_link.STL" />
    <mesh name="left_shoulder_yaw_link" file="left_shoulder_yaw_link.STL" />
    <mesh name="left_elbow_link" file="left_elbow_link.STL" />
    <mesh name="left_wrist_roll_link" file="left_wrist_roll_link.STL" />
    <mesh name="left_wrist_pitch_link" file="left_wrist_pitch_link.STL" />
    <mesh name="left_wrist_yaw_link" file="left_wrist_yaw_link.STL" />
    <mesh name="right_shoulder_pitch_link" file="right_shoulder_pitch_link.STL" />
    <mesh name="right_shoulder_roll_link" file="right_shoulder_roll_link.STL" />
    <mesh name="right_shoulder_yaw_link" file="right_shoulder_yaw_link.STL" />
    <mesh name="right_elbow_link" file="right_elbow_link.STL" />
    <mesh name="right_wrist_roll_link" file="right_wrist_roll_link.STL" />
    <mesh name="right_wrist_pitch_link" file="right_wrist_pitch_link.STL" />
    <mesh name="right_wrist_yaw_link" file="right_wrist_yaw_link.STL" />

    <!-- === Inspire Hand meshes (visual=GLB, collision=OBJ) === -->
    <!-- Right hand visual meshes -->
    <mesh name="r_ih_right_base_link"           file="../inspire_hand_meshes/visual/right_base_link.obj"/>
    <mesh name="r_ih_right_thumb_proximal_base" file="../inspire_hand_meshes/visual/right_thumb_proximal_base.obj"/>
    <mesh name="r_ih_right_thumb_proximal"      file="../inspire_hand_meshes/visual/right_thumb_proximal.obj"/>
    <mesh name="r_ih_right_thumb_intermediate"  file="../inspire_hand_meshes/visual/right_thumb_intermediate.obj"/>
    <mesh name="r_ih_right_thumb_distal"        file="../inspire_hand_meshes/visual/right_thumb_distal.obj"/>
    <mesh name="r_ih_right_index_proximal"      file="../inspire_hand_meshes/visual/right_index_proximal.obj"/>
    <mesh name="r_ih_right_index_intermediate"  file="../inspire_hand_meshes/visual/right_index_intermediate.obj"/>
    <mesh name="r_ih_right_middle_intermediate" file="../inspire_hand_meshes/visual/right_middle_intermediate.obj"/>
    <mesh name="r_ih_right_pinky_intermediate"  file="../inspire_hand_meshes/visual/right_pinky_intermediate.obj"/>
    <!-- Right hand collision meshes -->
    <mesh name="r_ih_c_right_thumb_proximal_base" file="../inspire_hand_meshes/collision/right_thumb_proximal_base.obj"/>
    <mesh name="r_ih_c_right_thumb_proximal"      file="../inspire_hand_meshes/collision/right_thumb_proximal.obj"/>
    <mesh name="r_ih_c_right_thumb_intermediate"  file="../inspire_hand_meshes/collision/right_thumb_intermediate.obj"/>
    <mesh name="r_ih_c_right_thumb_distal"        file="../inspire_hand_meshes/collision/right_thumb_distal.obj"/>
    <mesh name="r_ih_c_right_index_proximal"      file="../inspire_hand_meshes/collision/right_index_proximal.obj"/>
    <mesh name="r_ih_c_right_index_intermediate"  file="../inspire_hand_meshes/collision/right_index_intermediate.obj"/>
    <mesh name="r_ih_c_right_middle_intermediate" file="../inspire_hand_meshes/collision/right_middle_intermediate.obj"/>
    <mesh name="r_ih_c_right_pinky_intermediate"  file="../inspire_hand_meshes/collision/right_pinky_intermediate.obj"/>

    <!-- Left hand visual meshes -->
    <mesh name="l_ih_left_base_link"           file="../inspire_hand_meshes/visual/left_base_link.obj"/>
    <mesh name="l_ih_left_thumb_proximal_base" file="../inspire_hand_meshes/visual/left_thumb_proximal_base.obj"/>
    <mesh name="l_ih_left_thumb_proximal"      file="../inspire_hand_meshes/visual/left_thumb_proximal.obj"/>
    <mesh name="l_ih_left_thumb_intermediate"  file="../inspire_hand_meshes/visual/left_thumb_intermediate.obj"/>
    <mesh name="l_ih_left_thumb_distal"        file="../inspire_hand_meshes/visual/left_thumb_distal.obj"/>
    <mesh name="l_ih_left_index_proximal"      file="../inspire_hand_meshes/visual/left_index_proximal.obj"/>
    <mesh name="l_ih_left_index_intermediate"  file="../inspire_hand_meshes/visual/left_index_intermediate.obj"/>
    <mesh name="l_ih_left_middle_intermediate" file="../inspire_hand_meshes/visual/left_middle_intermediate.obj"/>
    <mesh name="l_ih_left_pinky_intermediate"  file="../inspire_hand_meshes/visual/left_pinky_intermediate.obj"/>
    <!-- Left hand collision meshes -->
    <mesh name="l_ih_c_left_thumb_proximal_base" file="../inspire_hand_meshes/collision/left_thumb_proximal_base.obj"/>
    <mesh name="l_ih_c_left_thumb_proximal"      file="../inspire_hand_meshes/collision/left_thumb_proximal.obj"/>
    <mesh name="l_ih_c_left_thumb_intermediate"  file="../inspire_hand_meshes/collision/left_thumb_intermediate.obj"/>
    <mesh name="l_ih_c_left_thumb_distal"        file="../inspire_hand_meshes/collision/left_thumb_distal.obj"/>
    <mesh name="l_ih_c_left_index_proximal"      file="../inspire_hand_meshes/collision/left_index_proximal.obj"/>
    <mesh name="l_ih_c_left_index_intermediate"  file="../inspire_hand_meshes/collision/left_index_intermediate.obj"/>
    <mesh name="l_ih_c_left_middle_intermediate" file="../inspire_hand_meshes/collision/left_middle_intermediate.obj"/>
    <mesh name="l_ih_c_left_pinky_intermediate"  file="../inspire_hand_meshes/collision/left_pinky_intermediate.obj"/>
  </asset>

  <worldbody>
    <body name="pelvis" pos="0 0 0.793">
      <inertial pos="0 0 -0.07605" quat="1 0 -0.000399148 0" mass="3.813"
        diaginertia="0.010549 0.0093089 0.0079184" />
      <joint name="floating_base_joint" type="free" limited="false" actuatorfrclimited="false" />
      <geom type="mesh" contype="0" conaffinity="0" group="1" density="0" rgba="0.2 0.2 0.2 1"
        mesh="pelvis" />
      <geom type="mesh" contype="0" conaffinity="0" group="1" density="0" rgba="0.7 0.7 0.7 1"
        mesh="pelvis_contour_link" />
      <geom type="mesh" rgba="0.7 0.7 0.7 1" mesh="pelvis_contour_link" />
      <body name="left_hip_pitch_link" pos="0 0.064452 -0.1027">
        <inertial pos="0.002741 0.047791 -0.02606" quat="0.954862 0.293964 0.0302556 0.030122"
          mass="1.35" diaginertia="0.00181517 0.00153422 0.00116212" />
        <joint name="left_hip_pitch_joint" pos="0 0 0" axis="0 1 0" range="-2.5307 2.8798"
          actuatorfrcrange="-88 88" class="leg_motor" />
        <geom type="mesh" contype="0" conaffinity="0" group="1" density="0" rgba="0.2 0.2 0.2 1"
          mesh="left_hip_pitch_link" />
        <geom type="mesh" rgba="0.2 0.2 0.2 1" mesh="left_hip_pitch_link" />
        <body name="left_hip_roll_link" pos="0 0.052 -0.030465" quat="0.996179 0 -0.0873386 0">
          <inertial pos="0.029812 -0.001045 -0.087934"
            quat="0.977808 -1.97119e-05 0.205576 -0.0403793" mass="1.52"
            diaginertia="0.00254986 0.00241169 0.00148755" />
          <joint name="left_hip_roll_joint" pos="0 0 0" axis="1 0 0" range="-0.5236 2.9671"
            actuatorfrcrange="-88 88" class="leg_motor" />
          <geom type="mesh" contype="0" conaffinity="0" group="1" density="0" rgba="0.7 0.7 0.7 1"
            mesh="left_hip_roll_link" />
          <geom type="mesh" rgba="0.7 0.7 0.7 1" mesh="left_hip_roll_link" />
          <body name="left_hip_yaw_link" pos="0.025001 0 -0.12412">
            <inertial pos="-0.057709 -0.010981 -0.15078" quat="0.600598 0.15832 0.223482 0.751181"
              mass="1.702" diaginertia="0.00776166 0.00717575 0.00160139" />
            <joint name="left_hip_yaw_joint" pos="0 0 0" axis="0 0 1" range="-2.7576 2.7576"
              actuatorfrcrange="-88 88" class="leg_motor" />
            <geom type="mesh" contype="0" conaffinity="0" group="1" density="0" rgba="0.7 0.7 0.7 1"
              mesh="left_hip_yaw_link" />
            <geom type="mesh" rgba="0.7 0.7 0.7 1" mesh="left_hip_yaw_link" />
            <body name="left_knee_link" pos="-0.078273 0.0021489 -0.17734"
              quat="0.996179 0 0.0873386 0">
              <inertial pos="0.005457 0.003964 -0.12074"
                quat="0.923418 -0.0327699 0.0158246 0.382067" mass="1.932"
                diaginertia="0.0113804 0.0112778 0.00146458" />
              <joint name="left_knee_joint" pos="0 0 0" axis="0 1 0" range="-0.087267 2.8798"
                actuatorfrcrange="-139 139" class="leg_motor" />
              <geom type="mesh" contype="0" conaffinity="0" group="1" density="0"
                rgba="0.7 0.7 0.7 1" mesh="left_knee_link" />
              <geom type="mesh" rgba="0.7 0.7 0.7 1" mesh="left_knee_link" />
              <body name="left_ankle_pitch_link" pos="0 -9.4445e-05 -0.30001">
                <inertial pos="-0.007269 0 0.011137" quat="0.603053 0.369225 0.369225 0.603053"
                  mass="0.074" diaginertia="1.89e-05 1.40805e-05 6.9195e-06" />
                <joint name="left_ankle_pitch_joint" pos="0 0 0" axis="0 1 0"
                  range="-0.87267 0.5236" actuatorfrcrange="-50 50" class="ankle_motor" />
                <geom type="mesh" contype="0" conaffinity="0" group="1" density="0"
                  rgba="0.7 0.7 0.7 1" mesh="left_ankle_pitch_link" />
                <geom type="mesh" rgba="0.7 0.7 0.7 1" mesh="left_ankle_pitch_link" />
                <body name="left_ankle_roll_link" pos="0 0 -0.017558">
                  <inertial pos="0.026505 0 -0.016425"
                    quat="-0.000481092 0.728482 -0.000618967 0.685065" mass="0.608"
                    diaginertia="0.00167218 0.0016161 0.000217621" />
                  <joint name="left_ankle_roll_joint" pos="0 0 0" axis="1 0 0"
                    range="-0.2618 0.2618" actuatorfrcrange="-50 50" class="ankle_motor" />
                  <geom type="mesh" contype="0" conaffinity="0" group="1" density="0"
                    rgba="0.2 0.2 0.2 1" mesh="left_ankle_roll_link" />
                  <geom size="0.005" pos="-0.05 0.025 -0.03" rgba="0.2 0.2 0.2 1" />
                  <geom size="0.005" pos="-0.05 -0.025 -0.03" rgba="0.2 0.2 0.2 1" />
                  <geom size="0.005" pos="0.12 0.03 -0.03" rgba="0.2 0.2 0.2 1" />
                  <geom size="0.005" pos="0.12 -0.03 -0.03" rgba="0.2 0.2 0.2 1" />
                </body>
              </body>
            </body>
          </body>
        </body>
      </body>
      <body name="right_hip_pitch_link" pos="0 -0.064452 -0.1027">
        <inertial pos="0.002741 -0.047791 -0.02606" quat="0.954862 -0.293964 0.0302556 -0.030122"
          mass="1.35" diaginertia="0.00181517 0.00153422 0.00116212" />
        <joint name="right_hip_pitch_joint" pos="0 0 0" axis="0 1 0" range="-2.5307 2.8798"
          actuatorfrcrange="-88 88" class="leg_motor" />
        <geom type="mesh" contype="0" conaffinity="0" group="1" density="0" rgba="0.2 0.2 0.2 1"
          mesh="right_hip_pitch_link" />
        <geom type="mesh" rgba="0.2 0.2 0.2 1" mesh="right_hip_pitch_link" />
        <body name="right_hip_roll_link" pos="0 -0.052 -0.030465" quat="0.996179 0 -0.0873386 0">
          <inertial pos="0.029812 0.001045 -0.087934" quat="0.977808 1.97119e-05 0.205576 0.0403793"
            mass="1.52" diaginertia="0.00254986 0.00241169 0.00148755" />
          <joint name="right_hip_roll_joint" pos="0 0 0" axis="1 0 0" range="-2.9671 0.5236"
            actuatorfrcrange="-88 88" class="leg_motor" />
          <geom type="mesh" contype="0" conaffinity="0" group="1" density="0" rgba="0.7 0.7 0.7 1"
            mesh="right_hip_roll_link" />
          <geom type="mesh" rgba="0.7 0.7 0.7 1" mesh="right_hip_roll_link" />
          <body name="right_hip_yaw_link" pos="0.025001 0 -0.12412">
            <inertial pos="-0.057709 0.010981 -0.15078" quat="0.751181 0.223482 0.15832 0.600598"
              mass="1.702" diaginertia="0.00776166 0.00717575 0.00160139" />
            <joint name="right_hip_yaw_joint" pos="0 0 0" axis="0 0 1" range="-2.7576 2.7576"
              actuatorfrcrange="-88 88" class="leg_motor" />
            <geom type="mesh" contype="0" conaffinity="0" group="1" density="0" rgba="0.7 0.7 0.7 1"
              mesh="right_hip_yaw_link" />
            <geom type="mesh" rgba="0.7 0.7 0.7 1" mesh="right_hip_yaw_link" />
            <body name="right_knee_link" pos="-0.078273 -0.0021489 -0.17734"
              quat="0.996179 0 0.0873386 0">
              <inertial pos="0.005457 -0.003964 -0.12074"
                quat="0.923439 0.0345276 0.0116333 -0.382012" mass="1.932"
                diaginertia="0.011374 0.0112843 0.00146452" />
              <joint name="right_knee_joint" pos="0 0 0" axis="0 1 0" range="-0.087267 2.8798"
                actuatorfrcrange="-139 139" class="leg_motor" />
              <geom type="mesh" contype="0" conaffinity="0" group="1" density="0"
                rgba="0.7 0.7 0.7 1" mesh="right_knee_link" />
              <geom type="mesh" rgba="0.7 0.7 0.7 1" mesh="right_knee_link" />
              <body name="right_ankle_pitch_link" pos="0 9.4445e-05 -0.30001">
                <inertial pos="-0.007269 0 0.011137" quat="0.603053 0.369225 0.369225 0.603053"
                  mass="0.074" diaginertia="1.89e-05 1.40805e-05 6.9195e-06" />
                <joint name="right_ankle_pitch_joint" pos="0 0 0" axis="0 1 0"
                  range="-0.87267 0.5236" actuatorfrcrange="-50 50" class="ankle_motor" />
                <geom type="mesh" contype="0" conaffinity="0" group="1" density="0"
                  rgba="0.7 0.7 0.7 1" mesh="right_ankle_pitch_link" />
                <geom type="mesh" rgba="0.7 0.7 0.7 1" mesh="right_ankle_pitch_link" />
                <body name="right_ankle_roll_link" pos="0 0 -0.017558">
                  <inertial pos="0.026505 0 -0.016425"
                    quat="0.000481092 0.728482 0.000618967 0.685065" mass="0.608"
                    diaginertia="0.00167218 0.0016161 0.000217621" />
                  <joint name="right_ankle_roll_joint" pos="0 0 0" axis="1 0 0"
                    range="-0.2618 0.2618" actuatorfrcrange="-50 50" class="ankle_motor" />
                  <geom type="mesh" contype="0" conaffinity="0" group="1" density="0"
                    rgba="0.2 0.2 0.2 1" mesh="right_ankle_roll_link" />
                  <geom size="0.005" pos="-0.05 0.025 -0.03" rgba="0.2 0.2 0.2 1" />
                  <geom size="0.005" pos="-0.05 -0.025 -0.03" rgba="0.2 0.2 0.2 1" />
                  <geom size="0.005" pos="0.12 0.03 -0.03" rgba="0.2 0.2 0.2 1" />
                  <geom size="0.005" pos="0.12 -0.03 -0.03" rgba="0.2 0.2 0.2 1" />
                </body>
              </body>
            </body>
          </body>
        </body>
      </body>
      <body name="waist_yaw_link">
        <inertial pos="0.003964 0 0.018769" quat="-0.0178291 0.628464 0.0282471 0.777121"
          mass="0.244" diaginertia="0.000158561 0.000124229 9.67669e-05" />
        <joint name="waist_yaw_joint" pos="0 0 0" axis="0 0 1" range="-2.618 2.618"
          actuatorfrcrange="-88 88" class="torso_motor" />
        <geom type="mesh" contype="0" conaffinity="0" group="1" density="0" rgba="0.7 0.7 0.7 1"
          mesh="waist_yaw_link" />
        <body name="waist_roll_link" pos="-0.0039635 0 0.035">
          <inertial pos="0 -0.000236 0.010111" quat="0.99979 0.020492 0 0" mass="0.047"
            diaginertia="7.515e-06 6.40206e-06 3.98394e-06" />
          <joint name="waist_roll_joint" pos="0 0 0" axis="1 0 0" range="-0.52 0.52"
            actuatorfrcrange="-50 50" class="torso_motor"/>
          <geom type="mesh" contype="0" conaffinity="0" group="1" density="0" rgba="0.7 0.7 0.7 1"
            mesh="waist_roll_link" />
          <body name="torso_link" pos="0 0 0.019">
            <camera name="head_camera" pos="0.06 0.0 0.45" euler="0 -0.8 -1.57" fovy="90"/>
            <inertial pos="0.00331658 0.000261533 0.179856"
              quat="0.999831 0.000376204 0.0179895 -0.00377704" mass="9.598"
              diaginertia="0.12407 0.111951 0.0325382" />
            <joint name="waist_pitch_joint" pos="0 0 0" axis="0 1 0" range="-0.52 0.52"
              actuatorfrcrange="-50 50" class="torso_motor"/>
            <geom type="mesh" contype="0" conaffinity="0" group="1" density="0" rgba="0.7 0.7 0.7 1"
              mesh="torso_link" />
            <geom type="mesh" rgba="0.7 0.7 0.7 1" mesh="torso_link" />
            <geom pos="0.0039635 0 -0.054" quat="1 0 0 0" type="mesh" contype="0" conaffinity="0"
              group="1" density="0" rgba="0.2 0.2 0.2 1" mesh="logo_link" />
            <geom pos="0.0039635 0 -0.054" quat="1 0 0 0" type="mesh" rgba="0.2 0.2 0.2 1"
              mesh="logo_link" />
            <geom pos="0.0039635 0 -0.054" type="mesh" contype="0" conaffinity="0" group="1"
              density="0" rgba="0.2 0.2 0.2 1" mesh="head_link" />
            <geom pos="0.0039635 0 -0.054" type="mesh" rgba="0.2 0.2 0.2 1" mesh="head_link" />
            <geom pos="0.0039635 0 -0.054" quat="1 0 0 0" type="mesh" contype="0" conaffinity="0"
              group="1" density="0" rgba="0.7 0.7 0.7 1" mesh="waist_support_link" />
            <geom pos="0.0039635 0 -0.054" quat="1 0 0 0" type="mesh" rgba="0.7 0.7 0.7 1"
              mesh="waist_support_link" />
            <site name="imu" size="0.01" pos="-0.03959 -0.00224 0.13792" />
            <!-- ======================== LEFT ARM ======================== -->
            <body name="left_shoulder_pitch_link" pos="0.0039563 0.10022 0.23778"
              quat="0.990264 0.139201 1.38722e-05 -9.86868e-05">
              <inertial pos="0 0.035892 -0.011628" quat="0.654152 0.0130458 -0.326267 0.68225"
                mass="0.718" diaginertia="0.000465864 0.000432842 0.000406394" />
              <joint name="left_shoulder_pitch_joint" pos="0 0 0" axis="0 1 0"
                range="-3.0892 2.6704" actuatorfrcrange="-25 25" class="arm_motor" />
              <geom type="mesh" contype="0" conaffinity="0" group="1" density="0"
                rgba="0.7 0.7 0.7 1" mesh="left_shoulder_pitch_link" />
              <geom size="0.03 0.025" pos="0 0.04 -0.01" quat="0.707107 0 0.707107 0"
                type="cylinder" rgba="0.7 0.7 0.7 1" />
              <body name="left_shoulder_roll_link" pos="0 0.038 -0.013831"
                quat="0.990268 -0.139172 0 0">
                <inertial pos="-0.000227 0.00727 -0.063243"
                  quat="0.701256 -0.0196223 -0.00710317 0.712604" mass="0.643"
                  diaginertia="0.000691311 0.000618011 0.000388977" />
                <joint name="left_shoulder_roll_joint" pos="0 0 0" axis="1 0 0"
                  range="-1.5882 2.2515" actuatorfrcrange="-25 25" class="arm_motor" />
                <geom type="mesh" contype="0" conaffinity="0" group="1" density="0"
                  rgba="0.7 0.7 0.7 1" mesh="left_shoulder_roll_link" />
                <geom size="0.03 0.015" pos="-0.004 0.006 -0.053" type="cylinder"
                  rgba="0.7 0.7 0.7 1" />
                <body name="left_shoulder_yaw_link" pos="0 0.00624 -0.1032">
                  <inertial pos="0.010773 -0.002949 -0.072009"
                    quat="0.716879 -0.0964829 -0.0679942 0.687134" mass="0.734"
                    diaginertia="0.00106187 0.00103217 0.000400661" />
                  <joint name="left_shoulder_yaw_joint" pos="0 0 0" axis="0 0 1"
                    range="-2.618 2.618" actuatorfrcrange="-25 25" class="arm_motor" />
                  <geom type="mesh" contype="0" conaffinity="0" group="1" density="0"
                    rgba="0.7 0.7 0.7 1" mesh="left_shoulder_yaw_link" />
                  <geom type="mesh" rgba="0.7 0.7 0.7 1" mesh="left_shoulder_yaw_link" />
                  <body name="left_elbow_link" pos="0.015783 0 -0.080518">
                    <inertial pos="0.064956 0.004454 -0.010062"
                      quat="0.541765 0.636132 0.388821 0.388129" mass="0.6"
                      diaginertia="0.000443035 0.000421612 0.000259353" />
                    <joint name="left_elbow_joint" pos="0 0 0" axis="0 1 0" range="-1.0472 2.0944"
                      actuatorfrcrange="-25 25" class="arm_motor" />
                    <geom type="mesh" contype="0" conaffinity="0" group="1" density="0"
                      rgba="0.7 0.7 0.7 1" mesh="left_elbow_link" />
                    <geom type="mesh" rgba="0.7 0.7 0.7 1" mesh="left_elbow_link" />
                    <body name="left_wrist_roll_link" pos="0.1 0.00188791 -0.01">
                      <inertial pos="0.0171394 0.000537591 4.8864e-07"
                        quat="0.575338 0.411667 -0.574906 0.411094" mass="0.085445"
                        diaginertia="5.48211e-05 4.96646e-05 3.57798e-05" />
                      <joint name="left_wrist_roll_joint" pos="0 0 0" axis="1 0 0"
                        range="-1.97222 1.97222" actuatorfrcrange="-25 25" class="arm_motor" />
                      <geom type="mesh" contype="0" conaffinity="0" group="1" density="0"
                        rgba="0.7 0.7 0.7 1" mesh="left_wrist_roll_link" />
                      <geom type="mesh" rgba="0.7 0.7 0.7 1" mesh="left_wrist_roll_link" />
                      <body name="left_wrist_pitch_link" pos="0.038 0 0">
                        <inertial pos="0.0229999 -0.00111685 -0.00111658"
                          quat="0.249998 0.661363 0.293036 0.643608" mass="0.48405"
                          diaginertia="0.000430353 0.000429873 0.000164648" />
                        <joint name="left_wrist_pitch_joint" pos="0 0 0" axis="0 1 0"
                          range="-1.61443 1.61443" actuatorfrcrange="-5 5" class="wrist_motor" />
                        <geom type="mesh" contype="0" conaffinity="0" group="1" density="0"
                          rgba="0.7 0.7 0.7 1" mesh="left_wrist_pitch_link" />
                        <geom type="mesh" rgba="0.7 0.7 0.7 1" mesh="left_wrist_pitch_link" />
                        <body name="left_wrist_yaw_link" pos="0.046 0 0">
                          <inertial pos="0.0885506 0.00212216 -0.000374562"
                            quat="0.487149 0.493844 0.513241 0.505358" mass="0.457415"
                            diaginertia="0.00105989 0.000895419 0.000323842" />
                          <joint name="left_wrist_yaw_joint" pos="0 0 0" axis="0 0 1"
                            range="-1.61443 1.61443" actuatorfrcrange="-5 5" class="wrist_motor" />
                          <geom type="mesh" contype="0" conaffinity="0" group="1" density="0"
                            rgba="0.7 0.7 0.7 1" mesh="left_wrist_yaw_link" />
                          <geom type="mesh" rgba="0.7 0.7 0.7 1" mesh="left_wrist_yaw_link" />

                          <!-- ===== LEFT INSPIRE HAND ===== -->
                          <!-- Attached at wrist end; euler="0 0 1.5708" rotates hand_base_link  -->
                          <!-- so that fingers (hand -Y) point in wrist +X (forward along arm). -->
                          <body name="l_ih_hand_base" pos="0.05 0 0" euler="0 0 1.5708">
                            <inertial pos="-0.0025264 -0.066047 -0.0019598" mass="0.14143"
                              fullinertia="0.00012281 8.3832E-05 7.6663E-05 2.1711E-06 1.7709E-06 -1.6551E-06"/>
                            <geom type="mesh" contype="0" conaffinity="0" group="1" density="0"
                              rgba="0.8 0.65 0.5 1" mesh="l_ih_left_base_link"/>
                            <geom type="mesh" rgba="0.8 0.65 0.5 1" mesh="l_ih_left_base_link"/>
                            <!-- Palm collision primitives (half-extents for box) -->
                            <geom type="cylinder" pos="0 -0.0136 0" euler="1.5708 0 0"
                              size="0.028 0.0139" rgba="0.8 0.65 0.5 0"/>
                            <geom type="box" pos="-0.0032 -0.038 0"
                              size="0.01955 0.0101 0.0287" rgba="0.8 0.65 0.5 0"/>
                            <geom type="box" pos="-0.0032 -0.0682 0"
                              size="0.01955 0.02 0.0407" rgba="0.8 0.65 0.5 0"/>
                            <geom type="box" pos="0 -0.1081 0"
                              size="0.0161 0.02 0.0407" rgba="0.8 0.65 0.5 0"/>

                            <!-- Left Thumb -->
                            <body name="l_ih_thumb_proximal_base"
                              pos="-0.01696 -0.0691 0.02045" euler="1.5708 0 1.5708">
                              <inertial pos="0.0048817 0.0009382 -0.00722" mass="0.0018869"
                                fullinertia="5.816E-08 7.9161E-08 6.7433E-08 -1.4539E-08 -4.491E-09 -1.8727E-09"/>
                              <joint name="l_ih_thumb_proximal_yaw" axis="0 0 1" range="0 1.308"
                                actuatorfrcrange="-1 1" class="finger_motor"/>
                              <geom type="mesh" contype="0" conaffinity="0" group="1" density="0"
                                rgba="0.8 0.65 0.5 1" mesh="l_ih_left_thumb_proximal_base"/>
                              <geom type="mesh" rgba="0.8 0.65 0.5 1" mesh="l_ih_left_thumb_proximal_base"/>
                              <geom type="mesh" contype="0" conaffinity="0" group="1" density="0"
                                rgba="0 0 0 0" mesh="l_ih_c_left_thumb_proximal_base"/>
                              <geom type="mesh" rgba="0 0 0 0" mesh="l_ih_c_left_thumb_proximal_base"/>
                              <body name="l_ih_thumb_proximal"
                                pos="0.0099867 0.0098242 -0.0089" euler="-1.5708 -0.16939 0">
                                <inertial pos="0.021932 -0.012785 -0.0080386" mass="0.0066075"
                                  fullinertia="1.5686E-06 1.7353E-06 2.786E-06 7.8296E-07 8.9143E-10 1.0191E-09"/>
                                <joint name="l_ih_thumb_proximal_pitch" axis="0 0 -1" range="0 0.6"
                                  actuatorfrcrange="-1 1" class="finger_motor"/>
                                <geom type="mesh" contype="0" conaffinity="0" group="1" density="0"
                                  rgba="0.8 0.65 0.5 1" mesh="l_ih_left_thumb_proximal"/>
                                <geom type="mesh" rgba="0.8 0.65 0.5 1" mesh="l_ih_left_thumb_proximal"/>
                                <geom type="mesh" contype="0" conaffinity="0" group="1" density="0"
                                  rgba="0 0 0 0" mesh="l_ih_c_left_thumb_proximal"/>
                                <geom type="mesh" rgba="0 0 0 0" mesh="l_ih_c_left_thumb_proximal"/>
                                <body name="l_ih_thumb_intermediate"
                                  pos="0.04407 -0.034553 -0.0008">
                                  <inertial pos="0.0095544 0.0016282 -0.0071997" mass="0.0037847"
                                    fullinertia="3.6981E-07 3.2394E-07 4.6531E-07 9.8581E-08 -4.7469E-12 -1.0939E-12"/>
                                  <joint name="l_ih_thumb_intermediate" axis="0 0 -1" range="0 0.8"
                                    actuatorfrcrange="-1 1" class="finger_motor"/>
                                  <geom type="mesh" contype="0" conaffinity="0" group="1" density="0"
                                    rgba="0.8 0.65 0.5 1" mesh="l_ih_left_thumb_intermediate"/>
                                  <geom type="mesh" rgba="0.8 0.65 0.5 1" mesh="l_ih_left_thumb_intermediate"/>
                                  <geom type="mesh" contype="0" conaffinity="0" group="1" density="0"
                                    rgba="0 0 0 0" mesh="l_ih_c_left_thumb_intermediate"/>
                                  <geom type="mesh" rgba="0 0 0 0" mesh="l_ih_c_left_thumb_intermediate"/>
                                  <body name="l_ih_thumb_distal" pos="0.020248 -0.010156 -0.0012">
                                    <inertial pos="0.0092888 -0.0049529 -0.0060033" mass="0.0033441"
                                      fullinertia="1.3632E-07 1.4052E-07 2.0026E-07 5.6788E-08 -9.2764E-11 1.2283E-10"/>
                                    <joint name="l_ih_thumb_distal" axis="0 0 -1" range="0 0.4"
                                      actuatorfrcrange="-1 1" class="finger_motor"/>
                                    <geom type="mesh" contype="0" conaffinity="0" group="1" density="0"
                                      rgba="0.8 0.65 0.5 1" mesh="l_ih_left_thumb_distal"/>
                                    <geom type="mesh" rgba="0.8 0.65 0.5 1" mesh="l_ih_left_thumb_distal"/>
                                    <geom type="mesh" contype="0" conaffinity="0" group="1" density="0"
                                      rgba="0 0 0 0" mesh="l_ih_c_left_thumb_distal"/>
                                    <geom type="mesh" rgba="0 0 0 0" mesh="l_ih_c_left_thumb_distal"/>
                                  </body>
                                </body>
                              </body>
                            </body>

                            <!-- Left Index finger -->
                            <body name="l_ih_index_proximal"
                              pos="0.00028533 -0.13653 0.032268" euler="-0.034907 0 0">
                              <inertial pos="0.0012259 -0.011942 -0.0060001" mass="0.0042403"
                                fullinertia="6.6232E-07 2.1146E-07 6.9398E-07 1.5775E-08 1.8515E-12 5.0828E-12"/>
                              <joint name="l_ih_index_proximal" axis="0 0 -1" range="0 1.47"
                                actuatorfrcrange="-1 1" class="finger_motor"/>
                              <geom type="mesh" contype="0" conaffinity="0" group="1" density="0"
                                rgba="0.8 0.65 0.5 1" mesh="l_ih_left_index_proximal"/>
                              <geom type="mesh" rgba="0.8 0.65 0.5 1" mesh="l_ih_left_index_proximal"/>
                              <geom type="mesh" contype="0" conaffinity="0" group="1" density="0"
                                rgba="0 0 0 0" mesh="l_ih_c_left_index_proximal"/>
                              <geom type="mesh" rgba="0 0 0 0" mesh="l_ih_c_left_index_proximal"/>
                              <body name="l_ih_index_intermediate" pos="-0.0026138 -0.032026 -0.001">
                                <inertial pos="0.0019697 -0.019589 -0.005" mass="0.0045683"
                                  fullinertia="7.6111E-07 9.6076E-08 7.8179E-07 -8.7637E-08 -3.7751E-13 -9.9444E-13"/>
                                <joint name="l_ih_index_intermediate" axis="0 0 -1"
                                  range="-0.04545 1.56" actuatorfrcrange="-1 1" class="finger_motor"/>
                                <geom type="mesh" contype="0" conaffinity="0" group="1" density="0"
                                  rgba="0.8 0.65 0.5 1" mesh="l_ih_left_index_intermediate"/>
                                <geom type="mesh" rgba="0.8 0.65 0.5 1" mesh="l_ih_left_index_intermediate"/>
                                <geom type="mesh" contype="0" conaffinity="0" group="1" density="0"
                                  rgba="0 0 0 0" mesh="l_ih_c_left_index_intermediate"/>
                                <geom type="mesh" rgba="0 0 0 0" mesh="l_ih_c_left_index_intermediate"/>
                              </body>
                            </body>

                            <!-- Left Middle finger -->
                            <body name="l_ih_middle_proximal"
                              pos="0.00028533 -0.1371 0.01295" euler="0 0 0">
                              <inertial pos="0.001297 -0.011934 -0.0060001" mass="0.0042403"
                                fullinertia="6.6211E-07 2.1167E-07 6.9397E-07 1.8461E-08 1.8002E-12 6.6808E-12"/>
                              <joint name="l_ih_middle_proximal" axis="0 0 -1" range="0 1.47"
                                actuatorfrcrange="-1 1" class="finger_motor"/>
                              <geom type="mesh" contype="0" conaffinity="0" group="1" density="0"
                                rgba="0.8 0.65 0.5 1" mesh="l_ih_left_index_proximal"/>
                              <geom type="mesh" rgba="0.8 0.65 0.5 1" mesh="l_ih_left_index_proximal"/>
                              <geom type="mesh" contype="0" conaffinity="0" group="1" density="0"
                                rgba="0 0 0 0" mesh="l_ih_c_left_index_proximal"/>
                              <geom type="mesh" rgba="0 0 0 0" mesh="l_ih_c_left_index_proximal"/>
                              <body name="l_ih_middle_intermediate" pos="-0.0024229 -0.032041 -0.001">
                                <inertial pos="0.001921 -0.020796 -0.005" mass="0.0050396"
                                  fullinertia="9.5822E-07 1.0646E-07 9.8384E-07 -1.1425E-07 -2.4791E-12 -5.9173E-12"/>
                                <joint name="l_ih_middle_intermediate" axis="0 0 -1"
                                  range="-0.04545 1.56" actuatorfrcrange="-1 1" class="finger_motor"/>
                                <geom type="mesh" contype="0" conaffinity="0" group="1" density="0"
                                  rgba="0.8 0.65 0.5 1" mesh="l_ih_left_middle_intermediate"/>
                                <geom type="mesh" rgba="0.8 0.65 0.5 1" mesh="l_ih_left_middle_intermediate"/>
                                <geom type="mesh" contype="0" conaffinity="0" group="1" density="0"
                                  rgba="0 0 0 0" mesh="l_ih_c_left_middle_intermediate"/>
                                <geom type="mesh" rgba="0 0 0 0" mesh="l_ih_c_left_middle_intermediate"/>
                              </body>
                            </body>

                            <!-- Left Ring finger -->
                            <body name="l_ih_ring_proximal"
                              pos="0.00028533 -0.13691 -0.0062872" euler="0.05236 0 0">
                              <inertial pos="0.001297 -0.011934 -0.0060002" mass="0.0042403"
                                fullinertia="6.6211E-07 2.1167E-07 6.9397E-07 1.8461E-08 1.5793E-12 6.6868E-12"/>
                              <joint name="l_ih_ring_proximal" axis="0 0 -1" range="0 1.47"
                                actuatorfrcrange="-1 1" class="finger_motor"/>
                              <geom type="mesh" contype="0" conaffinity="0" group="1" density="0"
                                rgba="0.8 0.65 0.5 1" mesh="l_ih_left_index_proximal"/>
                              <geom type="mesh" rgba="0.8 0.65 0.5 1" mesh="l_ih_left_index_proximal"/>
                              <geom type="mesh" contype="0" conaffinity="0" group="1" density="0"
                                rgba="0 0 0 0" mesh="l_ih_c_left_index_proximal"/>
                              <geom type="mesh" rgba="0 0 0 0" mesh="l_ih_c_left_index_proximal"/>
                              <body name="l_ih_ring_intermediate" pos="-0.0024229 -0.032041 -0.001">
                                <inertial pos="0.0021753 -0.019567 -0.005" mass="0.0045683"
                                  fullinertia="7.6286E-07 9.431E-08 7.8177E-07 -8.0635E-08 -6.1562E-13 -5.8619E-13"/>
                                <joint name="l_ih_ring_intermediate" axis="0 0 -1"
                                  range="-0.04545 1.56" actuatorfrcrange="-1 1" class="finger_motor"/>
                                <geom type="mesh" contype="0" conaffinity="0" group="1" density="0"
                                  rgba="0.8 0.65 0.5 1" mesh="l_ih_left_index_intermediate"/>
                                <geom type="mesh" rgba="0.8 0.65 0.5 1" mesh="l_ih_left_index_intermediate"/>
                                <geom type="mesh" contype="0" conaffinity="0" group="1" density="0"
                                  rgba="0 0 0 0" mesh="l_ih_c_left_index_intermediate"/>
                                <geom type="mesh" rgba="0 0 0 0" mesh="l_ih_c_left_index_intermediate"/>
                              </body>
                            </body>

                            <!-- Left Pinky finger -->
                            <body name="l_ih_pinky_proximal"
                              pos="0.00028533 -0.13571 -0.025488" euler="0.10472 0 0">
                              <inertial pos="0.001297 -0.011934 -0.0060001" mass="0.0042403"
                                fullinertia="6.6211E-07 2.1167E-07 6.9397E-07 1.8461E-08 1.6907E-12 6.9334E-12"/>
                              <joint name="l_ih_pinky_proximal" axis="0 0 -1" range="0 1.47"
                                actuatorfrcrange="-1 1" class="finger_motor"/>
                              <geom type="mesh" contype="0" conaffinity="0" group="1" density="0"
                                rgba="0.8 0.65 0.5 1" mesh="l_ih_left_index_proximal"/>
                              <geom type="mesh" rgba="0.8 0.65 0.5 1" mesh="l_ih_left_index_proximal"/>
                              <geom type="mesh" contype="0" conaffinity="0" group="1" density="0"
                                rgba="0 0 0 0" mesh="l_ih_c_left_index_proximal"/>
                              <geom type="mesh" rgba="0 0 0 0" mesh="l_ih_c_left_index_proximal"/>
                              <body name="l_ih_pinky_intermediate" pos="-0.0024229 -0.032041 -0.001">
                                <inertial pos="0.0024748 -0.016203 -0.0050031" mass="0.0035996"
                                  fullinertia="4.3913E-07 7.0247E-08 4.4867E-07 -4.1418E-08 3.7168E-11 -5.8613E-11"/>
                                <joint name="l_ih_pinky_intermediate" axis="0 0 -1"
                                  range="-0.04545 1.56" actuatorfrcrange="-1 1" class="finger_motor"/>
                                <geom type="mesh" contype="0" conaffinity="0" group="1" density="0"
                                  rgba="0.8 0.65 0.5 1" mesh="l_ih_left_pinky_intermediate"/>
                                <geom type="mesh" rgba="0.8 0.65 0.5 1" mesh="l_ih_left_pinky_intermediate"/>
                                <geom type="mesh" contype="0" conaffinity="0" group="1" density="0"
                                  rgba="0 0 0 0" mesh="l_ih_c_left_pinky_intermediate"/>
                                <geom type="mesh" rgba="0 0 0 0" mesh="l_ih_c_left_pinky_intermediate"/>
                              </body>
                            </body>
                          </body>
                          <!-- ===== END LEFT INSPIRE HAND ===== -->

                        </body>
                      </body>
                    </body>
                  </body>
                </body>
              </body>
            </body>
            <!-- ======================== RIGHT ARM ======================== -->
            <body name="right_shoulder_pitch_link" pos="0.0039563 -0.10021 0.23778"
              quat="0.990264 -0.139201 1.38722e-05 9.86868e-05">
              <inertial pos="0 -0.035892 -0.011628" quat="0.68225 -0.326267 0.0130458 0.654152"
                mass="0.718" diaginertia="0.000465864 0.000432842 0.000406394" />
              <joint name="right_shoulder_pitch_joint" pos="0 0 0" axis="0 1 0"
                range="-3.0892 2.6704" actuatorfrcrange="-25 25" class="arm_motor" />
              <geom type="mesh" contype="0" conaffinity="0" group="1" density="0"
                rgba="0.7 0.7 0.7 1" mesh="right_shoulder_pitch_link" />
              <geom size="0.03 0.025" pos="0 -0.04 -0.01" quat="0.707107 0 0.707107 0"
                type="cylinder" rgba="0.7 0.7 0.7 1" />
              <body name="right_shoulder_roll_link" pos="0 -0.038 -0.013831"
                quat="0.990268 0.139172 0 0">
                <inertial pos="-0.000227 -0.00727 -0.063243"
                  quat="0.712604 -0.00710317 -0.0196223 0.701256" mass="0.643"
                  diaginertia="0.000691311 0.000618011 0.000388977" />
                <joint name="right_shoulder_roll_joint" pos="0 0 0" axis="1 0 0"
                  range="-2.2515 1.5882" actuatorfrcrange="-25 25" class="arm_motor" />
                <geom type="mesh" contype="0" conaffinity="0" group="1" density="0"
                  rgba="0.7 0.7 0.7 1" mesh="right_shoulder_roll_link" />
                <geom size="0.03 0.015" pos="-0.004 -0.006 -0.053" type="cylinder"
                  rgba="0.7 0.7 0.7 1" />
                <body name="right_shoulder_yaw_link" pos="0 -0.00624 -0.1032">
                  <inertial pos="0.010773 0.002949 -0.072009"
                    quat="0.687134 -0.0679942 -0.0964829 0.716879" mass="0.734"
                    diaginertia="0.00106187 0.00103217 0.000400661" />
                  <joint name="right_shoulder_yaw_joint" pos="0 0 0" axis="0 0 1"
                    range="-2.618 2.618" actuatorfrcrange="-25 25" class="arm_motor" />
                  <geom type="mesh" contype="0" conaffinity="0" group="1" density="0"
                    rgba="0.7 0.7 0.7 1" mesh="right_shoulder_yaw_link" />
                  <geom type="mesh" rgba="0.7 0.7 0.7 1" mesh="right_shoulder_yaw_link" />
                  <body name="right_elbow_link" pos="0.015783 0 -0.080518">
                    <inertial pos="0.064956 -0.004454 -0.010062"
                      quat="0.388129 0.388821 0.636132 0.541765" mass="0.6"
                      diaginertia="0.000443035 0.000421612 0.000259353" />
                    <joint name="right_elbow_joint" pos="0 0 0" axis="0 1 0" range="-1.0472 2.0944"
                      actuatorfrcrange="-25 25" class="arm_motor" />
                    <geom type="mesh" contype="0" conaffinity="0" group="1" density="0"
                      rgba="0.7 0.7 0.7 1" mesh="right_elbow_link" />
                    <geom type="mesh" rgba="0.7 0.7 0.7 1" mesh="right_elbow_link" />
                    <body name="right_wrist_roll_link" pos="0.1 -0.00188791 -0.01">
                      <inertial pos="0.0171394 -0.000537591 4.8864e-07"
                        quat="0.411667 0.575338 -0.411094 0.574906" mass="0.085445"
                        diaginertia="5.48211e-05 4.96646e-05 3.57798e-05" />
                      <joint name="right_wrist_roll_joint" pos="0 0 0" axis="1 0 0"
                        range="-1.97222 1.97222" actuatorfrcrange="-25 25" class="arm_motor" />
                      <geom type="mesh" contype="0" conaffinity="0" group="1" density="0"
                        rgba="0.7 0.7 0.7 1" mesh="right_wrist_roll_link" />
                      <geom type="mesh" rgba="0.7 0.7 0.7 1" mesh="right_wrist_roll_link" />
                      <body name="right_wrist_pitch_link" pos="0.038 0 0">
                        <inertial pos="0.0229999 0.00111685 -0.00111658"
                          quat="0.643608 0.293036 0.661363 0.249998" mass="0.48405"
                          diaginertia="0.000430353 0.000429873 0.000164648" />
                        <joint name="right_wrist_pitch_joint" pos="0 0 0" axis="0 1 0"
                          range="-1.61443 1.61443" actuatorfrcrange="-5 5" class="wrist_motor" />
                        <geom type="mesh" contype="0" conaffinity="0" group="1" density="0"
                          rgba="0.7 0.7 0.7 1" mesh="right_wrist_pitch_link" />
                        <geom type="mesh" rgba="0.7 0.7 0.7 1" mesh="right_wrist_pitch_link" />
                        <body name="right_wrist_yaw_link" pos="0.046 0 0">
                          <inertial pos="0.0885506 -0.00212216 0.000573742"
                            quat="0.507224 0.511377 0.494292 0.486717" mass="0.457415"
                            diaginertia="0.0010598 0.000895373 0.0003238" />
                          <joint name="right_wrist_yaw_joint" pos="0 0 0" axis="0 0 1"
                            range="-1.61443 1.61443" actuatorfrcrange="-5 5" class="wrist_motor" />
                          <geom type="mesh" contype="0" conaffinity="0" group="1" density="0"
                            rgba="0.7 0.7 0.7 1" mesh="right_wrist_yaw_link" />
                          <geom type="mesh" rgba="0.7 0.7 0.7 1" mesh="right_wrist_yaw_link" />

                          <!-- ===== RIGHT INSPIRE HAND ===== -->
                          <!-- euler="3.14159 0 1.5708" = Rx(pi)@Rz(pi/2):                        -->
                          <!--   hand_base -Y → wrist +X (fingers fwd)                             -->
                          <!--   hand_base -Z → wrist +Z (right thumb up)                          -->
                          <!--   hand_base +X → wrist -Y (palm inward for right arm)               -->
                          <!-- All child pos/euler/axis taken directly from right URDF.             -->
                          <body name="r_ih_hand_base" pos="0.05 0 0" euler="3.14159 0 1.5708">
                            <inertial pos="-0.0025264 -0.066047 0.0019598" mass="0.14143"
                              fullinertia="0.00012281 8.3832E-05 7.6663E-05 2.1711E-06 1.7709E-06 -1.6551E-06"/>
                            <geom type="mesh" contype="0" conaffinity="0" group="1" density="0"
                              rgba="0.8 0.65 0.5 1" mesh="r_ih_right_base_link"/>
                            <geom type="mesh" rgba="0.8 0.65 0.5 1" mesh="r_ih_right_base_link"/>
                            <!-- Palm collision primitives (in hand_base_link frame) -->
                            <geom type="cylinder" pos="0 -0.0136 0" euler="1.5708 0 0"
                              size="0.028 0.0139" rgba="0.8 0.65 0.5 0"/>
                            <geom type="box" pos="-0.0032 -0.038 0"
                              size="0.01955 0.0101 0.0287" rgba="0.8 0.65 0.5 0"/>
                            <geom type="box" pos="-0.0032 -0.0682 0"
                              size="0.01955 0.02 0.0407" rgba="0.8 0.65 0.5 0"/>
                            <geom type="box" pos="0 -0.1081 0"
                              size="0.0161 0.02 0.0407" rgba="0.8 0.65 0.5 0"/>

                            <!-- Right Thumb -->
                            <body name="r_ih_thumb_proximal_base"
                              pos="-0.01696 -0.0691 -0.02045" euler="1.5708 0 -1.5708">
                              <inertial pos="-0.0048064 0.0009382 -0.00757" mass="0.0018869"
                                fullinertia="5.816E-08 7.9161E-08 6.7433E-08 1.4539E-08 4.491E-09 -1.8727E-09"/>
                              <joint name="r_ih_thumb_proximal_yaw" axis="0 0 -1" range="0 1.308"
                                actuatorfrcrange="-1 1" class="finger_motor"/>
                              <geom type="mesh" contype="0" conaffinity="0" group="1" density="0"
                                rgba="0.8 0.65 0.5 1" mesh="r_ih_right_thumb_proximal_base"/>
                              <geom type="mesh" rgba="0.8 0.65 0.5 1" mesh="r_ih_right_thumb_proximal_base"/>
                              <geom type="mesh" contype="0" conaffinity="0" group="1" density="0"
                                rgba="0 0 0 0" mesh="r_ih_c_right_thumb_proximal_base"/>
                              <geom type="mesh" rgba="0 0 0 0" mesh="r_ih_c_right_thumb_proximal_base"/>
                              <body name="r_ih_thumb_proximal"
                                pos="0.0099867 -0.0098242 -0.0089" euler="1.5708 -0.16939 0">
                                <inertial pos="0.021932 0.012785 -0.0080386" mass="0.0066075"
                                  fullinertia="1.5686E-06 1.7353E-06 2.786E-06 -7.8296E-07 8.9143E-10 -1.0191E-09"/>
                                <joint name="r_ih_thumb_proximal_pitch" axis="0 0 1" range="0 0.6"
                                  actuatorfrcrange="-1 1" class="finger_motor"/>
                                <geom type="mesh" contype="0" conaffinity="0" group="1" density="0"
                                  rgba="0.8 0.65 0.5 1" mesh="r_ih_right_thumb_proximal"/>
                                <geom type="mesh" rgba="0.8 0.65 0.5 1" mesh="r_ih_right_thumb_proximal"/>
                                <geom type="mesh" contype="0" conaffinity="0" group="1" density="0"
                                  rgba="0 0 0 0" mesh="r_ih_c_right_thumb_proximal"/>
                                <geom type="mesh" rgba="0 0 0 0" mesh="r_ih_c_right_thumb_proximal"/>
                                <body name="r_ih_thumb_intermediate"
                                  pos="0.04407 0.034553 -0.0008">
                                  <inertial pos="0.0095544 -0.0016282 -0.0071997" mass="0.0037847"
                                    fullinertia="3.6981E-07 3.2394E-07 4.6531E-07 -9.8581E-08 -4.7469E-12 1.0939E-12"/>
                                  <joint name="r_ih_thumb_intermediate" axis="0 0 1" range="0 0.8"
                                    actuatorfrcrange="-1 1" class="finger_motor"/>
                                  <geom type="mesh" contype="0" conaffinity="0" group="1" density="0"
                                    rgba="0.8 0.65 0.5 1" mesh="r_ih_right_thumb_intermediate"/>
                                  <geom type="mesh" rgba="0.8 0.65 0.5 1" mesh="r_ih_right_thumb_intermediate"/>
                                  <geom type="mesh" contype="0" conaffinity="0" group="1" density="0"
                                    rgba="0 0 0 0" mesh="r_ih_c_right_thumb_intermediate"/>
                                  <geom type="mesh" rgba="0 0 0 0" mesh="r_ih_c_right_thumb_intermediate"/>
                                  <body name="r_ih_thumb_distal" pos="0.020248 0.010156 -0.0012">
                                    <inertial pos="0.0092888 0.0049529 -0.0060033" mass="0.0033441"
                                      fullinertia="1.3632E-07 1.4052E-07 2.0026E-07 -5.6788E-08 -9.2764E-11 -1.2283E-10"/>
                                    <joint name="r_ih_thumb_distal" axis="0 0 1" range="0 0.4"
                                      actuatorfrcrange="-1 1" class="finger_motor"/>
                                    <geom type="mesh" contype="0" conaffinity="0" group="1" density="0"
                                      rgba="0.8 0.65 0.5 1" mesh="r_ih_right_thumb_distal"/>
                                    <geom type="mesh" rgba="0.8 0.65 0.5 1" mesh="r_ih_right_thumb_distal"/>
                                    <geom type="mesh" contype="0" conaffinity="0" group="1" density="0"
                                      rgba="0 0 0 0" mesh="r_ih_c_right_thumb_distal"/>
                                    <geom type="mesh" rgba="0 0 0 0" mesh="r_ih_c_right_thumb_distal"/>
                                  </body>
                                </body>
                              </body>
                            </body>

                            <!-- Right Index finger -->
                            <body name="r_ih_index_proximal"
                              pos="0.00028533 -0.13653 -0.032268" euler="-3.1067 0 0">
                              <inertial pos="0.0012259 0.011942 -0.0060001" mass="0.0042403"
                                fullinertia="6.6232E-07 2.1146E-07 6.9398E-07 -1.5775E-08 1.8515E-12 -5.0828E-12"/>
                              <joint name="r_ih_index_proximal" axis="0 0 1" range="0 1.47"
                                actuatorfrcrange="-1 1" class="finger_motor"/>
                              <geom type="mesh" contype="0" conaffinity="0" group="1" density="0"
                                rgba="0.8 0.65 0.5 1" mesh="r_ih_right_index_proximal"/>
                              <geom type="mesh" rgba="0.8 0.65 0.5 1" mesh="r_ih_right_index_proximal"/>
                              <geom type="mesh" contype="0" conaffinity="0" group="1" density="0"
                                rgba="0 0 0 0" mesh="r_ih_c_right_index_proximal"/>
                              <geom type="mesh" rgba="0 0 0 0" mesh="r_ih_c_right_index_proximal"/>
                              <body name="r_ih_index_intermediate" pos="-0.0026138 0.032026 -0.001">
                                <inertial pos="0.0019697 0.019589 -0.005" mass="0.0045683"
                                  fullinertia="7.6111E-07 9.6076E-08 7.8179E-07 8.7637E-08 -3.7751E-13 9.9444E-13"/>
                                <joint name="r_ih_index_intermediate" axis="0 0 1"
                                  range="-0.04545 1.56" actuatorfrcrange="-1 1" class="finger_motor"/>
                                <geom type="mesh" contype="0" conaffinity="0" group="1" density="0"
                                  rgba="0.8 0.65 0.5 1" mesh="r_ih_right_index_intermediate"/>
                                <geom type="mesh" rgba="0.8 0.65 0.5 1" mesh="r_ih_right_index_intermediate"/>
                                <geom type="mesh" contype="0" conaffinity="0" group="1" density="0"
                                  rgba="0 0 0 0" mesh="r_ih_c_right_index_intermediate"/>
                                <geom type="mesh" rgba="0 0 0 0" mesh="r_ih_c_right_index_intermediate"/>
                              </body>
                            </body>

                            <!-- Right Middle finger -->
                            <body name="r_ih_middle_proximal"
                              pos="0.00028533 -0.1371 -0.01295" euler="3.14159 0 0">
                              <inertial pos="0.001297 0.011934 -0.0060001" mass="0.0042403"
                                fullinertia="6.6211E-07 2.1167E-07 6.9397E-07 -1.8461E-08 1.8002E-12 -6.6808E-12"/>
                              <joint name="r_ih_middle_proximal" axis="0 0 1" range="0 1.47"
                                actuatorfrcrange="-1 1" class="finger_motor"/>
                              <geom type="mesh" contype="0" conaffinity="0" group="1" density="0"
                                rgba="0.8 0.65 0.5 1" mesh="r_ih_right_index_proximal"/>
                              <geom type="mesh" rgba="0.8 0.65 0.5 1" mesh="r_ih_right_index_proximal"/>
                              <geom type="mesh" contype="0" conaffinity="0" group="1" density="0"
                                rgba="0 0 0 0" mesh="r_ih_c_right_index_proximal"/>
                              <geom type="mesh" rgba="0 0 0 0" mesh="r_ih_c_right_index_proximal"/>
                              <body name="r_ih_middle_intermediate" pos="-0.0024229 0.032041 -0.001">
                                <inertial pos="0.001921 0.020796 -0.005" mass="0.0050396"
                                  fullinertia="9.5822E-07 1.0646E-07 9.8384E-07 1.1425E-07 -2.4791E-12 5.9173E-12"/>
                                <joint name="r_ih_middle_intermediate" axis="0 0 1"
                                  range="-0.04545 1.56" actuatorfrcrange="-1 1" class="finger_motor"/>
                                <geom type="mesh" contype="0" conaffinity="0" group="1" density="0"
                                  rgba="0.8 0.65 0.5 1" mesh="r_ih_right_middle_intermediate"/>
                                <geom type="mesh" rgba="0.8 0.65 0.5 1" mesh="r_ih_right_middle_intermediate"/>
                                <geom type="mesh" contype="0" conaffinity="0" group="1" density="0"
                                  rgba="0 0 0 0" mesh="r_ih_c_right_middle_intermediate"/>
                                <geom type="mesh" rgba="0 0 0 0" mesh="r_ih_c_right_middle_intermediate"/>
                              </body>
                            </body>

                            <!-- Right Ring finger -->
                            <body name="r_ih_ring_proximal"
                              pos="0.00028533 -0.13691 0.0062872" euler="3.0892 0 0">
                              <inertial pos="0.001297 0.011934 -0.0060002" mass="0.0042403"
                                fullinertia="6.6211E-07 2.1167E-07 6.9397E-07 -1.8461E-08 1.5793E-12 -6.6868E-12"/>
                              <joint name="r_ih_ring_proximal" axis="0 0 1" range="0 1.47"
                                actuatorfrcrange="-1 1" class="finger_motor"/>
                              <geom type="mesh" contype="0" conaffinity="0" group="1" density="0"
                                rgba="0.8 0.65 0.5 1" mesh="r_ih_right_index_proximal"/>
                              <geom type="mesh" rgba="0.8 0.65 0.5 1" mesh="r_ih_right_index_proximal"/>
                              <geom type="mesh" contype="0" conaffinity="0" group="1" density="0"
                                rgba="0 0 0 0" mesh="r_ih_c_right_index_proximal"/>
                              <geom type="mesh" rgba="0 0 0 0" mesh="r_ih_c_right_index_proximal"/>
                              <body name="r_ih_ring_intermediate" pos="-0.0024229 0.032041 -0.001">
                                <inertial pos="0.0021753 0.019567 -0.005" mass="0.0045683"
                                  fullinertia="7.6286E-07 9.431E-08 7.8177E-07 8.0635E-08 -6.1562E-13 5.8619E-13"/>
                                <joint name="r_ih_ring_intermediate" axis="0 0 1"
                                  range="-0.04545 1.56" actuatorfrcrange="-1 1" class="finger_motor"/>
                                <geom type="mesh" contype="0" conaffinity="0" group="1" density="0"
                                  rgba="0.8 0.65 0.5 1" mesh="r_ih_right_index_intermediate"/>
                                <geom type="mesh" rgba="0.8 0.65 0.5 1" mesh="r_ih_right_index_intermediate"/>
                                <geom type="mesh" contype="0" conaffinity="0" group="1" density="0"
                                  rgba="0 0 0 0" mesh="r_ih_c_right_index_intermediate"/>
                                <geom type="mesh" rgba="0 0 0 0" mesh="r_ih_c_right_index_intermediate"/>
                              </body>
                            </body>

                            <!-- Right Pinky finger -->
                            <body name="r_ih_pinky_proximal"
                              pos="0.00028533 -0.13571 0.025488" euler="3.0369 0 0">
                              <inertial pos="0.001297 0.011934 -0.0060001" mass="0.0042403"
                                fullinertia="6.6211E-07 2.1167E-07 6.9397E-07 -1.8461E-08 1.6907E-12 -6.9334E-12"/>
                              <joint name="r_ih_pinky_proximal" axis="0 0 1" range="0 1.47"
                                actuatorfrcrange="-1 1" class="finger_motor"/>
                              <geom type="mesh" contype="0" conaffinity="0" group="1" density="0"
                                rgba="0.8 0.65 0.5 1" mesh="r_ih_right_index_proximal"/>
                              <geom type="mesh" rgba="0.8 0.65 0.5 1" mesh="r_ih_right_index_proximal"/>
                              <geom type="mesh" contype="0" conaffinity="0" group="1" density="0"
                                rgba="0 0 0 0" mesh="r_ih_c_right_index_proximal"/>
                              <geom type="mesh" rgba="0 0 0 0" mesh="r_ih_c_right_index_proximal"/>
                              <body name="r_ih_pinky_intermediate" pos="-0.0024229 0.032041 -0.001">
                                <inertial pos="0.0024748 0.016203 -0.0050031" mass="0.0035996"
                                  fullinertia="4.3913E-07 7.0247E-08 4.4867E-07 4.1418E-08 3.7168E-11 5.8613E-11"/>
                                <joint name="r_ih_pinky_intermediate" axis="0 0 1"
                                  range="-0.04545 1.56" actuatorfrcrange="-1 1" class="finger_motor"/>
                                <geom type="mesh" contype="0" conaffinity="0" group="1" density="0"
                                  rgba="0.8 0.65 0.5 1" mesh="r_ih_right_pinky_intermediate"/>
                                <geom type="mesh" rgba="0.8 0.65 0.5 1" mesh="r_ih_right_pinky_intermediate"/>
                                <geom type="mesh" contype="0" conaffinity="0" group="1" density="0"
                                  rgba="0 0 0 0" mesh="r_ih_c_right_pinky_intermediate"/>
                                <geom type="mesh" rgba="0 0 0 0" mesh="r_ih_c_right_pinky_intermediate"/>
                              </body>
                            </body>
                          </body>
                          <!-- ===== END RIGHT INSPIRE HAND ===== -->

                        </body>
                      </body>
                    </body>
                  </body>
                </body>
              </body>
            </body>
          </body>
        </body>
      </body>
    </body>
  </worldbody>

  <!-- ================================================================ -->
  <!-- Mimic joint equality constraints (from URDF <mimic> elements)    -->
  <!-- joint2 = polycoef[0] + polycoef[1]*joint1                        -->
  <!-- ================================================================ -->
  <equality>
    <!-- Left hand thumb coupling -->
    <joint joint1="l_ih_thumb_proximal_pitch" joint2="l_ih_thumb_intermediate"
      polycoef="0 1.334 0 0 0" solref="0.02 1" solimp="0.9 0.95 0.001"/>
    <joint joint1="l_ih_thumb_proximal_pitch" joint2="l_ih_thumb_distal"
      polycoef="0 0.667 0 0 0" solref="0.02 1" solimp="0.9 0.95 0.001"/>
    <!-- Left hand finger coupling (proximal drives intermediate) -->
    <joint joint1="l_ih_index_proximal" joint2="l_ih_index_intermediate"
      polycoef="-0.04545 1.06399 0 0 0" solref="0.02 1" solimp="0.9 0.95 0.001"/>
    <joint joint1="l_ih_middle_proximal" joint2="l_ih_middle_intermediate"
      polycoef="-0.04545 1.06399 0 0 0" solref="0.02 1" solimp="0.9 0.95 0.001"/>
    <joint joint1="l_ih_ring_proximal" joint2="l_ih_ring_intermediate"
      polycoef="-0.04545 1.06399 0 0 0" solref="0.02 1" solimp="0.9 0.95 0.001"/>
    <joint joint1="l_ih_pinky_proximal" joint2="l_ih_pinky_intermediate"
      polycoef="-0.04545 1.06399 0 0 0" solref="0.02 1" solimp="0.9 0.95 0.001"/>

    <!-- Right hand thumb coupling -->
    <joint joint1="r_ih_thumb_proximal_pitch" joint2="r_ih_thumb_intermediate"
      polycoef="0 1.334 0 0 0" solref="0.02 1" solimp="0.9 0.95 0.001"/>
    <joint joint1="r_ih_thumb_proximal_pitch" joint2="r_ih_thumb_distal"
      polycoef="0 0.667 0 0 0" solref="0.02 1" solimp="0.9 0.95 0.001"/>
    <!-- Right hand finger coupling -->
    <joint joint1="r_ih_index_proximal" joint2="r_ih_index_intermediate"
      polycoef="-0.04545 1.06399 0 0 0" solref="0.02 1" solimp="0.9 0.95 0.001"/>
    <joint joint1="r_ih_middle_proximal" joint2="r_ih_middle_intermediate"
      polycoef="-0.04545 1.06399 0 0 0" solref="0.02 1" solimp="0.9 0.95 0.001"/>
    <joint joint1="r_ih_ring_proximal" joint2="r_ih_ring_intermediate"
      polycoef="-0.04545 1.06399 0 0 0" solref="0.02 1" solimp="0.9 0.95 0.001"/>
    <joint joint1="r_ih_pinky_proximal" joint2="r_ih_pinky_intermediate"
      polycoef="-0.04545 1.06399 0 0 0" solref="0.02 1" solimp="0.9 0.95 0.001"/>
  </equality>

  <actuator>
    <!-- Legs -->
    <motor name="left_hip_pitch" joint="left_hip_pitch_joint" ctrlrange="-88 88" />
    <motor name="left_hip_roll" joint="left_hip_roll_joint" ctrlrange="-88 88" />
    <motor name="left_hip_yaw" joint="left_hip_yaw_joint" ctrlrange="-88 88" />
    <motor name="left_knee" joint="left_knee_joint" ctrlrange="-139 139" />
    <motor name="left_ankle_pitch" joint="left_ankle_pitch_joint" ctrlrange="-50 50" />
    <motor name="left_ankle_roll" joint="left_ankle_roll_joint" ctrlrange="-50 50" />

    <motor name="right_hip_pitch" joint="right_hip_pitch_joint" ctrlrange="-88 88" />
    <motor name="right_hip_roll" joint="right_hip_roll_joint" ctrlrange="-88 88" />
    <motor name="right_hip_yaw" joint="right_hip_yaw_joint" ctrlrange="-88 88" />
    <motor name="right_knee" joint="right_knee_joint" ctrlrange="-139 139" />
    <motor name="right_ankle_pitch" joint="right_ankle_pitch_joint" ctrlrange="-50 50" />
    <motor name="right_ankle_roll" joint="right_ankle_roll_joint" ctrlrange="-50 50" />

    <!-- Waist -->
    <motor name="waist_yaw" joint="waist_yaw_joint" ctrlrange="-88 88" />
    <motor name="waist_roll" joint="waist_roll_joint" ctrlrange="-50 50" />
    <motor name="waist_pitch" joint="waist_pitch_joint" ctrlrange="-50 50" />

    <!-- Left arm -->
    <motor name="left_shoulder_pitch" joint="left_shoulder_pitch_joint" ctrlrange="-25 25" />
    <motor name="left_shoulder_roll" joint="left_shoulder_roll_joint" ctrlrange="-25 25" />
    <motor name="left_shoulder_yaw" joint="left_shoulder_yaw_joint" ctrlrange="-25 25" />
    <motor name="left_elbow" joint="left_elbow_joint" ctrlrange="-25 25" />
    <motor name="left_wrist_roll" joint="left_wrist_roll_joint" ctrlrange="-25 25" />
    <motor name="left_wrist_pitch" joint="left_wrist_pitch_joint" ctrlrange="-5 5" />
    <motor name="left_wrist_yaw" joint="left_wrist_yaw_joint" ctrlrange="-5 5" />

    <!-- Left Inspire Hand (6 actuated DOF: thumb yaw + pitch, index/middle/ring/pinky proximal) -->
    <motor name="l_ih_thumb_proximal_yaw"   joint="l_ih_thumb_proximal_yaw"   ctrlrange="-1 1" />
    <motor name="l_ih_thumb_proximal_pitch" joint="l_ih_thumb_proximal_pitch" ctrlrange="-1 1" />
    <motor name="l_ih_index_proximal"       joint="l_ih_index_proximal"       ctrlrange="-1 1" />
    <motor name="l_ih_middle_proximal"      joint="l_ih_middle_proximal"      ctrlrange="-1 1" />
    <motor name="l_ih_ring_proximal"        joint="l_ih_ring_proximal"        ctrlrange="-1 1" />
    <motor name="l_ih_pinky_proximal"       joint="l_ih_pinky_proximal"       ctrlrange="-1 1" />

    <!-- Right arm -->
    <motor name="right_shoulder_pitch" joint="right_shoulder_pitch_joint" ctrlrange="-25 25" />
    <motor name="right_shoulder_roll" joint="right_shoulder_roll_joint" ctrlrange="-25 25" />
    <motor name="right_shoulder_yaw" joint="right_shoulder_yaw_joint" ctrlrange="-25 25" />
    <motor name="right_elbow" joint="right_elbow_joint" ctrlrange="-25 25" />
    <motor name="right_wrist_roll" joint="right_wrist_roll_joint" ctrlrange="-25 25" />
    <motor name="right_wrist_pitch" joint="right_wrist_pitch_joint" ctrlrange="-5 5" />
    <motor name="right_wrist_yaw" joint="right_wrist_yaw_joint" ctrlrange="-5 5" />

    <!-- Right Inspire Hand (6 actuated DOF) -->
    <motor name="r_ih_thumb_proximal_yaw"   joint="r_ih_thumb_proximal_yaw"   ctrlrange="-1 1" />
    <motor name="r_ih_thumb_proximal_pitch" joint="r_ih_thumb_proximal_pitch" ctrlrange="-1 1" />
    <motor name="r_ih_index_proximal"       joint="r_ih_index_proximal"       ctrlrange="-1 1" />
    <motor name="r_ih_middle_proximal"      joint="r_ih_middle_proximal"      ctrlrange="-1 1" />
    <motor name="r_ih_ring_proximal"        joint="r_ih_ring_proximal"        ctrlrange="-1 1" />
    <motor name="r_ih_pinky_proximal"       joint="r_ih_pinky_proximal"       ctrlrange="-1 1" />
  </actuator>

  <sensor>
    <!-- Legs -->
    <jointpos name="left_hip_pitch_pos" joint="left_hip_pitch_joint" />
    <jointpos name="left_hip_roll_pos" joint="left_hip_roll_joint" />
    <jointpos name="left_hip_yaw_pos" joint="left_hip_yaw_joint" />
    <jointpos name="left_knee_pos" joint="left_knee_joint" />
    <jointpos name="left_ankle_pitch_pos" joint="left_ankle_pitch_joint" />
    <jointpos name="left_ankle_roll_pos" joint="left_ankle_roll_joint" />
    <jointpos name="right_hip_pitch_pos" joint="right_hip_pitch_joint" />
    <jointpos name="right_hip_roll_pos" joint="right_hip_roll_joint" />
    <jointpos name="right_hip_yaw_pos" joint="right_hip_yaw_joint" />
    <jointpos name="right_knee_pos" joint="right_knee_joint" />
    <jointpos name="right_ankle_pitch_pos" joint="right_ankle_pitch_joint" />
    <jointpos name="right_ankle_roll_pos" joint="right_ankle_roll_joint" />
    <!-- Waist -->
    <jointpos name="waist_yaw_pos" joint="waist_yaw_joint" />
    <jointpos name="waist_roll_pos" joint="waist_roll_joint" />
    <jointpos name="waist_pitch_pos" joint="waist_pitch_joint" />
    <!-- Left arm -->
    <jointpos name="left_shoulder_pitch_pos" joint="left_shoulder_pitch_joint" />
    <jointpos name="left_shoulder_roll_pos" joint="left_shoulder_roll_joint" />
    <jointpos name="left_shoulder_yaw_pos" joint="left_shoulder_yaw_joint" />
    <jointpos name="left_elbow_pos" joint="left_elbow_joint" />
    <jointpos name="left_wrist_roll_pos" joint="left_wrist_roll_joint" />
    <jointpos name="left_wrist_pitch_pos" joint="left_wrist_pitch_joint" />
    <jointpos name="left_wrist_yaw_pos" joint="left_wrist_yaw_joint" />
    <!-- Left hand -->
    <jointpos name="l_ih_thumb_yaw_pos"    joint="l_ih_thumb_proximal_yaw" />
    <jointpos name="l_ih_thumb_pitch_pos"  joint="l_ih_thumb_proximal_pitch" />
    <jointpos name="l_ih_index_pos"        joint="l_ih_index_proximal" />
    <jointpos name="l_ih_middle_pos"       joint="l_ih_middle_proximal" />
    <jointpos name="l_ih_ring_pos"         joint="l_ih_ring_proximal" />
    <jointpos name="l_ih_pinky_pos"        joint="l_ih_pinky_proximal" />
    <!-- Right arm -->
    <jointpos name="right_shoulder_pitch_pos" joint="right_shoulder_pitch_joint" />
    <jointpos name="right_shoulder_roll_pos" joint="right_shoulder_roll_joint" />
    <jointpos name="right_shoulder_yaw_pos" joint="right_shoulder_yaw_joint" />
    <jointpos name="right_elbow_pos" joint="right_elbow_joint" />
    <jointpos name="right_wrist_roll_pos" joint="right_wrist_roll_joint" />
    <jointpos name="right_wrist_pitch_pos" joint="right_wrist_pitch_joint" />
    <jointpos name="right_wrist_yaw_pos" joint="right_wrist_yaw_joint" />
    <!-- Right hand -->
    <jointpos name="r_ih_thumb_yaw_pos"    joint="r_ih_thumb_proximal_yaw" />
    <jointpos name="r_ih_thumb_pitch_pos"  joint="r_ih_thumb_proximal_pitch" />
    <jointpos name="r_ih_index_pos"        joint="r_ih_index_proximal" />
    <jointpos name="r_ih_middle_pos"       joint="r_ih_middle_proximal" />
    <jointpos name="r_ih_ring_pos"         joint="r_ih_ring_proximal" />
    <jointpos name="r_ih_pinky_pos"        joint="r_ih_pinky_proximal" />

    <!-- Velocities -->
    <jointvel name="left_hip_pitch_vel" joint="left_hip_pitch_joint" />
    <jointvel name="left_hip_roll_vel" joint="left_hip_roll_joint" />
    <jointvel name="left_hip_yaw_vel" joint="left_hip_yaw_joint" />
    <jointvel name="left_knee_vel" joint="left_knee_joint" />
    <jointvel name="left_ankle_pitch_vel" joint="left_ankle_pitch_joint" />
    <jointvel name="left_ankle_roll_vel" joint="left_ankle_roll_joint" />
    <jointvel name="right_hip_pitch_vel" joint="right_hip_pitch_joint" />
    <jointvel name="right_hip_roll_vel" joint="right_hip_roll_joint" />
    <jointvel name="right_hip_yaw_vel" joint="right_hip_yaw_joint" />
    <jointvel name="right_knee_vel" joint="right_knee_joint" />
    <jointvel name="right_ankle_pitch_vel" joint="right_ankle_pitch_joint" />
    <jointvel name="right_ankle_roll_vel" joint="right_ankle_roll_joint" />
    <jointvel name="waist_yaw_vel" joint="waist_yaw_joint" />
    <jointvel name="waist_roll_vel" joint="waist_roll_joint" />
    <jointvel name="waist_pitch_vel" joint="waist_pitch_joint" />
    <jointvel name="left_shoulder_pitch_vel" joint="left_shoulder_pitch_joint" />
    <jointvel name="left_shoulder_roll_vel" joint="left_shoulder_roll_joint" />
    <jointvel name="left_shoulder_yaw_vel" joint="left_shoulder_yaw_joint" />
    <jointvel name="left_elbow_vel" joint="left_elbow_joint" />
    <jointvel name="left_wrist_roll_vel" joint="left_wrist_roll_joint" />
    <jointvel name="left_wrist_pitch_vel" joint="left_wrist_pitch_joint" />
    <jointvel name="left_wrist_yaw_vel" joint="left_wrist_yaw_joint" />
    <jointvel name="l_ih_thumb_yaw_vel"    joint="l_ih_thumb_proximal_yaw" />
    <jointvel name="l_ih_thumb_pitch_vel"  joint="l_ih_thumb_proximal_pitch" />
    <jointvel name="l_ih_index_vel"        joint="l_ih_index_proximal" />
    <jointvel name="l_ih_middle_vel"       joint="l_ih_middle_proximal" />
    <jointvel name="l_ih_ring_vel"         joint="l_ih_ring_proximal" />
    <jointvel name="l_ih_pinky_vel"        joint="l_ih_pinky_proximal" />
    <jointvel name="right_shoulder_pitch_vel" joint="right_shoulder_pitch_joint" />
    <jointvel name="right_shoulder_roll_vel" joint="right_shoulder_roll_joint" />
    <jointvel name="right_shoulder_yaw_vel" joint="right_shoulder_yaw_joint" />
    <jointvel name="right_elbow_vel" joint="right_elbow_joint" />
    <jointvel name="right_wrist_roll_vel" joint="right_wrist_roll_joint" />
    <jointvel name="right_wrist_pitch_vel" joint="right_wrist_pitch_joint" />
    <jointvel name="right_wrist_yaw_vel" joint="right_wrist_yaw_joint" />
    <jointvel name="r_ih_thumb_yaw_vel"    joint="r_ih_thumb_proximal_yaw" />
    <jointvel name="r_ih_thumb_pitch_vel"  joint="r_ih_thumb_proximal_pitch" />
    <jointvel name="r_ih_index_vel"        joint="r_ih_index_proximal" />
    <jointvel name="r_ih_middle_vel"       joint="r_ih_middle_proximal" />
    <jointvel name="r_ih_ring_vel"         joint="r_ih_ring_proximal" />
    <jointvel name="r_ih_pinky_vel"        joint="r_ih_pinky_proximal" />

    <!-- Torques -->
    <jointactuatorfrc name="left_hip_pitch_torque" joint="left_hip_pitch_joint" />
    <jointactuatorfrc name="left_hip_roll_torque" joint="left_hip_roll_joint" />
    <jointactuatorfrc name="left_hip_yaw_torque" joint="left_hip_yaw_joint" />
    <jointactuatorfrc name="left_knee_torque" joint="left_knee_joint" />
    <jointactuatorfrc name="left_ankle_pitch_torque" joint="left_ankle_pitch_joint" />
    <jointactuatorfrc name="left_ankle_roll_torque" joint="left_ankle_roll_joint" />
    <jointactuatorfrc name="right_hip_pitch_torque" joint="right_hip_pitch_joint" />
    <jointactuatorfrc name="right_hip_roll_torque" joint="right_hip_roll_joint" />
    <jointactuatorfrc name="right_hip_yaw_torque" joint="right_hip_yaw_joint" />
    <jointactuatorfrc name="right_knee_torque" joint="right_knee_joint" />
    <jointactuatorfrc name="right_ankle_pitch_torque" joint="right_ankle_pitch_joint" />
    <jointactuatorfrc name="right_ankle_roll_torque" joint="right_ankle_roll_joint" />
    <jointactuatorfrc name="waist_yaw_torque" joint="waist_yaw_joint" />
    <jointactuatorfrc name="waist_roll_torque" joint="waist_roll_joint" />
    <jointactuatorfrc name="waist_pitch_torque" joint="waist_pitch_joint" />
    <jointactuatorfrc name="left_shoulder_pitch_torque" joint="left_shoulder_pitch_joint" />
    <jointactuatorfrc name="left_shoulder_roll_torque" joint="left_shoulder_roll_joint" />
    <jointactuatorfrc name="left_shoulder_yaw_torque" joint="left_shoulder_yaw_joint" />
    <jointactuatorfrc name="left_elbow_torque" joint="left_elbow_joint" />
    <jointactuatorfrc name="left_wrist_roll_torque" joint="left_wrist_roll_joint" />
    <jointactuatorfrc name="left_wrist_pitch_torque" joint="left_wrist_pitch_joint" />
    <jointactuatorfrc name="left_wrist_yaw_torque" joint="left_wrist_yaw_joint" />
    <jointactuatorfrc name="l_ih_thumb_yaw_torque"    joint="l_ih_thumb_proximal_yaw" />
    <jointactuatorfrc name="l_ih_thumb_pitch_torque"  joint="l_ih_thumb_proximal_pitch" />
    <jointactuatorfrc name="l_ih_index_torque"        joint="l_ih_index_proximal" />
    <jointactuatorfrc name="l_ih_middle_torque"       joint="l_ih_middle_proximal" />
    <jointactuatorfrc name="l_ih_ring_torque"         joint="l_ih_ring_proximal" />
    <jointactuatorfrc name="l_ih_pinky_torque"        joint="l_ih_pinky_proximal" />
    <jointactuatorfrc name="right_shoulder_pitch_torque" joint="right_shoulder_pitch_joint" />
    <jointactuatorfrc name="right_shoulder_roll_torque" joint="right_shoulder_roll_joint" />
    <jointactuatorfrc name="right_shoulder_yaw_torque" joint="right_shoulder_yaw_joint" />
    <jointactuatorfrc name="right_elbow_torque" joint="right_elbow_joint" />
    <jointactuatorfrc name="right_wrist_roll_torque" joint="right_wrist_roll_joint" />
    <jointactuatorfrc name="right_wrist_pitch_torque" joint="right_wrist_pitch_joint" />
    <jointactuatorfrc name="right_wrist_yaw_torque" joint="right_wrist_yaw_joint" />
    <jointactuatorfrc name="r_ih_thumb_yaw_torque"    joint="r_ih_thumb_proximal_yaw" />
    <jointactuatorfrc name="r_ih_thumb_pitch_torque"  joint="r_ih_thumb_proximal_pitch" />
    <jointactuatorfrc name="r_ih_index_torque"        joint="r_ih_index_proximal" />
    <jointactuatorfrc name="r_ih_middle_torque"       joint="r_ih_middle_proximal" />
    <jointactuatorfrc name="r_ih_ring_torque"         joint="r_ih_ring_proximal" />
    <jointactuatorfrc name="r_ih_pinky_torque"        joint="r_ih_pinky_proximal" />

    <!-- IMU -->
    <framequat name="imu_quat" objtype="site" objname="imu" />
    <gyro name="imu_gyro" site="imu" />
    <accelerometer name="imu_acc" site="imu" />
    <framepos name="frame_pos" objtype="site" objname="imu" />
    <framelinvel name="frame_vel" objtype="site" objname="imu" />
  </sensor>
</mujoco>
