<mujoco model="g1_29dof_inspire_hand">
  <!--
    Unitree G1 (29 DOF body) with Inspire Hands (6 actuated DOF per hand).
    Inspire hand meshes and kinematics use RH56F1 assets from robot_hand_manager/etc/URDF.
    Mimic joints are handled via MuJoCo equality constraints.

    Hand attachment frame (both sides):
      euler="0 1.5708 0" matches the G1 RH56F1 URDF mount.
      Adjust wrist_roll/pitch/yaw to orient palm as desired.
  -->
  <compiler angle="radian" meshdir="meshes" />

  <default>
    <default class="g1">
      <position kp="500" dampratio="1" inheritrange="1" />
    </default>
    <default class="torso_motor">
      <joint damping="0.05" armature="0.01" frictionloss="0.2"/>
    </default>
    <default class="leg_motor">
      <joint damping="0.05" armature="0.01" frictionloss="0.2"/>
    </default>
    <default class="ankle_motor">
      <joint damping="0.05" armature="0.01" frictionloss="0.2"/>
    </default>
    <default class="arm_motor">
      <joint damping="0.05" armature="0.01" frictionloss="0.2"/>
    </default>
    <default class="wrist_motor">
      <joint damping="0.05" armature="0.01" frictionloss="0.1"/>
    </default>
    <default class="finger_motor">
      <joint damping="0.02" armature="0.005" frictionloss="0.05"/>
    </default>
  </default>

  <asset>
    <!-- G1 body meshes -->
    <mesh name="pelvis" file="pelvis.STL" />
    <mesh name="pelvis_contour_link" file="pelvis_contour_link.STL" />
    <mesh name="left_hip_pitch_link" file="left_hip_pitch_link.STL" />
    <mesh name="left_hip_roll_link" file="left_hip_roll_link.STL" />
    <mesh name="left_hip_yaw_link" file="left_hip_yaw_link.STL" />
    <mesh name="left_knee_link" file="left_knee_link.STL" />
    <mesh name="left_ankle_pitch_link" file="left_ankle_pitch_link.STL" />
    <mesh name="left_ankle_roll_link" file="left_ankle_roll_link.STL" />
    <mesh name="right_hip_pitch_link" file="right_hip_pitch_link.STL" />
    <mesh name="right_hip_roll_link" file="right_hip_roll_link.STL" />
    <mesh name="right_hip_yaw_link" file="right_hip_yaw_link.STL" />
    <mesh name="right_knee_link" file="right_knee_link.STL" />
    <mesh name="right_ankle_pitch_link" file="right_ankle_pitch_link.STL" />
    <mesh name="right_ankle_roll_link" file="right_ankle_roll_link.STL" />
    <mesh name="waist_yaw_link" file="waist_yaw_link.STL" />
    <mesh name="waist_roll_link" file="waist_roll_link.STL" />
    <mesh name="torso_link" file="torso_link.STL" />
    <mesh name="logo_link" file="logo_link.STL" />
    <mesh name="head_link" file="head_link.STL" />
    <mesh name="waist_support_link" file="waist_support_link.STL" />
    <mesh name="left_shoulder_pitch_link" file="left_shoulder_pitch_link.STL" />
    <mesh name="left_shoulder_roll_link" file="left_shoulder_roll_link.STL" />
    <mesh name="left_shoulder_yaw_link" file="left_shoulder_yaw_link.STL" />
    <mesh name="left_elbow_link" file="left_elbow_link.STL" />
    <mesh name="left_wrist_roll_link" file="left_wrist_roll_link.STL" />
    <mesh name="left_wrist_pitch_link" file="left_wrist_pitch_link.STL" />
    <mesh name="left_wrist_yaw_link" file="left_wrist_yaw_link.STL" />
    <mesh name="right_shoulder_pitch_link" file="right_shoulder_pitch_link.STL" />
    <mesh name="right_shoulder_roll_link" file="right_shoulder_roll_link.STL" />
    <mesh name="right_shoulder_yaw_link" file="right_shoulder_yaw_link.STL" />
    <mesh name="right_elbow_link" file="right_elbow_link.STL" />
    <mesh name="right_wrist_roll_link" file="right_wrist_roll_link.STL" />
    <mesh name="right_wrist_pitch_link" file="right_wrist_pitch_link.STL" />
    <mesh name="right_wrist_yaw_link" file="right_wrist_yaw_link.STL" />


    <!-- RH56F1 Inspire Hand meshes from robot_hand_manager/etc/URDF. -->
    <mesh name="rh56f1_l_base_link" content_type="model/stl" file="inspire_hand/RH56F1_L/base_link.STL"/>
    <mesh name="rh56f1_l_left_thumb_1" content_type="model/stl" file="inspire_hand/RH56F1_L/left_thumb_1.STL"/>
    <mesh name="rh56f1_l_left_thumb_2" content_type="model/stl" file="inspire_hand/RH56F1_L/left_thumb_2.STL"/>
    <mesh name="rh56f1_l_left_thumb_3" content_type="model/stl" file="inspire_hand/RH56F1_L/left_thumb_3.STL"/>
    <mesh name="rh56f1_l_left_thumb_4" content_type="model/stl" file="inspire_hand/RH56F1_L/left_thumb_4.STL"/>
    <mesh name="rh56f1_l_thumb_force_sensor" content_type="model/stl" file="inspire_hand/RH56F1_L/thumb_force_sensor.STL"/>
    <mesh name="rh56f1_l_thumb_tip" content_type="model/stl" file="inspire_hand/RH56F1_L/thumb_tip.STL"/>
    <mesh name="rh56f1_l_left_index_1" content_type="model/stl" file="inspire_hand/RH56F1_L/left_index_1.STL"/>
    <mesh name="rh56f1_l_left_index_2" content_type="model/stl" file="inspire_hand/RH56F1_L/left_index_2.STL"/>
    <mesh name="rh56f1_l_index_force_sensor" content_type="model/stl" file="inspire_hand/RH56F1_L/index_force_sensor.STL"/>
    <mesh name="rh56f1_l_index_tip" content_type="model/stl" file="inspire_hand/RH56F1_L/index_tip.STL"/>
    <mesh name="rh56f1_l_left_middle_1" content_type="model/stl" file="inspire_hand/RH56F1_L/left_middle_1.STL"/>
    <mesh name="rh56f1_l_left_middle_2" content_type="model/stl" file="inspire_hand/RH56F1_L/left_middle_2.STL"/>
    <mesh name="rh56f1_l_middle_force_sensor" content_type="model/stl" file="inspire_hand/RH56F1_L/middle_force_sensor.STL"/>
    <mesh name="rh56f1_l_middle_tip" content_type="model/stl" file="inspire_hand/RH56F1_L/middle_tip.STL"/>
    <mesh name="rh56f1_l_left_ring_1" content_type="model/stl" file="inspire_hand/RH56F1_L/left_ring_1.STL"/>
    <mesh name="rh56f1_l_left_ring_2" content_type="model/stl" file="inspire_hand/RH56F1_L/left_ring_2.STL"/>
    <mesh name="rh56f1_l_ring_force_sensor" content_type="model/stl" file="inspire_hand/RH56F1_L/ring_force_sensor.STL"/>
    <mesh name="rh56f1_l_ring_tip" content_type="model/stl" file="inspire_hand/RH56F1_L/ring_tip.STL"/>
    <mesh name="rh56f1_l_left_little_1" content_type="model/stl" file="inspire_hand/RH56F1_L/left_little_1.STL"/>
    <mesh name="rh56f1_l_left_little_2" content_type="model/stl" file="inspire_hand/RH56F1_L/left_little_2.STL"/>
    <mesh name="rh56f1_l_little_force_sensor" content_type="model/stl" file="inspire_hand/RH56F1_L/little_force_sensor.STL"/>
    <mesh name="rh56f1_l_little_tip" content_type="model/stl" file="inspire_hand/RH56F1_L/little_tip.STL"/>
    <mesh name="rh56f1_l_plam_1" content_type="model/stl" file="inspire_hand/RH56F1_L/plam_1.STL"/>
    <mesh name="rh56f1_l_plam_2" content_type="model/stl" file="inspire_hand/RH56F1_L/plam_2.STL"/>
    <mesh name="rh56f1_l_plam_3" content_type="model/stl" file="inspire_hand/RH56F1_L/plam_3.STL"/>
    <mesh name="rh56f1_l_plam_force_sensor" content_type="model/stl" file="inspire_hand/RH56F1_L/plam_force_sensor.STL"/>
    <mesh name="rh56f1_r_base_link" content_type="model/stl" file="inspire_hand/RH56F1_R/base_link.STL"/>
    <mesh name="rh56f1_r_plam_1" content_type="model/stl" file="inspire_hand/RH56F1_R/plam_1.STL"/>
    <mesh name="rh56f1_r_plam_2" content_type="model/stl" file="inspire_hand/RH56F1_R/plam_2.STL"/>
    <mesh name="rh56f1_r_plam_3" content_type="model/stl" file="inspire_hand/RH56F1_R/plam_3.STL"/>
    <mesh name="rh56f1_r_plam_force_sensor" content_type="model/stl" file="inspire_hand/RH56F1_R/plam_force_sensor.STL"/>
    <mesh name="rh56f1_r_right_thumb_1" content_type="model/stl" file="inspire_hand/RH56F1_R/right_thumb_1.STL"/>
    <mesh name="rh56f1_r_right_thumb_2" content_type="model/stl" file="inspire_hand/RH56F1_R/right_thumb_2.STL"/>
    <mesh name="rh56f1_r_right_thumb_3" content_type="model/stl" file="inspire_hand/RH56F1_R/right_thumb_3.STL"/>
    <mesh name="rh56f1_r_right_thumb_4" content_type="model/stl" file="inspire_hand/RH56F1_R/right_thumb_4.STL"/>
    <mesh name="rh56f1_r_thumb_force_sensor" content_type="model/stl" file="inspire_hand/RH56F1_R/thumb_force_sensor.STL"/>
    <mesh name="rh56f1_r_thumb_tip" content_type="model/stl" file="inspire_hand/RH56F1_R/thumb_tip.STL"/>
    <mesh name="rh56f1_r_right_index_1" content_type="model/stl" file="inspire_hand/RH56F1_R/right_index_1.STL"/>
    <mesh name="rh56f1_r_right_index_2" content_type="model/stl" file="inspire_hand/RH56F1_R/right_index_2.STL"/>
    <mesh name="rh56f1_r_index_force_sensor" content_type="model/stl" file="inspire_hand/RH56F1_R/index_force_sensor.STL"/>
    <mesh name="rh56f1_r_index_tip" content_type="model/stl" file="inspire_hand/RH56F1_R/index_tip.STL"/>
    <mesh name="rh56f1_r_right_middle_1" content_type="model/stl" file="inspire_hand/RH56F1_R/right_middle_1.STL"/>
    <mesh name="rh56f1_r_right_middle_2" content_type="model/stl" file="inspire_hand/RH56F1_R/right_middle_2.STL"/>
    <mesh name="rh56f1_r_middle_force_sensor" content_type="model/stl" file="inspire_hand/RH56F1_R/middle_force_sensor.STL"/>
    <mesh name="rh56f1_r_middle_tip" content_type="model/stl" file="inspire_hand/RH56F1_R/middle_tip.STL"/>
    <mesh name="rh56f1_r_right_ring_1" content_type="model/stl" file="inspire_hand/RH56F1_R/right_ring_1.STL"/>
    <mesh name="rh56f1_r_right_ring_2" content_type="model/stl" file="inspire_hand/RH56F1_R/right_ring_2.STL"/>
    <mesh name="rh56f1_r_ring_force_sensor" content_type="model/stl" file="inspire_hand/RH56F1_R/ring_force_sensor.STL"/>
    <mesh name="rh56f1_r_ring_tip" content_type="model/stl" file="inspire_hand/RH56F1_R/ring_tip.STL"/>
    <mesh name="rh56f1_r_right_little_1" content_type="model/stl" file="inspire_hand/RH56F1_R/right_little_1.STL"/>
    <mesh name="rh56f1_r_right_little_2" content_type="model/stl" file="inspire_hand/RH56F1_R/right_little_2.STL"/>
    <mesh name="rh56f1_r_little_force_sensor" content_type="model/stl" file="inspire_hand/RH56F1_R/little_force_sensor.STL"/>
    <mesh name="rh56f1_r_little_tip" content_type="model/stl" file="inspire_hand/RH56F1_R/little_tip.STL"/>
  </asset>

  <worldbody>
    <light pos="1 0 3.5" dir="0 0 -1" directional="true"/>
    <body name="pelvis" pos="0 0 0.793">
      <inertial pos="0 0 -0.07605" quat="1 0 -0.000399148 0" mass="3.813"
        diaginertia="0.010549 0.0093089 0.0079184" />
      <joint name="floating_base_joint" type="free" limited="false" actuatorfrclimited="false" />
      <geom type="mesh" contype="0" conaffinity="0" group="1" density="0" rgba="0.2 0.2 0.2 1"
        mesh="pelvis" />
      <geom type="mesh" contype="0" conaffinity="0" group="1" density="0" rgba="0.7 0.7 0.7 1"
        mesh="pelvis_contour_link" />
      <geom type="mesh" rgba="0.7 0.7 0.7 1" mesh="pelvis_contour_link" />
      <body name="left_hip_pitch_link" pos="0 0.064452 -0.1027">
        <inertial pos="0.002741 0.047791 -0.02606" quat="0.954862 0.293964 0.0302556 0.030122"
          mass="1.35" diaginertia="0.00181517 0.00153422 0.00116212" />
        <joint name="left_hip_pitch_joint" pos="0 0 0" axis="0 1 0" range="-2.5307 2.8798"
          actuatorfrcrange="-88 88" class="leg_motor" />
        <geom type="mesh" contype="0" conaffinity="0" group="1" density="0" rgba="0.2 0.2 0.2 1"
          mesh="left_hip_pitch_link" />
        <geom type="mesh" rgba="0.2 0.2 0.2 1" mesh="left_hip_pitch_link" />
        <body name="left_hip_roll_link" pos="0 0.052 -0.030465" quat="0.996179 0 -0.0873386 0">
          <inertial pos="0.029812 -0.001045 -0.087934"
            quat="0.977808 -1.97119e-05 0.205576 -0.0403793" mass="1.52"
            diaginertia="0.00254986 0.00241169 0.00148755" />
          <joint name="left_hip_roll_joint" pos="0 0 0" axis="1 0 0" range="-0.5236 2.9671"
            actuatorfrcrange="-88 88" class="leg_motor" />
          <geom type="mesh" contype="0" conaffinity="0" group="1" density="0" rgba="0.7 0.7 0.7 1"
            mesh="left_hip_roll_link" />
          <geom type="mesh" rgba="0.7 0.7 0.7 1" mesh="left_hip_roll_link" />
          <body name="left_hip_yaw_link" pos="0.025001 0 -0.12412">
            <inertial pos="-0.057709 -0.010981 -0.15078" quat="0.600598 0.15832 0.223482 0.751181"
              mass="1.702" diaginertia="0.00776166 0.00717575 0.00160139" />
            <joint name="left_hip_yaw_joint" pos="0 0 0" axis="0 0 1" range="-2.7576 2.7576"
              actuatorfrcrange="-88 88" class="leg_motor" />
            <geom type="mesh" contype="0" conaffinity="0" group="1" density="0" rgba="0.7 0.7 0.7 1"
              mesh="left_hip_yaw_link" />
            <geom type="mesh" rgba="0.7 0.7 0.7 1" mesh="left_hip_yaw_link" />
            <body name="left_knee_link" pos="-0.078273 0.0021489 -0.17734"
              quat="0.996179 0 0.0873386 0">
              <inertial pos="0.005457 0.003964 -0.12074"
                quat="0.923418 -0.0327699 0.0158246 0.382067" mass="1.932"
                diaginertia="0.0113804 0.0112778 0.00146458" />
              <joint name="left_knee_joint" pos="0 0 0" axis="0 1 0" range="-0.087267 2.8798"
                actuatorfrcrange="-139 139" class="leg_motor" />
              <geom type="mesh" contype="0" conaffinity="0" group="1" density="0"
                rgba="0.7 0.7 0.7 1" mesh="left_knee_link" />
              <geom type="mesh" rgba="0.7 0.7 0.7 1" mesh="left_knee_link" />
              <body name="left_ankle_pitch_link" pos="0 -9.4445e-05 -0.30001">
                <inertial pos="-0.007269 0 0.011137" quat="0.603053 0.369225 0.369225 0.603053"
                  mass="0.074" diaginertia="1.89e-05 1.40805e-05 6.9195e-06" />
                <joint name="left_ankle_pitch_joint" pos="0 0 0" axis="0 1 0"
                  range="-0.87267 0.5236" actuatorfrcrange="-50 50" class="ankle_motor" />
                <geom type="mesh" contype="0" conaffinity="0" group="1" density="0"
                  rgba="0.7 0.7 0.7 1" mesh="left_ankle_pitch_link" />
                <geom type="mesh" rgba="0.7 0.7 0.7 1" mesh="left_ankle_pitch_link" />
                <body name="left_ankle_roll_link" pos="0 0 -0.017558">
                  <inertial pos="0.026505 0 -0.016425"
                    quat="-0.000481092 0.728482 -0.000618967 0.685065" mass="0.608"
                    diaginertia="0.00167218 0.0016161 0.000217621" />
                  <joint name="left_ankle_roll_joint" pos="0 0 0" axis="1 0 0"
                    range="-0.2618 0.2618" actuatorfrcrange="-50 50" class="ankle_motor" />
                  <geom type="mesh" contype="0" conaffinity="0" group="1" density="0"
                    rgba="0.2 0.2 0.2 1" mesh="left_ankle_roll_link" />
                  <geom size="0.005" pos="-0.05 0.025 -0.03" rgba="0.2 0.2 0.2 1" />
                  <geom size="0.005" pos="-0.05 -0.025 -0.03" rgba="0.2 0.2 0.2 1" />
                  <geom size="0.005" pos="0.12 0.03 -0.03" rgba="0.2 0.2 0.2 1" />
                  <geom size="0.005" pos="0.12 -0.03 -0.03" rgba="0.2 0.2 0.2 1" />
                </body>
              </body>
            </body>
          </body>
        </body>
      </body>
      <body name="right_hip_pitch_link" pos="0 -0.064452 -0.1027">
        <inertial pos="0.002741 -0.047791 -0.02606" quat="0.954862 -0.293964 0.0302556 -0.030122"
          mass="1.35" diaginertia="0.00181517 0.00153422 0.00116212" />
        <joint name="right_hip_pitch_joint" pos="0 0 0" axis="0 1 0" range="-2.5307 2.8798"
          actuatorfrcrange="-88 88" class="leg_motor" />
        <geom type="mesh" contype="0" conaffinity="0" group="1" density="0" rgba="0.2 0.2 0.2 1"
          mesh="right_hip_pitch_link" />
        <geom type="mesh" rgba="0.2 0.2 0.2 1" mesh="right_hip_pitch_link" />
        <body name="right_hip_roll_link" pos="0 -0.052 -0.030465" quat="0.996179 0 -0.0873386 0">
          <inertial pos="0.029812 0.001045 -0.087934" quat="0.977808 1.97119e-05 0.205576 0.0403793"
            mass="1.52" diaginertia="0.00254986 0.00241169 0.00148755" />
          <joint name="right_hip_roll_joint" pos="0 0 0" axis="1 0 0" range="-2.9671 0.5236"
            actuatorfrcrange="-88 88" class="leg_motor" />
          <geom type="mesh" contype="0" conaffinity="0" group="1" density="0" rgba="0.7 0.7 0.7 1"
            mesh="right_hip_roll_link" />
          <geom type="mesh" rgba="0.7 0.7 0.7 1" mesh="right_hip_roll_link" />
          <body name="right_hip_yaw_link" pos="0.025001 0 -0.12412">
            <inertial pos="-0.057709 0.010981 -0.15078" quat="0.751181 0.223482 0.15832 0.600598"
              mass="1.702" diaginertia="0.00776166 0.00717575 0.00160139" />
            <joint name="right_hip_yaw_joint" pos="0 0 0" axis="0 0 1" range="-2.7576 2.7576"
              actuatorfrcrange="-88 88" class="leg_motor" />
            <geom type="mesh" contype="0" conaffinity="0" group="1" density="0" rgba="0.7 0.7 0.7 1"
              mesh="right_hip_yaw_link" />
            <geom type="mesh" rgba="0.7 0.7 0.7 1" mesh="right_hip_yaw_link" />
            <body name="right_knee_link" pos="-0.078273 -0.0021489 -0.17734"
              quat="0.996179 0 0.0873386 0">
              <inertial pos="0.005457 -0.003964 -0.12074"
                quat="0.923439 0.0345276 0.0116333 -0.382012" mass="1.932"
                diaginertia="0.011374 0.0112843 0.00146452" />
              <joint name="right_knee_joint" pos="0 0 0" axis="0 1 0" range="-0.087267 2.8798"
                actuatorfrcrange="-139 139" class="leg_motor" />
              <geom type="mesh" contype="0" conaffinity="0" group="1" density="0"
                rgba="0.7 0.7 0.7 1" mesh="right_knee_link" />
              <geom type="mesh" rgba="0.7 0.7 0.7 1" mesh="right_knee_link" />
              <body name="right_ankle_pitch_link" pos="0 9.4445e-05 -0.30001">
                <inertial pos="-0.007269 0 0.011137" quat="0.603053 0.369225 0.369225 0.603053"
                  mass="0.074" diaginertia="1.89e-05 1.40805e-05 6.9195e-06" />
                <joint name="right_ankle_pitch_joint" pos="0 0 0" axis="0 1 0"
                  range="-0.87267 0.5236" actuatorfrcrange="-50 50" class="ankle_motor" />
                <geom type="mesh" contype="0" conaffinity="0" group="1" density="0"
                  rgba="0.7 0.7 0.7 1" mesh="right_ankle_pitch_link" />
                <geom type="mesh" rgba="0.7 0.7 0.7 1" mesh="right_ankle_pitch_link" />
                <body name="right_ankle_roll_link" pos="0 0 -0.017558">
                  <inertial pos="0.026505 0 -0.016425"
                    quat="0.000481092 0.728482 0.000618967 0.685065" mass="0.608"
                    diaginertia="0.00167218 0.0016161 0.000217621" />
                  <joint name="right_ankle_roll_joint" pos="0 0 0" axis="1 0 0"
                    range="-0.2618 0.2618" actuatorfrcrange="-50 50" class="ankle_motor" />
                  <geom type="mesh" contype="0" conaffinity="0" group="1" density="0"
                    rgba="0.2 0.2 0.2 1" mesh="right_ankle_roll_link" />
                  <geom size="0.005" pos="-0.05 0.025 -0.03" rgba="0.2 0.2 0.2 1" />
                  <geom size="0.005" pos="-0.05 -0.025 -0.03" rgba="0.2 0.2 0.2 1" />
                  <geom size="0.005" pos="0.12 0.03 -0.03" rgba="0.2 0.2 0.2 1" />
                  <geom size="0.005" pos="0.12 -0.03 -0.03" rgba="0.2 0.2 0.2 1" />
                </body>
              </body>
            </body>
          </body>
        </body>
      </body>
      <body name="waist_yaw_link">
        <inertial pos="0.003964 0 0.018769" quat="-0.0178291 0.628464 0.0282471 0.777121"
          mass="0.244" diaginertia="0.000158561 0.000124229 9.67669e-05" />
        <joint name="waist_yaw_joint" pos="0 0 0" axis="0 0 1" range="-2.618 2.618"
          actuatorfrcrange="-88 88" class="torso_motor" />
        <geom type="mesh" contype="0" conaffinity="0" group="1" density="0" rgba="0.7 0.7 0.7 1"
          mesh="waist_yaw_link" />
        <body name="waist_roll_link" pos="-0.0039635 0 0.035">
          <inertial pos="0 -0.000236 0.010111" quat="0.99979 0.020492 0 0" mass="0.047"
            diaginertia="7.515e-06 6.40206e-06 3.98394e-06" />
          <joint name="waist_roll_joint" pos="0 0 0" axis="1 0 0" range="-0.52 0.52"
            actuatorfrcrange="-50 50" class="torso_motor"/>
          <geom type="mesh" contype="0" conaffinity="0" group="1" density="0" rgba="0.7 0.7 0.7 1"
            mesh="waist_roll_link" />
          <body name="torso_link" pos="0 0 0.019">
            <camera name="head_camera" pos="0.06 0.0 0.45" euler="0 -0.8 -1.57" fovy="90"/>
            <inertial pos="0.00331658 0.000261533 0.179856"
              quat="0.999831 0.000376204 0.0179895 -0.00377704" mass="9.598"
              diaginertia="0.12407 0.111951 0.0325382" />
            <joint name="waist_pitch_joint" pos="0 0 0" axis="0 1 0" range="-0.52 0.52"
              actuatorfrcrange="-50 50" class="torso_motor"/>
            <geom type="mesh" contype="0" conaffinity="0" group="1" density="0" rgba="0.7 0.7 0.7 1"
              mesh="torso_link" />
            <geom type="mesh" rgba="0.7 0.7 0.7 1" mesh="torso_link" />
            <geom pos="0.0039635 0 -0.054" quat="1 0 0 0" type="mesh" contype="0" conaffinity="0"
              group="1" density="0" rgba="0.2 0.2 0.2 1" mesh="logo_link" />
            <geom pos="0.0039635 0 -0.054" quat="1 0 0 0" type="mesh" rgba="0.2 0.2 0.2 1"
              mesh="logo_link" />
            <geom pos="0.0039635 0 -0.054" type="mesh" contype="0" conaffinity="0" group="1"
              density="0" rgba="0.2 0.2 0.2 1" mesh="head_link" />
            <geom pos="0.0039635 0 -0.054" type="mesh" rgba="0.2 0.2 0.2 1" mesh="head_link" />
            <geom pos="0.0039635 0 -0.054" quat="1 0 0 0" type="mesh" contype="0" conaffinity="0"
              group="1" density="0" rgba="0.7 0.7 0.7 1" mesh="waist_support_link" />
            <geom pos="0.0039635 0 -0.054" quat="1 0 0 0" type="mesh" rgba="0.7 0.7 0.7 1"
              mesh="waist_support_link" />
            <site name="imu" size="0.01" pos="-0.03959 -0.00224 0.13792" />
            <!-- ======================== LEFT ARM ======================== -->
            <body name="left_shoulder_pitch_link" pos="0.0039563 0.10022 0.23778"
              quat="0.990264 0.139201 1.38722e-05 -9.86868e-05">
              <inertial pos="0 0.035892 -0.011628" quat="0.654152 0.0130458 -0.326267 0.68225"
                mass="0.718" diaginertia="0.000465864 0.000432842 0.000406394" />
              <joint name="left_shoulder_pitch_joint" pos="0 0 0" axis="0 1 0"
                range="-3.0892 2.6704" actuatorfrcrange="-25 25" class="arm_motor" />
              <geom type="mesh" contype="0" conaffinity="0" group="1" density="0"
                rgba="0.7 0.7 0.7 1" mesh="left_shoulder_pitch_link" />
              <geom size="0.03 0.025" pos="0 0.04 -0.01" quat="0.707107 0 0.707107 0"
                type="cylinder" rgba="0.7 0.7 0.7 1" />
              <body name="left_shoulder_roll_link" pos="0 0.038 -0.013831"
                quat="0.990268 -0.139172 0 0">
                <inertial pos="-0.000227 0.00727 -0.063243"
                  quat="0.701256 -0.0196223 -0.00710317 0.712604" mass="0.643"
                  diaginertia="0.000691311 0.000618011 0.000388977" />
                <joint name="left_shoulder_roll_joint" pos="0 0 0" axis="1 0 0"
                  range="-1.5882 2.2515" actuatorfrcrange="-25 25" class="arm_motor" />
                <geom type="mesh" contype="0" conaffinity="0" group="1" density="0"
                  rgba="0.7 0.7 0.7 1" mesh="left_shoulder_roll_link" />
                <geom size="0.03 0.015" pos="-0.004 0.006 -0.053" type="cylinder"
                  rgba="0.7 0.7 0.7 1" />
                <body name="left_shoulder_yaw_link" pos="0 0.00624 -0.1032">
                  <inertial pos="0.010773 -0.002949 -0.072009"
                    quat="0.716879 -0.0964829 -0.0679942 0.687134" mass="0.734"
                    diaginertia="0.00106187 0.00103217 0.000400661" />
                  <joint name="left_shoulder_yaw_joint" pos="0 0 0" axis="0 0 1"
                    range="-2.618 2.618" actuatorfrcrange="-25 25" class="arm_motor" />
                  <geom type="mesh" contype="0" conaffinity="0" group="1" density="0"
                    rgba="0.7 0.7 0.7 1" mesh="left_shoulder_yaw_link" />
                  <geom type="mesh" rgba="0.7 0.7 0.7 1" mesh="left_shoulder_yaw_link" />
                  <body name="left_elbow_link" pos="0.015783 0 -0.080518">
                    <inertial pos="0.064956 0.004454 -0.010062"
                      quat="0.541765 0.636132 0.388821 0.388129" mass="0.6"
                      diaginertia="0.000443035 0.000421612 0.000259353" />
                    <joint name="left_elbow_joint" pos="0 0 0" axis="0 1 0" range="-1.0472 2.0944"
                      actuatorfrcrange="-25 25" class="arm_motor" />
                    <geom type="mesh" contype="0" conaffinity="0" group="1" density="0"
                      rgba="0.7 0.7 0.7 1" mesh="left_elbow_link" />
                    <geom type="mesh" rgba="0.7 0.7 0.7 1" mesh="left_elbow_link" />
                    <body name="left_wrist_roll_link" pos="0.1 0.00188791 -0.01">
                      <inertial pos="0.0171394 0.000537591 4.8864e-07"
                        quat="0.575338 0.411667 -0.574906 0.411094" mass="0.085445"
                        diaginertia="5.48211e-05 4.96646e-05 3.57798e-05" />
                      <joint name="left_wrist_roll_joint" pos="0 0 0" axis="1 0 0"
                        range="-1.97222 1.97222" actuatorfrcrange="-25 25" class="arm_motor" />
                      <geom type="mesh" contype="0" conaffinity="0" group="1" density="0"
                        rgba="0.7 0.7 0.7 1" mesh="left_wrist_roll_link" />
                      <geom type="mesh" rgba="0.7 0.7 0.7 1" mesh="left_wrist_roll_link" />
                      <body name="left_wrist_pitch_link" pos="0.038 0 0">
                        <inertial pos="0.0229999 -0.00111685 -0.00111658"
                          quat="0.249998 0.661363 0.293036 0.643608" mass="0.48405"
                          diaginertia="0.000430353 0.000429873 0.000164648" />
                        <joint name="left_wrist_pitch_joint" pos="0 0 0" axis="0 1 0"
                          range="-1.61443 1.61443" actuatorfrcrange="-5 5" class="wrist_motor" />
                        <geom type="mesh" contype="0" conaffinity="0" group="1" density="0"
                          rgba="0.7 0.7 0.7 1" mesh="left_wrist_pitch_link" />
                        <geom type="mesh" rgba="0.7 0.7 0.7 1" mesh="left_wrist_pitch_link" />
                        <body name="left_wrist_yaw_link" pos="0.046 0 0">
                          <inertial pos="0.0885506 0.00212216 -0.000374562"
                            quat="0.487149 0.493844 0.513241 0.505358" mass="0.457415"
                            diaginertia="0.00105989 0.000895419 0.000323842" />
                          <joint name="left_wrist_yaw_joint" pos="0 0 0" axis="0 0 1"
                            range="-1.61443 1.61443" actuatorfrcrange="-5 5" class="wrist_motor" />
                          <geom type="mesh" contype="0" conaffinity="0" group="1" density="0"
                            rgba="0.7 0.7 0.7 1" mesh="left_wrist_yaw_link" />
                          <geom type="mesh" rgba="0.7 0.7 0.7 1" mesh="left_wrist_yaw_link" />

                          <!-- ===== LEFT RH56F1 INSPIRE HAND ===== -->
                          <body name="left_hand_base" pos="0.05 0 0" quat="0.70710678119 0 -0.70710678119 0">
                          <body name="left_inspire_base_link">
                            <inertial pos="0.000631583768841232 -4.98983354635385E-11 0.0185710296512339" mass="0.0793945339384899" fullinertia="2.73302961659096E-05 2.62165201865506E-05 3.56824415579562E-05 -1.14020192447604E-12 2.86317776549754E-08 -9.86803596469321E-13" />
                            <geom type="mesh" rgba="1 1 1 1" mesh="rh56f1_l_base_link" contype="0" conaffinity="0" group="1" density="0" />
                            <geom pos="0 0 0.0305" type="mesh" rgba="1 1 1 1" mesh="rh56f1_l_plam_1" contype="0" conaffinity="0" group="1" density="0" />
                            <geom pos="0 0 0.0305" type="mesh" rgba="0.25 0.25 0.25 1" mesh="rh56f1_l_plam_2" contype="0" conaffinity="0" group="1" density="0" />
                            <geom pos="0 0 0.0305" quat="1 0 0 0" type="mesh" rgba="1 1 1 1" mesh="rh56f1_l_plam_3" contype="0" conaffinity="0" group="1" density="0" />
                            <geom pos="0.01594 -0.0013505 0.104246" quat="0.499998 0.5 0.500002 0.5" type="mesh" rgba="0.25 0.25 0.25 1" mesh="rh56f1_l_plam_force_sensor" contype="0" conaffinity="0" group="1" density="0" />
                            <body name="left_thumb_1" pos="0.01836 -0.027241 0.070511">
                              <inertial pos="-0.00015 0.00544 -0.00482" quat="0.743863 0.668146 0.0107013 0.0115653" mass="0.0168" diaginertia="7.34323e-07 5.85437e-07 2.7525e-07" />
                              <joint name="left_thumb_1_joint" pos="0 0 0" axis="8.7274e-05 0 1" range="0 2.0944" actuatorfrcrange="-1 1" class="finger_motor" />
                              <geom type="mesh" rgba="1 1 1 1" mesh="rh56f1_l_left_thumb_1" contype="0" conaffinity="0" group="1" density="0" />
                              <body name="left_thumb_2" pos="0.005034 -0.01349 -0.0049121" quat="0.500023 0.499975 -0.499977 -0.500025">
                                <inertial pos="-0.0238 0.01042 0.00478" quat="0.641808 0.297096 -0.64183 0.296429" mass="0.06526" diaginertia="2.24919e-05 1.88464e-05 6.77592e-06" />
                                <joint name="left_thumb_2_joint" pos="0 0 0" axis="0 0 1" range="0 0.474555" actuatorfrcrange="-1 1" class="finger_motor" />
                                <geom type="mesh" rgba="0.25 0.25 0.25 1" mesh="rh56f1_l_left_thumb_2" contype="0" conaffinity="0" group="1" density="0" />
                                <body name="left_thumb_3" pos="0.033907 0.034601 -0.0029656">
                                  <inertial pos="-0.01255 0.00331 0.00799" quat="0.598698 0.375924 -0.600236 0.374111" mass="0.01333" diaginertia="1.69211e-06 1.49274e-06 1.11195e-06" />
                                  <joint name="left_thumb_3_joint" pos="0 0 0" axis="0 0 1" range="0 3.14" actuatorfrcrange="-1 1" class="finger_motor" />
                                  <geom type="mesh" rgba="0.25 0.25 0.25 1" mesh="rh56f1_l_left_thumb_3" contype="0" conaffinity="0" group="1" density="0" />
                                  <body name="left_thumb_4" pos="0.01441 0.014648 0.0013">
                                    <inertial pos="-0.0102 0.00886 0.0067" quat="0.700656 0.700656 -0.0952978 -0.0952978" mass="0.01144" diaginertia="9.87352e-07 9.4781e-07 3.54518e-07" />
                                    <joint name="left_thumb_4_joint" pos="0 0 0" axis="0 0 1" range="0 3.14" actuatorfrcrange="-1 1" class="finger_motor" />
                                    <geom type="mesh" rgba="0.25 0.25 0.25 1" mesh="rh56f1_l_left_thumb_4" contype="0" conaffinity="0" group="1" density="0" />
                                    <geom pos="0.0082761 0.019128 0.0068" quat="0.260986 0.280713 -0.628925 -0.676417" type="mesh" rgba="0.25 0.25 0.25 1" mesh="rh56f1_l_thumb_force_sensor" contype="0" conaffinity="0" group="1" density="0" />
                                    <geom pos="0.016676 0.025314 0.0067577" quat="0.558607 -0.429663 -0.562322 -0.432598" type="mesh" rgba="0.25 0.25 0.25 1" mesh="rh56f1_l_thumb_tip" contype="0" conaffinity="0" group="1" density="0" />
                                  </body>
                                </body>
                              </body>
                            </body>
                            <body name="left_index_1" pos="0.00070753 -0.034377 0.13554" quat="0.685177 0.728377 0 0">
                              <inertial pos="0.00046 0.01509 0.0061" quat="0.476655 0.518214 -0.510702 0.493394" mass="0.01111" diaginertia="2.09489e-06 2.0469e-06 5.33997e-07" />
                              <joint name="left_index_1_joint" pos="0 0 0" axis="0 0 -1" range="0 1.52856" actuatorfrcrange="-1 1" class="finger_motor" />
                              <geom type="mesh" rgba="0.25 0.25 0.25 1" mesh="rh56f1_l_left_index_1" contype="0" conaffinity="0" group="1" density="0" />
                              <body name="left_index_2" pos="0.0031056 0.032854 -0.001">
                                <inertial pos="-0.00436 0.01623 0.00502" quat="0.68274 0.725748 0.0580265 0.0615598" mass="0.0103" diaginertia="1.60531e-06 1.57942e-06 2.53969e-07" />
                                <joint name="left_index_2_joint" pos="0 0 0" axis="0 0 -1" range="0 3.14" actuatorfrcrange="-1 1" class="finger_motor" />
                                <geom type="mesh" rgba="0.25 0.25 0.25 1" mesh="rh56f1_l_left_index_2" contype="0" conaffinity="0" group="1" density="0" />
                                <geom pos="0.005139 0.028671 -0.0059996" quat="0.683229 0.0398456 0.723933 -0.0867874" type="mesh" rgba="0.25 0.25 0.25 1" mesh="rh56f1_l_index_force_sensor" contype="0" conaffinity="0" group="1" density="0" />
                                <geom pos="0.0049188 0.039631 -0.006" quat="0.686443 -0.142024 0.705909 0.101572" type="mesh" rgba="0.25 0.25 0.25 1" mesh="rh56f1_l_index_tip" contype="0" conaffinity="0" group="1" density="0" />
                              </body>
                            </body>
                            <body name="left_middle_1" pos="0.00070746 -0.015767 0.13648" quat="0.707105 0.707108 0 0">
                              <inertial pos="0.00046 0.01468 0.00701" quat="0.492281 0.503436 -0.495374 0.50874" mass="0.01111" diaginertia="2.09488e-06 2.0469e-06 5.33993e-07" />
                              <joint name="left_middle_1_joint" pos="0 0 0" axis="0 0 -1" range="0 1.52856" actuatorfrcrange="-1 1" class="finger_motor" />
                              <geom type="mesh" rgba="0.25 0.25 0.25 1" mesh="rh56f1_l_left_middle_1" contype="0" conaffinity="0" group="1" density="0" />
                              <body name="left_middle_2" pos="0.0031056 0.032854 -0.001">
                                <inertial pos="-0.00402 0.01731 0.006" quat="0.704389 0.704366 0.0621741 0.0619657" mass="0.01122" diaginertia="1.9796e-06 1.95229e-06 2.77678e-07" />
                                <joint name="left_middle_2_joint" pos="0 0 0" axis="0 0 -1" range="0 3.14" actuatorfrcrange="-1 1" class="finger_motor" />
                                <geom type="mesh" rgba="0.25 0.25 0.25 1" mesh="rh56f1_l_left_middle_2" contype="0" conaffinity="0" group="1" density="0" />
                                <geom pos="0.0059655 0.031551 -0.0060998" quat="-0.684865 -0.069091 -0.721724 0.0728096" type="mesh" rgba="0.25 0.25 0.25 1" mesh="rh56f1_l_middle_force_sensor" contype="0" conaffinity="0" group="1" density="0" />
                                <geom pos="0.0059647 0.042512 -0.0060998" quat="0.698251 -0.1153 0.697067 0.115104" type="mesh" rgba="0.25 0.25 0.25 1" mesh="rh56f1_l_middle_tip" contype="0" conaffinity="0" group="1" density="0" />
                              </body>
                            </body>
                            <body name="left_ring_1" pos="0.00070746 0.0030876 0.13643" quat="0.725387 0.688341 0 0">
                              <inertial pos="0.00046 0.0143 0.00777" quat="0.505287 0.490373 -0.481891 0.521536" mass="0.01111" diaginertia="2.09489e-06 2.0469e-06 5.33994e-07" />
                              <joint name="left_ring_1_joint" pos="0 0 0" axis="0 0 -1" range="0 1.52856" actuatorfrcrange="-1 1" class="finger_motor" />
                              <geom type="mesh" rgba="0.25 0.25 0.25 1" mesh="rh56f1_l_left_ring_1" contype="0" conaffinity="0" group="1" density="0" />
                              <body name="left_ring_2" pos="0.0031056 0.032854 -0.001">
                                <inertial pos="-0.00436 0.01556 0.00682" quat="0.722784 0.685876 0.0614095 0.0581851" mass="0.0103" diaginertia="1.60531e-06 1.57942e-06 2.53965e-07" />
                                <joint name="left_ring_2_joint" pos="0 0 0" axis="0 0 -1" range="0 3.14" actuatorfrcrange="-1 1" class="finger_motor" />
                                <geom type="mesh" rgba="0.25 0.25 0.25 1" mesh="rh56f1_l_left_ring_2" contype="0" conaffinity="0" group="1" density="0" />
                                <geom pos="0.005139 0.028671 -0.0059996" quat="0.687077 0.0814501 0.720451 -0.0473445" type="mesh" rgba="0.25 0.25 0.25 1" mesh="rh56f1_l_ring_force_sensor" contype="0" conaffinity="0" group="1" density="0" />
                                <geom pos="0.0049188 0.039631 -0.006" quat="0.693402 -0.102853 0.699014 0.1414" type="mesh" rgba="0.25 0.25 0.25 1" mesh="rh56f1_l_ring_tip" contype="0" conaffinity="0" group="1" density="0" />
                              </body>
                            </body>
                            <body name="left_little_1" pos="0.00070753 0.021094 0.13531" quat="0.743137 0.669139 0 0">
                              <inertial pos="0.00046 0.01387 0.0085" quat="0.517961 0.476989 -0.468065 0.533959" mass="0.01111" diaginertia="2.09488e-06 2.0469e-06 5.33992e-07" />
                              <joint name="left_little_1_joint" pos="0 0 0" axis="0 0 -1" range="0 1.52856" actuatorfrcrange="-1 1" class="finger_motor" />
                              <geom type="mesh" rgba="0.25 0.25 0.25 1" mesh="rh56f1_l_left_little_1" contype="0" conaffinity="0" group="1" density="0" />
                              <body name="left_little_2" pos="0.0031057 0.032854 -0.001">
                                <inertial pos="-0.00407 0.01192 0.00728" quat="0.738363 0.664878 0.0832067 0.0763755" mass="0.00839" diaginertia="9.74394e-07 9.45689e-07 2.00057e-07" />
                                <joint name="left_little_2_joint" pos="0 0 0" axis="0 0 -1" range="0 3.14" actuatorfrcrange="-1 1" class="finger_motor" />
                                <geom type="mesh" rgba="0.25 0.25 0.25 1" mesh="rh56f1_l_left_little_2" contype="0" conaffinity="0" group="1" density="0" />
                                <geom pos="0.0051314 0.021582 -0.0063543" quat="0.6878 0.107216 0.717045 -0.0357966" type="mesh" rgba="0.25 0.25 0.25 1" mesh="rh56f1_l_little_force_sensor" contype="0" conaffinity="0" group="1" density="0" />
                                <geom pos="0.0051203 0.032544 -0.0063511" quat="0.690832 -0.0769627 0.70225 0.15386" type="mesh" rgba="0.25 0.25 0.25 1" mesh="rh56f1_l_little_tip" contype="0" conaffinity="0" group="1" density="0" />
                              </body>
                            </body>
                          </body>
                          </body>
                          <!-- ===== END LEFT RH56F1 INSPIRE HAND ===== -->

                        </body>
                      </body>
                    </body>
                  </body>
                </body>
              </body>
            </body>
            <!-- ======================== RIGHT ARM ======================== -->
            <body name="right_shoulder_pitch_link" pos="0.0039563 -0.10021 0.23778"
              quat="0.990264 -0.139201 1.38722e-05 9.86868e-05">
              <inertial pos="0 -0.035892 -0.011628" quat="0.68225 -0.326267 0.0130458 0.654152"
                mass="0.718" diaginertia="0.000465864 0.000432842 0.000406394" />
              <joint name="right_shoulder_pitch_joint" pos="0 0 0" axis="0 1 0"
                range="-3.0892 2.6704" actuatorfrcrange="-25 25" class="arm_motor" />
              <geom type="mesh" contype="0" conaffinity="0" group="1" density="0"
                rgba="0.7 0.7 0.7 1" mesh="right_shoulder_pitch_link" />
              <geom size="0.03 0.025" pos="0 -0.04 -0.01" quat="0.707107 0 0.707107 0"
                type="cylinder" rgba="0.7 0.7 0.7 1" />
              <body name="right_shoulder_roll_link" pos="0 -0.038 -0.013831"
                quat="0.990268 0.139172 0 0">
                <inertial pos="-0.000227 -0.00727 -0.063243"
                  quat="0.712604 -0.00710317 -0.0196223 0.701256" mass="0.643"
                  diaginertia="0.000691311 0.000618011 0.000388977" />
                <joint name="right_shoulder_roll_joint" pos="0 0 0" axis="1 0 0"
                  range="-2.2515 1.5882" actuatorfrcrange="-25 25" class="arm_motor" />
                <geom type="mesh" contype="0" conaffinity="0" group="1" density="0"
                  rgba="0.7 0.7 0.7 1" mesh="right_shoulder_roll_link" />
                <geom size="0.03 0.015" pos="-0.004 -0.006 -0.053" type="cylinder"
                  rgba="0.7 0.7 0.7 1" />
                <body name="right_shoulder_yaw_link" pos="0 -0.00624 -0.1032">
                  <inertial pos="0.010773 0.002949 -0.072009"
                    quat="0.687134 -0.0679942 -0.0964829 0.716879" mass="0.734"
                    diaginertia="0.00106187 0.00103217 0.000400661" />
                  <joint name="right_shoulder_yaw_joint" pos="0 0 0" axis="0 0 1"
                    range="-2.618 2.618" actuatorfrcrange="-25 25" class="arm_motor" />
                  <geom type="mesh" contype="0" conaffinity="0" group="1" density="0"
                    rgba="0.7 0.7 0.7 1" mesh="right_shoulder_yaw_link" />
                  <geom type="mesh" rgba="0.7 0.7 0.7 1" mesh="right_shoulder_yaw_link" />
                  <body name="right_elbow_link" pos="0.015783 0 -0.080518">
                    <inertial pos="0.064956 -0.004454 -0.010062"
                      quat="0.388129 0.388821 0.636132 0.541765" mass="0.6"
                      diaginertia="0.000443035 0.000421612 0.000259353" />
                    <joint name="right_elbow_joint" pos="0 0 0" axis="0 1 0" range="-1.0472 2.0944"
                      actuatorfrcrange="-25 25" class="arm_motor" />
                    <geom type="mesh" contype="0" conaffinity="0" group="1" density="0"
                      rgba="0.7 0.7 0.7 1" mesh="right_elbow_link" />
                    <geom type="mesh" rgba="0.7 0.7 0.7 1" mesh="right_elbow_link" />
                    <body name="right_wrist_roll_link" pos="0.1 -0.00188791 -0.01">
                      <inertial pos="0.0171394 -0.000537591 4.8864e-07"
                        quat="0.411667 0.575338 -0.411094 0.574906" mass="0.085445"
                        diaginertia="5.48211e-05 4.96646e-05 3.57798e-05" />
                      <joint name="right_wrist_roll_joint" pos="0 0 0" axis="1 0 0"
                        range="-1.97222 1.97222" actuatorfrcrange="-25 25" class="arm_motor" />
                      <geom type="mesh" contype="0" conaffinity="0" group="1" density="0"
                        rgba="0.7 0.7 0.7 1" mesh="right_wrist_roll_link" />
                      <geom type="mesh" rgba="0.7 0.7 0.7 1" mesh="right_wrist_roll_link" />
                      <body name="right_wrist_pitch_link" pos="0.038 0 0">
                        <inertial pos="0.0229999 0.00111685 -0.00111658"
                          quat="0.643608 0.293036 0.661363 0.249998" mass="0.48405"
                          diaginertia="0.000430353 0.000429873 0.000164648" />
                        <joint name="right_wrist_pitch_joint" pos="0 0 0" axis="0 1 0"
                          range="-1.61443 1.61443" actuatorfrcrange="-5 5" class="wrist_motor" />
                        <geom type="mesh" contype="0" conaffinity="0" group="1" density="0"
                          rgba="0.7 0.7 0.7 1" mesh="right_wrist_pitch_link" />
                        <geom type="mesh" rgba="0.7 0.7 0.7 1" mesh="right_wrist_pitch_link" />
                        <body name="right_wrist_yaw_link" pos="0.046 0 0">
                          <inertial pos="0.0885506 -0.00212216 0.000573742"
                            quat="0.507224 0.511377 0.494292 0.486717" mass="0.457415"
                            diaginertia="0.0010598 0.000895373 0.0003238" />
                          <joint name="right_wrist_yaw_joint" pos="0 0 0" axis="0 0 1"
                            range="-1.61443 1.61443" actuatorfrcrange="-5 5" class="wrist_motor" />
                          <geom type="mesh" contype="0" conaffinity="0" group="1" density="0"
                            rgba="0.7 0.7 0.7 1" mesh="right_wrist_yaw_link" />
                          <geom type="mesh" rgba="0.7 0.7 0.7 1" mesh="right_wrist_yaw_link" />

                          <!-- ===== RIGHT RH56F1 INSPIRE HAND ===== -->
                          <body name="right_hand_base" pos="0.05 0 0" quat="0.70710678119 0 -0.70710678119 0">
                          <body name="right_inspire_base_link">
                            <inertial pos="0.000631584180168987 1.55468476565051E-09 0.0185710308410627" mass="0.0793945003608915" fullinertia="2.73302869871105E-05 2.62165141408126E-05 3.5682432554866E-05 4.73396056660905E-13 2.86328005285174E-08 1.90463743334758E-12" />
                            <geom type="mesh" rgba="1 1 1 1" mesh="rh56f1_r_base_link" contype="0" conaffinity="0" group="1" density="0" />
                            <geom pos="0 0 0.0305" quat="1 0 0 0" type="mesh" rgba="0.866667 0.866667 0.890196 1" mesh="rh56f1_r_plam_1" contype="0" conaffinity="0" group="1" density="0" />
                            <geom pos="0 0 0.0305" type="mesh" rgba="0.25 0.25 0.25 1" mesh="rh56f1_r_plam_2" contype="0" conaffinity="0" group="1" density="0" />
                            <geom pos="0 0 0.0305" quat="1 0 0 0" type="mesh" rgba="1 1 1 1" mesh="rh56f1_r_plam_3" contype="0" conaffinity="0" group="1" density="0" />
                            <geom pos="0.0159402 -0.00135045 0.104246" quat="0.5 0.5 0.5 0.5" type="mesh" rgba="0.298039 0.298039 0.298039 1" mesh="rh56f1_r_plam_force_sensor" contype="0" conaffinity="0" group="1" density="0" />
                            <body name="right_thumb_1" pos="0.01836 0.027241 0.070511">
                              <inertial pos="-0.00015 0.00544 -0.00482" quat="0.668146 0.743863 -0.0115653 -0.0107013" mass="0.0168" diaginertia="7.34323e-07 5.85437e-07 2.7525e-07" />
                              <joint name="right_thumb_1_joint" pos="0 0 0" axis="8.7274e-05 0 -1" range="0 2.0944" actuatorfrcrange="-1 1" class="finger_motor" />
                              <geom type="mesh" rgba="1 1 1 1" mesh="rh56f1_r_right_thumb_1" contype="0" conaffinity="0" group="1" density="0" />
                              <body name="right_thumb_2" pos="0.0047995 0.013396 -0.0052536" quat="0.500023 0.499975 -0.499977 -0.500025">
                                <inertial pos="-0.0238 0.01042 0.00478" quat="0.297096 0.641808 -0.296429 0.64183" mass="0.06526" diaginertia="2.24919e-05 1.88464e-05 6.77592e-06" />
                                <joint name="right_thumb_2_joint" pos="0 0 0" axis="0 0 -1" range="0 0.474555" actuatorfrcrange="-1 1" class="finger_motor" />
                                <geom type="mesh" rgba="0.25 0.25 0.25 1" mesh="rh56f1_r_right_thumb_2" contype="0" conaffinity="0" group="1" density="0" />
                                <body name="right_thumb_3" pos="-0.029155 0.03869 -0.0032">
                                  <inertial pos="-0.01255 0.00331 0.00799" quat="0.375924 0.598698 -0.374111 0.600236" mass="0.01333" diaginertia="1.69211e-06 1.49274e-06 1.11195e-06" />
                                  <joint name="right_thumb_3_joint" pos="0 0 0" axis="0 0 -1" range="0 3.14" actuatorfrcrange="-1 1" class="finger_motor" />
                                  <geom type="mesh" rgba="0.25 0.25 0.25 1" mesh="rh56f1_r_right_thumb_3" contype="0" conaffinity="0" group="1" density="0" />
                                  <body name="right_thumb_4" pos="-0.01441 0.014648 0.0013">
                                    <inertial pos="-0.0102 0.00886 0.0067" quat="0.700656 0.700656 0.0952978 0.0952978" mass="0.01144" diaginertia="9.87352e-07 9.4781e-07 3.54518e-07" />
                                    <joint name="right_thumb_4_joint" pos="0 0 0" axis="0 0 -1" range="0 3.14" actuatorfrcrange="-1 1" class="finger_motor" />
                                    <geom type="mesh" rgba="0.25 0.25 0.25 1" mesh="rh56f1_r_right_thumb_4" contype="0" conaffinity="0" group="1" density="0" />
                                    <geom pos="-0.0082761 0.019128 0.0068" quat="0.628919 -0.676413 0.261003 -0.28072" type="mesh" rgba="0.25 0.25 0.25 1" mesh="rh56f1_r_thumb_force_sensor" contype="0" conaffinity="0" group="1" density="0" />
                                    <geom pos="-0.017405 0.025196 0.0068001" quat="0.562203 -0.432407 0.558749 0.429827" type="mesh" rgba="0.25 0.25 0.25 1" mesh="rh56f1_r_thumb_tip" contype="0" conaffinity="0" group="1" density="0" />
                                  </body>
                                </body>
                              </body>
                            </body>
                            <body name="right_index_1" pos="0.00070751 0.034376 0.13554" quat="0.728374 0.685179 0 0">
                              <inertial pos="0.00046 0.01509 0.0061" quat="0.518214 0.476655 -0.493394 0.510702" mass="0.01111" diaginertia="2.09489e-06 2.0469e-06 5.33997e-07" />
                              <joint name="right_index_1_joint" pos="0 0 0" axis="0 0 -1" range="0 1.52856" actuatorfrcrange="-1 1" class="finger_motor" />
                              <geom type="mesh" rgba="0.25 0.25 0.25 1" mesh="rh56f1_r_right_index_1" contype="0" conaffinity="0" group="1" density="0" />
                              <body name="right_index_2" pos="0.0031056 0.032854 0.001">
                                <inertial pos="-0.00436 0.01623 0.00502" quat="0.725748 0.68274 -0.0615598 -0.0580265" mass="0.0103" diaginertia="1.60531e-06 1.57942e-06 2.53969e-07" />
                                <joint name="right_index_2_joint" pos="0 0 0" axis="0 0 -1" range="0 3.14" actuatorfrcrange="-1 1" class="finger_motor" />
                                <geom type="mesh" rgba="0.25 0.25 0.25 1" mesh="rh56f1_r_right_index_2" contype="0" conaffinity="0" group="1" density="0" />
                                <geom pos="0.005139 0.028671 0.0059996" quat="0.687471 0.0873152 0.719735 -0.0417338" type="mesh" rgba="0.25 0.25 0.25 1" mesh="rh56f1_r_index_force_sensor" contype="0" conaffinity="0" group="1" density="0" />
                                <geom pos="0.0049188 0.039631 0.006" quat="0.69276 -0.099628 0.699451 0.144661" type="mesh" rgba="0.25 0.25 0.25 1" mesh="rh56f1_r_index_tip" contype="0" conaffinity="0" group="1" density="0" />
                              </body>
                            </body>
                            <body name="right_middle_1" pos="0.00070746 0.015767 0.13648" quat="0.707105 0.707108 0 0">
                              <inertial pos="0.00046 0.01468 0.00701" quat="0.503436 0.492281 -0.50874 0.495374" mass="0.01111" diaginertia="2.09488e-06 2.0469e-06 5.33993e-07" />
                              <joint name="right_middle_1_joint" pos="0 0 0" axis="0 0 -1" range="0 1.52856" actuatorfrcrange="-1 1" class="finger_motor" />
                              <geom type="mesh" rgba="0.25 0.25 0.25 1" mesh="rh56f1_r_right_middle_1" contype="0" conaffinity="0" group="1" density="0" />
                              <body name="right_middle_2" pos="0.0031056 0.032854 0.001">
                                <inertial pos="-0.00402 0.01731 0.006" quat="0.704366 0.704389 -0.0619657 -0.0621741" mass="0.01122" diaginertia="1.9796e-06 1.95229e-06 2.77678e-07" />
                                <joint name="right_middle_2_joint" pos="0 0 0" axis="0 0 -1" range="0 3.14" actuatorfrcrange="-1 1" class="finger_motor" />
                                <geom type="mesh" rgba="0.25 0.25 0.25 1" mesh="rh56f1_r_right_middle_2" contype="0" conaffinity="0" group="1" density="0" />
                                <geom pos="0.0059655 0.031551 0.0060998" quat="-0.684865 -0.069091 -0.721724 0.0728096" type="mesh" rgba="0.25 0.25 0.25 1" mesh="rh56f1_r_middle_force_sensor" contype="0" conaffinity="0" group="1" density="0" />
                                <geom pos="0.0059647 0.042512 0.0060998" quat="0.698251 -0.1153 0.697067 0.115104" type="mesh" rgba="0.25 0.25 0.25 1" mesh="rh56f1_r_middle_tip" contype="0" conaffinity="0" group="1" density="0" />
                              </body>
                            </body>
                            <body name="right_ring_1" pos="0.00070746 -0.0030876 0.13643" quat="0.688339 0.725389 0 0">
                              <inertial pos="0.00046 0.0143 0.00777" quat="0.490373 0.505287 -0.521536 0.481891" mass="0.01111" diaginertia="2.09489e-06 2.0469e-06 5.33994e-07" />
                              <joint name="right_ring_1_joint" pos="0 0 0" axis="0 0 -1" range="0 1.52856" actuatorfrcrange="-1 1" class="finger_motor" />
                              <geom type="mesh" rgba="0.25 0.25 0.25 1" mesh="rh56f1_r_right_ring_1" contype="0" conaffinity="0" group="1" density="0" />
                              <body name="right_ring_2" pos="0.0031056 0.032854 0.001">
                                <inertial pos="-0.00436 0.01556 0.00682" quat="0.685876 0.722784 -0.0581851 -0.0614095" mass="0.0103" diaginertia="1.60531e-06 1.57942e-06 2.53965e-07" />
                                <joint name="right_ring_2_joint" pos="0 0 0" axis="0 0 -1" range="0 3.14" actuatorfrcrange="-1 1" class="finger_motor" />
                                <geom type="mesh" rgba="0.25 0.25 0.25 1" mesh="rh56f1_r_right_ring_2" contype="0" conaffinity="0" group="1" density="0" />
                                <geom pos="0.005139 0.028671 0.0059996" quat="0.683611 0.0430277 0.723746 -0.0837647" type="mesh" rgba="0.25 0.25 0.25 1" mesh="rh56f1_r_ring_force_sensor" contype="0" conaffinity="0" group="1" density="0" />
                                <geom pos="0.0049188 0.039631 0.006" quat="0.700219 -0.141615 0.692174 0.102634" type="mesh" rgba="0.25 0.25 0.25 1" mesh="rh56f1_r_ring_tip" contype="0" conaffinity="0" group="1" density="0" />
                              </body>
                            </body>
                            <body name="right_little_1" pos="0.00070753 -0.021451 0.13527" quat="0.669137 0.743139 0 0">
                              <inertial pos="0.00046 0.01387 0.0085" quat="0.476989 0.517961 -0.533959 0.468065" mass="0.01111" diaginertia="2.09488e-06 2.0469e-06 5.33992e-07" />
                              <joint name="right_little_1_joint" pos="0 0 0" axis="0 0 -1" range="0 1.52856" actuatorfrcrange="-1 1" class="finger_motor" />
                              <geom type="mesh" rgba="0.25 0.25 0.25 1" mesh="rh56f1_r_right_little_1" contype="0" conaffinity="0" group="1" density="0" />
                              <body name="right_little_2" pos="0.0031057 0.032854 0.001">
                                <inertial pos="-0.00407 0.01192 0.00728" quat="0.664878 0.738363 -0.0763755 -0.0832067" mass="0.00839" diaginertia="9.74394e-07 9.45689e-07 2.00057e-07" />
                                <joint name="right_little_2_joint" pos="0 0 0" axis="0 0 -1" range="0 3.14" actuatorfrcrange="-1 1" class="finger_motor" />
                                <geom type="mesh" rgba="0.25 0.25 0.25 1" mesh="rh56f1_r_right_little_2" contype="0" conaffinity="0" group="1" density="0" />
                                <geom pos="0.0051314 0.021582 0.0059959" quat="0.680037 0.0302139 0.724421 -0.108858" type="mesh" rgba="0.25 0.25 0.25 1" mesh="rh56f1_r_little_force_sensor" contype="0" conaffinity="0" group="1" density="0" />
                                <geom pos="0.0051203 0.032544 0.0059927" quat="0.703455 -0.153947 0.689619 0.0766592" type="mesh" rgba="0.25 0.25 0.25 1" mesh="rh56f1_r_little_tip" contype="0" conaffinity="0" group="1" density="0" />
                              </body>
                            </body>
                          </body>
                          </body>
                          <!-- ===== END RIGHT RH56F1 INSPIRE HAND ===== -->

                        </body>
                      </body>
                    </body>
                  </body>
                </body>
              </body>
            </body>
          </body>
        </body>
      </body>
    </body>
  </worldbody>

  <!-- ================================================================ -->
  <!-- Mimic joint equality constraints (from URDF <mimic> elements)    -->
  <!-- MuJoCo joint equality constrains joint1 = polycoef(joint2).       -->
  <!-- ================================================================ -->
  <equality>
    <!-- Left RH56F1 passive mimic joints -->
    <joint joint1="left_thumb_3_joint" joint2="left_thumb_2_joint"
      polycoef="0 1.2953 0 0 0" solref="0.02 1" solimp="0.9 0.95 0.001"/>
    <joint joint1="left_thumb_4_joint" joint2="left_thumb_3_joint"
      polycoef="0 0.8962 0 0 0" solref="0.02 1" solimp="0.9 0.95 0.001"/>
    <joint joint1="left_index_2_joint" joint2="left_index_1_joint"
      polycoef="0 1.1545 0 0 0" solref="0.02 1" solimp="0.9 0.95 0.001"/>
    <joint joint1="left_middle_2_joint" joint2="left_middle_1_joint"
      polycoef="0 1.1545 0 0 0" solref="0.02 1" solimp="0.9 0.95 0.001"/>
    <joint joint1="left_ring_2_joint" joint2="left_ring_1_joint"
      polycoef="0 1.1545 0 0 0" solref="0.02 1" solimp="0.9 0.95 0.001"/>
    <joint joint1="left_little_2_joint" joint2="left_little_1_joint"
      polycoef="0 1.1545 0 0 0" solref="0.02 1" solimp="0.9 0.95 0.001"/>

    <!-- Right RH56F1 passive mimic joints -->
    <joint joint1="right_thumb_3_joint" joint2="right_thumb_2_joint"
      polycoef="0 1.2953 0 0 0" solref="0.02 1" solimp="0.9 0.95 0.001"/>
    <joint joint1="right_thumb_4_joint" joint2="right_thumb_3_joint"
      polycoef="0 0.8962 0 0 0" solref="0.02 1" solimp="0.9 0.95 0.001"/>
    <joint joint1="right_index_2_joint" joint2="right_index_1_joint"
      polycoef="0 1.1545 0 0 0" solref="0.02 1" solimp="0.9 0.95 0.001"/>
    <joint joint1="right_middle_2_joint" joint2="right_middle_1_joint"
      polycoef="0 1.1545 0 0 0" solref="0.02 1" solimp="0.9 0.95 0.001"/>
    <joint joint1="right_ring_2_joint" joint2="right_ring_1_joint"
      polycoef="0 1.1545 0 0 0" solref="0.02 1" solimp="0.9 0.95 0.001"/>
    <joint joint1="right_little_2_joint" joint2="right_little_1_joint"
      polycoef="0 1.1545 0 0 0" solref="0.02 1" solimp="0.9 0.95 0.001"/>
  </equality>


  <actuator>
    <!-- Legs -->
    <position class="g1" name="left_hip_pitch_joint" joint="left_hip_pitch_joint" />
    <position class="g1" name="left_hip_roll_joint" joint="left_hip_roll_joint" />
    <position class="g1" name="left_hip_yaw_joint" joint="left_hip_yaw_joint" />
    <position class="g1" name="left_knee_joint" joint="left_knee_joint" />
    <position class="g1" name="left_ankle_pitch_joint" joint="left_ankle_pitch_joint" />
    <position class="g1" name="left_ankle_roll_joint" joint="left_ankle_roll_joint" />
    <position class="g1" name="right_hip_pitch_joint" joint="right_hip_pitch_joint" />
    <position class="g1" name="right_hip_roll_joint" joint="right_hip_roll_joint" />
    <position class="g1" name="right_hip_yaw_joint" joint="right_hip_yaw_joint" />
    <position class="g1" name="right_knee_joint" joint="right_knee_joint" />
    <position class="g1" name="right_ankle_pitch_joint" joint="right_ankle_pitch_joint" />
    <position class="g1" name="right_ankle_roll_joint" joint="right_ankle_roll_joint" />
    <!-- Waist -->
    <position class="g1" name="waist_yaw_joint" joint="waist_yaw_joint" />
    <position class="g1" name="waist_roll_joint" joint="waist_roll_joint" />
    <position class="g1" name="waist_pitch_joint" joint="waist_pitch_joint" />
    <!-- Left arm -->
    <position class="g1" name="left_shoulder_pitch_joint" joint="left_shoulder_pitch_joint" />
    <position class="g1" name="left_shoulder_roll_joint" joint="left_shoulder_roll_joint" />
    <position class="g1" name="left_shoulder_yaw_joint" joint="left_shoulder_yaw_joint" />
    <position class="g1" name="left_elbow_joint" joint="left_elbow_joint" />
    <position class="g1" name="left_wrist_roll_joint" joint="left_wrist_roll_joint" />
    <position class="g1" name="left_wrist_pitch_joint" joint="left_wrist_pitch_joint" />
    <position class="g1" name="left_wrist_yaw_joint" joint="left_wrist_yaw_joint" />
    <!-- Left Inspire Hand (6 actuated DOF: thumb yaw + pitch, index/middle/ring/pinky proximal) -->
    <position class="g1" name="left_thumb_1_joint" joint="left_thumb_1_joint" />
    <position class="g1" name="left_thumb_2_joint" joint="left_thumb_2_joint" />
    <position class="g1" name="left_index_1_joint" joint="left_index_1_joint" />
    <position class="g1" name="left_middle_1_joint" joint="left_middle_1_joint" />
    <position class="g1" name="left_ring_1_joint" joint="left_ring_1_joint" />
    <position class="g1" name="left_little_1_joint" joint="left_little_1_joint" />
    <!-- Right arm -->
    <position class="g1" name="right_shoulder_pitch_joint" joint="right_shoulder_pitch_joint" />
    <position class="g1" name="right_shoulder_roll_joint" joint="right_shoulder_roll_joint" />
    <position class="g1" name="right_shoulder_yaw_joint" joint="right_shoulder_yaw_joint" />
    <position class="g1" name="right_elbow_joint" joint="right_elbow_joint" />
    <position class="g1" name="right_wrist_roll_joint" joint="right_wrist_roll_joint" />
    <position class="g1" name="right_wrist_pitch_joint" joint="right_wrist_pitch_joint" />
    <position class="g1" name="right_wrist_yaw_joint" joint="right_wrist_yaw_joint" />
    <!-- Right Inspire Hand (6 actuated DOF) -->
    <position class="g1" name="right_thumb_1_joint" joint="right_thumb_1_joint" />
    <position class="g1" name="right_thumb_2_joint" joint="right_thumb_2_joint" />
    <position class="g1" name="right_index_1_joint" joint="right_index_1_joint" />
    <position class="g1" name="right_middle_1_joint" joint="right_middle_1_joint" />
    <position class="g1" name="right_ring_1_joint" joint="right_ring_1_joint" />
    <position class="g1" name="right_little_1_joint" joint="right_little_1_joint" />
  </actuator>

  <sensor>
    <!-- Legs -->
    <jointpos name="left_hip_pitch_pos" joint="left_hip_pitch_joint" />
    <jointpos name="left_hip_roll_pos" joint="left_hip_roll_joint" />
    <jointpos name="left_hip_yaw_pos" joint="left_hip_yaw_joint" />
    <jointpos name="left_knee_pos" joint="left_knee_joint" />
    <jointpos name="left_ankle_pitch_pos" joint="left_ankle_pitch_joint" />
    <jointpos name="left_ankle_roll_pos" joint="left_ankle_roll_joint" />
    <jointpos name="right_hip_pitch_pos" joint="right_hip_pitch_joint" />
    <jointpos name="right_hip_roll_pos" joint="right_hip_roll_joint" />
    <jointpos name="right_hip_yaw_pos" joint="right_hip_yaw_joint" />
    <jointpos name="right_knee_pos" joint="right_knee_joint" />
    <jointpos name="right_ankle_pitch_pos" joint="right_ankle_pitch_joint" />
    <jointpos name="right_ankle_roll_pos" joint="right_ankle_roll_joint" />
    <!-- Waist -->
    <jointpos name="waist_yaw_pos" joint="waist_yaw_joint" />
    <jointpos name="waist_roll_pos" joint="waist_roll_joint" />
    <jointpos name="waist_pitch_pos" joint="waist_pitch_joint" />
    <!-- Left arm -->
    <jointpos name="left_shoulder_pitch_pos" joint="left_shoulder_pitch_joint" />
    <jointpos name="left_shoulder_roll_pos" joint="left_shoulder_roll_joint" />
    <jointpos name="left_shoulder_yaw_pos" joint="left_shoulder_yaw_joint" />
    <jointpos name="left_elbow_pos" joint="left_elbow_joint" />
    <jointpos name="left_wrist_roll_pos" joint="left_wrist_roll_joint" />
    <jointpos name="left_wrist_pitch_pos" joint="left_wrist_pitch_joint" />
    <jointpos name="left_wrist_yaw_pos" joint="left_wrist_yaw_joint" />
    <!-- Left hand -->
    <jointpos name="l_ih_thumb_yaw_pos"    joint="left_thumb_1_joint" />
    <jointpos name="l_ih_thumb_pitch_pos"  joint="left_thumb_2_joint" />
    <jointpos name="l_ih_index_pos"        joint="left_index_1_joint" />
    <jointpos name="l_ih_middle_pos"       joint="left_middle_1_joint" />
    <jointpos name="l_ih_ring_pos"         joint="left_ring_1_joint" />
    <jointpos name="l_ih_pinky_pos"        joint="left_little_1_joint" />
    <!-- Right arm -->
    <jointpos name="right_shoulder_pitch_pos" joint="right_shoulder_pitch_joint" />
    <jointpos name="right_shoulder_roll_pos" joint="right_shoulder_roll_joint" />
    <jointpos name="right_shoulder_yaw_pos" joint="right_shoulder_yaw_joint" />
    <jointpos name="right_elbow_pos" joint="right_elbow_joint" />
    <jointpos name="right_wrist_roll_pos" joint="right_wrist_roll_joint" />
    <jointpos name="right_wrist_pitch_pos" joint="right_wrist_pitch_joint" />
    <jointpos name="right_wrist_yaw_pos" joint="right_wrist_yaw_joint" />
    <!-- Right hand -->
    <jointpos name="r_ih_thumb_yaw_pos"    joint="right_thumb_1_joint" />
    <jointpos name="r_ih_thumb_pitch_pos"  joint="right_thumb_2_joint" />
    <jointpos name="r_ih_index_pos"        joint="right_index_1_joint" />
    <jointpos name="r_ih_middle_pos"       joint="right_middle_1_joint" />
    <jointpos name="r_ih_ring_pos"         joint="right_ring_1_joint" />
    <jointpos name="r_ih_pinky_pos"        joint="right_little_1_joint" />

    <!-- Velocities -->
    <jointvel name="left_hip_pitch_vel" joint="left_hip_pitch_joint" />
    <jointvel name="left_hip_roll_vel" joint="left_hip_roll_joint" />
    <jointvel name="left_hip_yaw_vel" joint="left_hip_yaw_joint" />
    <jointvel name="left_knee_vel" joint="left_knee_joint" />
    <jointvel name="left_ankle_pitch_vel" joint="left_ankle_pitch_joint" />
    <jointvel name="left_ankle_roll_vel" joint="left_ankle_roll_joint" />
    <jointvel name="right_hip_pitch_vel" joint="right_hip_pitch_joint" />
    <jointvel name="right_hip_roll_vel" joint="right_hip_roll_joint" />
    <jointvel name="right_hip_yaw_vel" joint="right_hip_yaw_joint" />
    <jointvel name="right_knee_vel" joint="right_knee_joint" />
    <jointvel name="right_ankle_pitch_vel" joint="right_ankle_pitch_joint" />
    <jointvel name="right_ankle_roll_vel" joint="right_ankle_roll_joint" />
    <jointvel name="waist_yaw_vel" joint="waist_yaw_joint" />
    <jointvel name="waist_roll_vel" joint="waist_roll_joint" />
    <jointvel name="waist_pitch_vel" joint="waist_pitch_joint" />
    <jointvel name="left_shoulder_pitch_vel" joint="left_shoulder_pitch_joint" />
    <jointvel name="left_shoulder_roll_vel" joint="left_shoulder_roll_joint" />
    <jointvel name="left_shoulder_yaw_vel" joint="left_shoulder_yaw_joint" />
    <jointvel name="left_elbow_vel" joint="left_elbow_joint" />
    <jointvel name="left_wrist_roll_vel" joint="left_wrist_roll_joint" />
    <jointvel name="left_wrist_pitch_vel" joint="left_wrist_pitch_joint" />
    <jointvel name="left_wrist_yaw_vel" joint="left_wrist_yaw_joint" />
    <jointvel name="l_ih_thumb_yaw_vel"    joint="left_thumb_1_joint" />
    <jointvel name="l_ih_thumb_pitch_vel"  joint="left_thumb_2_joint" />
    <jointvel name="l_ih_index_vel"        joint="left_index_1_joint" />
    <jointvel name="l_ih_middle_vel"       joint="left_middle_1_joint" />
    <jointvel name="l_ih_ring_vel"         joint="left_ring_1_joint" />
    <jointvel name="l_ih_pinky_vel"        joint="left_little_1_joint" />
    <jointvel name="right_shoulder_pitch_vel" joint="right_shoulder_pitch_joint" />
    <jointvel name="right_shoulder_roll_vel" joint="right_shoulder_roll_joint" />
    <jointvel name="right_shoulder_yaw_vel" joint="right_shoulder_yaw_joint" />
    <jointvel name="right_elbow_vel" joint="right_elbow_joint" />
    <jointvel name="right_wrist_roll_vel" joint="right_wrist_roll_joint" />
    <jointvel name="right_wrist_pitch_vel" joint="right_wrist_pitch_joint" />
    <jointvel name="right_wrist_yaw_vel" joint="right_wrist_yaw_joint" />
    <jointvel name="r_ih_thumb_yaw_vel"    joint="right_thumb_1_joint" />
    <jointvel name="r_ih_thumb_pitch_vel"  joint="right_thumb_2_joint" />
    <jointvel name="r_ih_index_vel"        joint="right_index_1_joint" />
    <jointvel name="r_ih_middle_vel"       joint="right_middle_1_joint" />
    <jointvel name="r_ih_ring_vel"         joint="right_ring_1_joint" />
    <jointvel name="r_ih_pinky_vel"        joint="right_little_1_joint" />

    <!-- Torques -->
    <jointactuatorfrc name="left_hip_pitch_torque" joint="left_hip_pitch_joint" />
    <jointactuatorfrc name="left_hip_roll_torque" joint="left_hip_roll_joint" />
    <jointactuatorfrc name="left_hip_yaw_torque" joint="left_hip_yaw_joint" />
    <jointactuatorfrc name="left_knee_torque" joint="left_knee_joint" />
    <jointactuatorfrc name="left_ankle_pitch_torque" joint="left_ankle_pitch_joint" />
    <jointactuatorfrc name="left_ankle_roll_torque" joint="left_ankle_roll_joint" />
    <jointactuatorfrc name="right_hip_pitch_torque" joint="right_hip_pitch_joint" />
    <jointactuatorfrc name="right_hip_roll_torque" joint="right_hip_roll_joint" />
    <jointactuatorfrc name="right_hip_yaw_torque" joint="right_hip_yaw_joint" />
    <jointactuatorfrc name="right_knee_torque" joint="right_knee_joint" />
    <jointactuatorfrc name="right_ankle_pitch_torque" joint="right_ankle_pitch_joint" />
    <jointactuatorfrc name="right_ankle_roll_torque" joint="right_ankle_roll_joint" />
    <jointactuatorfrc name="waist_yaw_torque" joint="waist_yaw_joint" />
    <jointactuatorfrc name="waist_roll_torque" joint="waist_roll_joint" />
    <jointactuatorfrc name="waist_pitch_torque" joint="waist_pitch_joint" />
    <jointactuatorfrc name="left_shoulder_pitch_torque" joint="left_shoulder_pitch_joint" />
    <jointactuatorfrc name="left_shoulder_roll_torque" joint="left_shoulder_roll_joint" />
    <jointactuatorfrc name="left_shoulder_yaw_torque" joint="left_shoulder_yaw_joint" />
    <jointactuatorfrc name="left_elbow_torque" joint="left_elbow_joint" />
    <jointactuatorfrc name="left_wrist_roll_torque" joint="left_wrist_roll_joint" />
    <jointactuatorfrc name="left_wrist_pitch_torque" joint="left_wrist_pitch_joint" />
    <jointactuatorfrc name="left_wrist_yaw_torque" joint="left_wrist_yaw_joint" />
    <jointactuatorfrc name="l_ih_thumb_yaw_torque"    joint="left_thumb_1_joint" />
    <jointactuatorfrc name="l_ih_thumb_pitch_torque"  joint="left_thumb_2_joint" />
    <jointactuatorfrc name="l_ih_index_torque"        joint="left_index_1_joint" />
    <jointactuatorfrc name="l_ih_middle_torque"       joint="left_middle_1_joint" />
    <jointactuatorfrc name="l_ih_ring_torque"         joint="left_ring_1_joint" />
    <jointactuatorfrc name="l_ih_pinky_torque"        joint="left_little_1_joint" />
    <jointactuatorfrc name="right_shoulder_pitch_torque" joint="right_shoulder_pitch_joint" />
    <jointactuatorfrc name="right_shoulder_roll_torque" joint="right_shoulder_roll_joint" />
    <jointactuatorfrc name="right_shoulder_yaw_torque" joint="right_shoulder_yaw_joint" />
    <jointactuatorfrc name="right_elbow_torque" joint="right_elbow_joint" />
    <jointactuatorfrc name="right_wrist_roll_torque" joint="right_wrist_roll_joint" />
    <jointactuatorfrc name="right_wrist_pitch_torque" joint="right_wrist_pitch_joint" />
    <jointactuatorfrc name="right_wrist_yaw_torque" joint="right_wrist_yaw_joint" />
    <jointactuatorfrc name="r_ih_thumb_yaw_torque"    joint="right_thumb_1_joint" />
    <jointactuatorfrc name="r_ih_thumb_pitch_torque"  joint="right_thumb_2_joint" />
    <jointactuatorfrc name="r_ih_index_torque"        joint="right_index_1_joint" />
    <jointactuatorfrc name="r_ih_middle_torque"       joint="right_middle_1_joint" />
    <jointactuatorfrc name="r_ih_ring_torque"         joint="right_ring_1_joint" />
    <jointactuatorfrc name="r_ih_pinky_torque"        joint="right_little_1_joint" />

    <!-- IMU -->
    <framequat name="imu_quat" objtype="site" objname="imu" />
    <gyro name="imu_gyro" site="imu" />
    <accelerometer name="imu_acc" site="imu" />
    <framepos name="frame_pos" objtype="site" objname="imu" />
    <framelinvel name="frame_vel" objtype="site" objname="imu" />
  </sensor>
</mujoco>
