<?xml version="1.0"?>
<robot xmlns:xacro="http://www.ros.org/wiki/xacro">
  <xacro:macro name="rh56f1_left_hand" params="parent mount_xyz mount_rpy">
    <joint name="left_inspire_mount_joint" type="fixed">
        <origin xyz="${mount_xyz}" rpy="${mount_rpy}"/>
        <parent link="${parent}"/>
        <child link="left_inspire_base_link"/>
    </joint>
    <link name="left_inspire_base_link">
        <inertial>
            <origin xyz="0.000631583768841232 -4.98983354635385E-11 0.0185710296512339" rpy="0 0 0"/>
            <mass value="0.0793945339384899"/>
            <inertia ixx="2.73302961659096E-05" ixy="-1.14020192447604E-12" ixz="2.86317776549754E-08" iyy="2.62165201865506E-05" iyz="-9.86803596469321E-13" izz="3.56824415579562E-05"/>
        </inertial>
        <visual>
            <origin xyz="0 0 0" rpy="0 0 0"/>
            <geometry>
                <mesh filename="package://g1_mujoco_description/meshes/inspire_hand/RH56F1_L/base_link.STL"/>
            </geometry>
            <material name="">
                <color rgba="1 1 1 1"/>
            </material>
        </visual>
        <collision>
            <origin xyz="0 0 0" rpy="0 0 0"/>
            <geometry>
                <mesh filename="package://g1_mujoco_description/meshes/inspire_hand/RH56F1_L/base_link.STL"/>
            </geometry>
        </collision>
    </link>
    <link name="left_thumb_1">
        <inertial>
            <origin xyz="-0.00015 0.00544 -0.0048200000000000005" rpy="0 0 0"/>
            <mass value="0.016800000000000002"/>
            <inertia ixx="7.3387e-07" ixy="1.436e-08" ixz="-1.11e-09" iyy="2.7925e-07" iyz="3.296e-08" izz="5.8189e-07"/>
        </inertial>
        <visual>
            <origin xyz="0 0 0" rpy="0 0 0"/>
            <geometry>
                <mesh filename="package://g1_mujoco_description/meshes/inspire_hand/RH56F1_L/left_thumb_1.STL"/>
            </geometry>
            <material name="">
                <color rgba="1 1 1 1"/>
            </material>
        </visual>
        <collision>
            <origin xyz="0 0 0" rpy="0 0 0"/>
            <geometry>
                <mesh filename="package://g1_mujoco_description/meshes/inspire_hand/RH56F1_L/left_thumb_1.STL"/>
            </geometry>
        </collision>
    </link>
    <joint name="left_thumb_1_joint" type="revolute">
        <origin xyz="0.01836 -0.027241 0.070511" rpy="0 0 0"/>
        <parent link="left_inspire_base_link"/>
        <child link="left_thumb_1"/>
        <axis xyz="8.7274E-05 0 1"/>
        <limit lower="0" upper="2.0943951023931953" effort="1" velocity="2"/>
    </joint>
    <link name="left_thumb_2">
        <inertial>
            <origin xyz="-0.0238 0.01042 0.00478" rpy="0 0 0"/>
            <mass value="0.06526"/>
            <inertia ixx="1.378224e-05" ixy="-5.95663e-06" ixz="-1.9799999999999998e-09" iyy="1.1840129999999999e-05" iyz="-7.070000000000001e-09" izz="2.249189e-05"/>
        </inertial>
        <visual>
            <origin xyz="0 0 0" rpy="0 0 0"/>
            <geometry>
                <mesh filename="package://g1_mujoco_description/meshes/inspire_hand/RH56F1_L/left_thumb_2.STL"/>
            </geometry>
            <material name="">
                <color rgba="0.25 0.25 0.25 1"/>
            </material>
        </visual>
        <collision>
            <origin xyz="0 0 0" rpy="0 0 0"/>
            <geometry>
                <mesh filename="package://g1_mujoco_description/meshes/inspire_hand/RH56F1_L/left_thumb_2.STL"/>
            </geometry>
        </collision>
    </link>
    <joint name="left_thumb_2_joint" type="revolute">
        <origin xyz="0.005034 -0.01349 -0.0049121" rpy="1.5707 0 -1.5708"/>
        <parent link="left_thumb_1"/>
        <child link="left_thumb_2"/>
        <axis xyz="0 0 1"/>
        <limit lower="0" upper="0.4745550236172582" effort="1" velocity="2"/>
    </joint>
    <link name="left_thumb_3">
        <inertial>
            <origin xyz="-0.01255 0.00331 0.00799" rpy="0 0 0"/>
            <mass value="0.01333"/>
            <inertia ixx="1.41987e-06" ixy="-1.4979e-07" ixz="-6.3e-10" iyy="1.18482e-06" iyz="-1.76e-09" izz="1.6920999999999999e-06"/>
        </inertial>
        <visual>
            <origin xyz="0 0 0" rpy="0 0 0"/>
            <geometry>
                <mesh filename="package://g1_mujoco_description/meshes/inspire_hand/RH56F1_L/left_thumb_3.STL"/>
            </geometry>
            <material name="">
                <color rgba="0.25 0.25 0.25 1"/>
            </material>
        </visual>
        <collision>
            <origin xyz="0 0 0" rpy="0 0 0"/>
            <geometry>
                <mesh filename="package://g1_mujoco_description/meshes/inspire_hand/RH56F1_L/left_thumb_3.STL"/>
            </geometry>
        </collision>
    </link>
    <joint name="left_thumb_3_joint" type="revolute">
        <origin xyz="0.033907 0.034601 -0.0029656" rpy="0 0 0"/>
        <parent link="left_thumb_2"/>
        <child link="left_thumb_3"/>
        <axis xyz="0 0 1"/>
        <limit lower="0" upper="3.14" effort="1" velocity="2"/>
        <mimic joint="left_thumb_2_joint" multiplier="1.2953" offset="0"/>
    </joint>
    <link name="left_thumb_4">
        <inertial>
            <origin xyz="-0.010199999999999999 0.00886 0.0067" rpy="0 0 0"/>
            <mass value="0.011439999999999999"/>
            <inertia ixx="9.4221e-07" ixy="-1.6288e-07" ixz="-0.0" iyy="3.9966e-07" iyz="0.0" izz="9.478099999999999e-07"/>
        </inertial>
        <visual>
            <origin xyz="0 0 0" rpy="0 0 0"/>
            <geometry>
                <mesh filename="package://g1_mujoco_description/meshes/inspire_hand/RH56F1_L/left_thumb_4.STL"/>
            </geometry>
            <material name="">
                <color rgba="0.25 0.25 0.25 1"/>
            </material>
        </visual>
        <collision>
            <origin xyz="0 0 0" rpy="0 0 0"/>
            <geometry>
                <mesh filename="package://g1_mujoco_description/meshes/inspire_hand/RH56F1_L/left_thumb_4.STL"/>
            </geometry>
        </collision>
    </link>
    <joint name="left_thumb_4_joint" type="revolute">
        <origin xyz="0.01441 0.014648 0.0013" rpy="0 0 0"/>
        <parent link="left_thumb_3"/>
        <child link="left_thumb_4"/>
        <axis xyz="0 0 1"/>
        <limit lower="0" upper="3.14" effort="1" velocity="2"/>
        <mimic joint="left_thumb_3_joint" multiplier="0.8962" offset="0"/>
    </joint>
    <link name="left_inspire_thumb_force_sensor">
        <inertial>
            <origin xyz="0.00489751957141649 0.0007076731556618 -0.00883776267773212" rpy="0 0 0"/>
            <mass value="0"/>
            <inertia ixx="0" ixy="0" ixz="0" iyy="0" iyz="0" izz="0"/>
        </inertial>
        <visual>
            <origin xyz="0 0 0" rpy="0 0 0"/>
            <geometry>
                <mesh filename="package://g1_mujoco_description/meshes/inspire_hand/RH56F1_L/thumb_force_sensor.STL"/>
            </geometry>
            <material name="">
                <color rgba="0.25 0.25 0.25 1"/>
            </material>
        </visual>
        <collision>
            <origin xyz="0 0 0" rpy="0 0 0"/>
            <geometry>
                <mesh filename="package://g1_mujoco_description/meshes/inspire_hand/RH56F1_L/thumb_force_sensor.STL"/>
            </geometry>
        </collision>
    </link>
    <joint name="left_inspire_thumb_force_sensor_joint" type="fixed">
        <origin xyz="0.0082761 0.019128 0.0068" rpy="1.5194 0.0515 -2.3562"/>
        <parent link="left_thumb_4"/>
        <child link="left_inspire_thumb_force_sensor"/>
        <axis xyz="0 0 0"/>
    </joint>
    <link name="left_inspire_thumb_tip">
        <inertial>
            <origin xyz="8.11478806861891E-05 -0.00949601991936605 -0.0139509187579862" rpy="0 0 0"/>
            <mass value="0"/>
            <inertia ixx="0" ixy="0" ixz="0" iyy="0" iyz="0" izz="0"/>
        </inertial>
        <visual>
            <origin xyz="0 0 0" rpy="0 0 0"/>
            <geometry>
                <mesh filename="package://g1_mujoco_description/meshes/inspire_hand/RH56F1_L/thumb_tip.STL"/>
            </geometry>
            <material name="">
                <color rgba="0.25 0.25 0.25 1"/>
            </material>
        </visual>
        <collision>
            <origin xyz="0 0 0" rpy="0 0 0"/>
            <geometry>
                <mesh filename="package://g1_mujoco_description/meshes/inspire_hand/RH56F1_L/thumb_tip.STL"/>
            </geometry>
        </collision>
    </link>
    <joint name="left_inspire_thumb_tip_joint" type="fixed">
        <origin xyz="0.016676 0.025314 0.0067577" rpy="1.8172 -1.5641 -3.1286"/>
        <parent link="left_thumb_4"/>
        <child link="left_inspire_thumb_tip"/>
        <axis xyz="0 0 0"/>
    </joint>
    <link name="left_index_1">
        <inertial>
            <origin xyz="0.00046 0.01509 0.0060999999999999995" rpy="0 0 0"/>
            <mass value="0.01111"/>
            <inertia ixx="2.04599e-06" ixy="3.703e-08" ixz="1.77e-09" iyy="5.4029e-07" iyz="-9.149e-08" izz="2.0895e-06"/>
        </inertial>
        <visual>
            <origin xyz="0 0 0" rpy="0 0 0"/>
            <geometry>
                <mesh filename="package://g1_mujoco_description/meshes/inspire_hand/RH56F1_L/left_index_1.STL"/>
            </geometry>
            <material name="">
                <color rgba="0.25 0.25 0.25 1"/>
            </material>
        </visual>
        <collision>
            <origin xyz="0 0 0" rpy="0 0 0"/>
            <geometry>
                <mesh filename="package://g1_mujoco_description/meshes/inspire_hand/RH56F1_L/left_index_1.STL"/>
            </geometry>
        </collision>
    </link>
    <joint name="left_index_1_joint" type="revolute">
        <origin xyz="0.00070753 -0.034377 0.13554" rpy="1.6319 0 0"/>
        <parent link="left_inspire_base_link"/>
        <child link="left_index_1"/>
        <axis xyz="0 0 -1"/>
        <limit lower="0" upper="1.5285593588966337" effort="1" velocity="2"/>
    </joint>
    <link name="left_index_2">
        <inertial>
            <origin xyz="-0.00436 0.01623 0.005019999999999999" rpy="0 0 0"/>
            <mass value="0.0103"/>
            <inertia ixx="1.5669000000000002e-06" ixy="2.2414e-07" ixz="1.3699999999999999e-08" iyy="2.9717e-07" iyz="-7.84e-08" izz="1.5746300000000001e-06"/>
        </inertial>
        <visual>
            <origin xyz="0 0 0" rpy="0 0 0"/>
            <geometry>
                <mesh filename="package://g1_mujoco_description/meshes/inspire_hand/RH56F1_L/left_index_2.STL"/>
            </geometry>
            <material name="">
                <color rgba="0.25 0.25 0.25 1"/>
            </material>
        </visual>
        <collision>
            <origin xyz="0 0 0" rpy="0 0 0"/>
            <geometry>
                <mesh filename="package://g1_mujoco_description/meshes/inspire_hand/RH56F1_L/left_index_2.STL"/>
            </geometry>
        </collision>
    </link>
    <joint name="left_index_2_joint" type="revolute">
        <origin xyz="0.0031056 0.032854 -0.001" rpy="0 0 0"/>
        <parent link="left_index_1"/>
        <child link="left_index_2"/>
        <axis xyz="0 0 -1"/>
        <limit lower="0" upper="3.14" effort="1" velocity="2"/>
        <mimic joint="left_index_1_joint" multiplier="1.1545" offset="0"/>
    </joint>
    <link name="left_inspire_index_force_sensor">
        <inertial>
            <origin xyz="0.00120718275325524 -0.012261274947138 -0.00640384837472582" rpy="0 0 0"/>
            <mass value="0"/>
            <inertia ixx="0" ixy="0" ixz="0" iyy="0" iyz="0" izz="0"/>
        </inertial>
        <visual>
            <origin xyz="0 0 0" rpy="0 0 0"/>
            <geometry>
                <mesh filename="package://g1_mujoco_description/meshes/inspire_hand/RH56F1_L/index_force_sensor.STL"/>
            </geometry>
            <material name="">
                <color rgba="0.25 0.25 0.25 1"/>
            </material>
        </visual>
        <collision>
            <origin xyz="0 0 0" rpy="0 0 0"/>
            <geometry>
                <mesh filename="package://g1_mujoco_description/meshes/inspire_hand/RH56F1_L/index_force_sensor.STL"/>
            </geometry>
        </collision>
    </link>
    <joint name="left_inspire_index_force_sensor_joint" type="fixed">
        <origin xyz="0.005139 0.028671 -0.0059996" rpy="-2.1954 1.4829 -2.3749"/>
        <parent link="left_index_2"/>
        <child link="left_inspire_index_force_sensor"/>
        <axis xyz="0 0 0"/>
    </joint>
    <link name="left_inspire_index_tip">
        <inertial>
            <origin xyz="0.0014808314279941 -0.0177565390809834 -0.0152284217596933" rpy="0 0 0"/>
            <mass value="0"/>
            <inertia ixx="0" ixy="0" ixz="0" iyy="0" iyz="0" izz="0"/>
        </inertial>
        <visual>
            <origin xyz="0 0 0" rpy="0 0 0"/>
            <geometry>
                <mesh filename="package://g1_mujoco_description/meshes/inspire_hand/RH56F1_L/index_tip.STL"/>
            </geometry>
            <material name="">
                <color rgba="0.25 0.25 0.25 1"/>
            </material>
        </visual>
        <collision>
            <origin xyz="0 0 0" rpy="0 0 0"/>
            <geometry>
                <mesh filename="package://g1_mujoco_description/meshes/inspire_hand/RH56F1_L/index_tip.STL"/>
            </geometry>
        </collision>
    </link>
    <joint name="left_inspire_index_tip_joint" type="fixed">
        <origin xyz="0.0049188 0.039631 -0.006" rpy="-2.1925 1.5073 -1.8461"/>
        <parent link="left_index_2"/>
        <child link="left_inspire_index_tip"/>
        <axis xyz="0 0 0"/>
    </joint>
    <link name="left_middle_1">
        <inertial>
            <origin xyz="0.00046 0.01468 0.00701" rpy="0 0 0"/>
            <mass value="0.01111"/>
            <inertia ixx="2.04599e-06" ixy="3.707e-08" ixz="-4.9e-10" iyy="5.3491e-07" iyz="3.6e-09" izz="2.09487e-06"/>
        </inertial>
        <visual>
            <origin xyz="0 0 0" rpy="0 0 0"/>
            <geometry>
                <mesh filename="package://g1_mujoco_description/meshes/inspire_hand/RH56F1_L/left_middle_1.STL"/>
            </geometry>
            <material name="">
                <color rgba="0.25 0.25 0.25 1"/>
            </material>
        </visual>
        <collision>
            <origin xyz="0 0 0" rpy="0 0 0"/>
            <geometry>
                <mesh filename="package://g1_mujoco_description/meshes/inspire_hand/RH56F1_L/left_middle_1.STL"/>
            </geometry>
        </collision>
    </link>
    <joint name="left_middle_1_joint" type="revolute">
        <origin xyz="0.00070746 -0.015767 0.13648" rpy="1.5708 0 0"/>
        <parent link="left_inspire_base_link"/>
        <child link="left_middle_1"/>
        <axis xyz="0 0 -1"/>
        <limit lower="0" upper="1.5285593588966337" effort="1" velocity="2"/>
    </joint>
    <link name="left_middle_2">
        <inertial>
            <origin xyz="-0.004019999999999999 0.01731 0.006" rpy="0 0 0"/>
            <mass value="0.01122"/>
            <inertia ixx="1.92755e-06" ixy="2.9305e-07" ixz="-1.0000000000000001e-11" iyy="3.2973000000000003e-07" iyz="1.0000000000000001e-11" izz="1.95229e-06"/>
        </inertial>
        <visual>
            <origin xyz="0 0 0" rpy="0 0 0"/>
            <geometry>
                <mesh filename="package://g1_mujoco_description/meshes/inspire_hand/RH56F1_L/left_middle_2.STL"/>
            </geometry>
            <material name="">
                <color rgba="0.25 0.25 0.25 1"/>
            </material>
        </visual>
        <collision>
            <origin xyz="0 0 0" rpy="0 0 0"/>
            <geometry>
                <mesh filename="package://g1_mujoco_description/meshes/inspire_hand/RH56F1_L/left_middle_2.STL"/>
            </geometry>
        </collision>
    </link>
    <joint name="left_middle_2_joint" type="revolute">
        <origin xyz="0.0031056 0.032854 -0.001" rpy="0 0 0"/>
        <parent link="left_middle_1"/>
        <child link="left_middle_2"/>
        <axis xyz="0 0 -1"/>
        <limit lower="0" upper="3.14" effort="1" velocity="2"/>
        <mimic joint="left_middle_1_joint" multiplier="1.1545" offset="0"/>
    </joint>
    <link name="left_inspire_middle_force_sensor">
        <inertial>
            <origin xyz="0.000471409970909109 -0.0138861005738287 -0.00634250554762082" rpy="0 0 0"/>
            <mass value="0"/>
            <inertia ixx="0" ixy="0" ixz="0" iyy="0" iyz="0" izz="0"/>
        </inertial>
        <visual>
            <origin xyz="0 0 0" rpy="0 0 0"/>
            <geometry>
                <mesh filename="package://g1_mujoco_description/meshes/inspire_hand/RH56F1_L/middle_force_sensor.STL"/>
            </geometry>
            <material name="">
                <color rgba="0.25 0.25 0.25 1"/>
            </material>
        </visual>
        <collision>
            <origin xyz="0 0 0" rpy="0 0 0"/>
            <geometry>
                <mesh filename="package://g1_mujoco_description/meshes/inspire_hand/RH56F1_L/middle_force_sensor.STL"/>
            </geometry>
        </collision>
    </link>
    <joint name="left_inspire_middle_force_sensor_joint" type="fixed">
        <origin xyz="0.0059655 0.031551 -0.0060998" rpy="-2.9405 1.5184 3.1416"/>
        <parent link="left_middle_2"/>
        <child link="left_inspire_middle_force_sensor"/>
        <axis xyz="0 0 0"/>
    </joint>
    <link name="left_inspire_middle_tip">
        <inertial>
            <origin xyz="-1.57112051041297E-05 -0.0191707815454482 -0.0160132461086732" rpy="0 0 0"/>
            <mass value="0"/>
            <inertia ixx="0" ixy="0" ixz="0" iyy="0" iyz="0" izz="0"/>
        </inertial>
        <visual>
            <origin xyz="0 0 0" rpy="0 0 0"/>
            <geometry>
                <mesh filename="package://g1_mujoco_description/meshes/inspire_hand/RH56F1_L/middle_tip.STL"/>
            </geometry>
            <material name="">
                <color rgba="0.25 0.25 0.25 1"/>
            </material>
        </visual>
        <collision>
            <origin xyz="0 0 0" rpy="0 0 0"/>
            <geometry>
                <mesh filename="package://g1_mujoco_description/meshes/inspire_hand/RH56F1_L/middle_tip.STL"/>
            </geometry>
        </collision>
    </link>
    <joint name="left_inspire_middle_tip_joint" type="fixed">
        <origin xyz="0.0059647 0.042512 -0.0060998" rpy="-0.3273 1.5691 0"/>
        <parent link="left_middle_2"/>
        <child link="left_inspire_middle_tip"/>
        <axis xyz="0 0 0"/>
    </joint>
    <link name="left_ring_1">
        <inertial>
            <origin xyz="0.00046 0.0143 0.00777" rpy="0 0 0"/>
            <mass value="0.01111"/>
            <inertia ixx="2.04599e-06" ixy="3.699e-08" ixz="-2.43e-09" iyy="5.395599999999999e-07" iyz="8.511e-08" izz="2.09023e-06"/>
        </inertial>
        <visual>
            <origin xyz="0 0 0" rpy="0 0 0"/>
            <geometry>
                <mesh filename="package://g1_mujoco_description/meshes/inspire_hand/RH56F1_L/left_ring_1.STL"/>
            </geometry>
            <material name="">
                <color rgba="0.25 0.25 0.25 1"/>
            </material>
        </visual>
        <collision>
            <origin xyz="0 0 0" rpy="0 0 0"/>
            <geometry>
                <mesh filename="package://g1_mujoco_description/meshes/inspire_hand/RH56F1_L/left_ring_1.STL"/>
            </geometry>
        </collision>
    </link>
    <joint name="left_ring_1_joint" type="revolute">
        <origin xyz="0.00070746 0.0030876 0.13643" rpy="1.5184 0 0"/>
        <parent link="left_inspire_base_link"/>
        <child link="left_ring_1"/>
        <axis xyz="0 0 -1"/>
        <limit lower="0" upper="1.5285593588966337" effort="1" velocity="2"/>
    </joint>
    <link name="left_ring_2">
        <inertial>
            <origin xyz="-0.00436 0.015560000000000001 0.0068200000000000005" rpy="0 0 0"/>
            <mass value="0.0103"/>
            <inertia ixx="1.5669000000000002e-06" ixy="2.2425e-07" ixz="-1.1759999999999999e-08" iyy="2.959e-07" iyz="6.729e-08" izz="1.5758900000000002e-06"/>
        </inertial>
        <visual>
            <origin xyz="0 0 0" rpy="0 0 0"/>
            <geometry>
                <mesh filename="package://g1_mujoco_description/meshes/inspire_hand/RH56F1_L/left_ring_2.STL"/>
            </geometry>
            <material name="">
                <color rgba="0.25 0.25 0.25 1"/>
            </material>
        </visual>
        <collision>
            <origin xyz="0 0 0" rpy="0 0 0"/>
            <geometry>
                <mesh filename="package://g1_mujoco_description/meshes/inspire_hand/RH56F1_L/left_ring_2.STL"/>
            </geometry>
        </collision>
    </link>
    <joint name="left_ring_2_joint" type="revolute">
        <origin xyz="0.0031056 0.032854 -0.001" rpy="0 0 0"/>
        <parent link="left_ring_1"/>
        <child link="left_ring_2"/>
        <axis xyz="0 0 -1"/>
        <limit lower="0" upper="3.14" effort="1" velocity="2"/>
        <mimic joint="left_ring_1_joint" multiplier="1.1545" offset="0"/>
    </joint>
    <link name="left_inspire_ring_force_sensor">
        <inertial>
            <origin xyz="-0.000209715894633783 -0.0123187686132097 -0.00640384736210899" rpy="0 0 0"/>
            <mass value="0"/>
            <inertia ixx="0" ixy="0" ixz="0" iyy="0" iyz="0" izz="0"/>
        </inertial>
        <visual>
            <origin xyz="0 0 0" rpy="0 0 0"/>
            <geometry>
                <mesh filename="package://g1_mujoco_description/meshes/inspire_hand/RH56F1_L/ring_force_sensor.STL"/>
            </geometry>
            <material name="">
                <color rgba="0.25 0.25 0.25 1"/>
            </material>
        </visual>
        <collision>
            <origin xyz="0 0 0" rpy="0 0 0"/>
            <geometry>
                <mesh filename="package://g1_mujoco_description/meshes/inspire_hand/RH56F1_L/ring_force_sensor.STL"/>
            </geometry>
        </collision>
    </link>
    <joint name="left_inspire_ring_force_sensor_joint" type="fixed">
        <origin xyz="0.005139 0.028671 -0.0059996" rpy="2.4366 1.5033 2.2541"/>
        <parent link="left_ring_2"/>
        <child link="left_inspire_ring_force_sensor"/>
        <axis xyz="0 0 0"/>
    </joint>
    <link name="left_inspire_ring_tip">
        <inertial>
            <origin xyz="-0.00100385930577584 -0.0177521786857137 -0.0152723548834053" rpy="0 0 0"/>
            <mass value="0"/>
            <inertia ixx="0" ixy="0" ixz="0" iyy="0" iyz="0" izz="0"/>
        </inertial>
        <visual>
            <origin xyz="0 0 0" rpy="0 0 0"/>
            <geometry>
                <mesh filename="package://g1_mujoco_description/meshes/inspire_hand/RH56F1_L/ring_tip.STL"/>
            </geometry>
            <material name="">
                <color rgba="0.25 0.25 0.25 1"/>
            </material>
        </visual>
        <collision>
            <origin xyz="0 0 0" rpy="0 0 0"/>
            <geometry>
                <mesh filename="package://g1_mujoco_description/meshes/inspire_hand/RH56F1_L/ring_tip.STL"/>
            </geometry>
        </collision>
    </link>
    <joint name="left_inspire_ring_tip_joint" type="fixed">
        <origin xyz="0.0049188 0.039631 -0.006" rpy="1.5417 1.5157 1.889"/>
        <parent link="left_ring_2"/>
        <child link="left_inspire_ring_tip"/>
        <axis xyz="0 0 0"/>
    </joint>
    <link name="left_little_1">
        <inertial>
            <origin xyz="0.00046 0.013869999999999999 0.0085" rpy="0 0 0"/>
            <mass value="0.01111"/>
            <inertia ixx="2.04599e-06" ixy="3.6810000000000003e-08" ixz="-4.360000000000001e-09" iyy="5.527e-07" iyz="1.6568e-07" izz="2.07708e-06"/>
        </inertial>
        <visual>
            <origin xyz="0 0 0" rpy="0 0 0"/>
            <geometry>
                <mesh filename="package://g1_mujoco_description/meshes/inspire_hand/RH56F1_L/left_little_1.STL"/>
            </geometry>
            <material name="">
                <color rgba="0.25 0.25 0.25 1"/>
            </material>
        </visual>
        <collision>
            <origin xyz="0 0 0" rpy="0 0 0"/>
            <geometry>
                <mesh filename="package://g1_mujoco_description/meshes/inspire_hand/RH56F1_L/left_little_1.STL"/>
            </geometry>
        </collision>
    </link>
    <joint name="left_little_1_joint" type="revolute">
        <origin xyz="0.00070753 0.021094 0.13531" rpy="1.4661 0 0"/>
        <parent link="left_inspire_base_link"/>
        <child link="left_little_1"/>
        <axis xyz="0 0 -1"/>
        <limit lower="0" upper="1.5285593588966337" effort="1" velocity="2"/>
    </joint>
    <link name="left_little_2">
        <inertial>
            <origin xyz="-0.004070000000000001 0.01192 0.00728" rpy="0 0 0"/>
            <mass value="0.00839"/>
            <inertia ixx="9.3539e-07" ixy="1.6843e-07" ixz="-1.7670000000000002e-08" iyy="2.4681e-07" iyz="7.359e-08" izz="9.379400000000001e-07"/>
        </inertial>
        <visual>
            <origin xyz="0 0 0" rpy="0 0 0"/>
            <geometry>
                <mesh filename="package://g1_mujoco_description/meshes/inspire_hand/RH56F1_L/left_little_2.STL"/>
            </geometry>
            <material name="">
                <color rgba="0.25 0.25 0.25 1"/>
            </material>
        </visual>
        <collision>
            <origin xyz="0 0 0" rpy="0 0 0"/>
            <geometry>
                <mesh filename="package://g1_mujoco_description/meshes/inspire_hand/RH56F1_L/left_little_2.STL"/>
            </geometry>
        </collision>
    </link>
    <joint name="left_little_2_joint" type="revolute">
        <origin xyz="0.0031057 0.032854 -0.001" rpy="0 0 0"/>
        <parent link="left_little_1"/>
        <child link="left_little_2"/>
        <axis xyz="0 0 -1"/>
        <limit lower="0" upper="3.14" effort="1" velocity="2"/>
        <mimic joint="left_little_1_joint" multiplier="1.1545" offset="0"/>
    </joint>
    <link name="left_inspire_little_force_sensor">
        <inertial>
            <origin xyz="-0.000486995031034054 -0.00853489982845629 -0.00651155949691547" rpy="0 0 0"/>
            <mass value="0"/>
            <inertia ixx="0" ixy="0" ixz="0" iyy="0" iyz="0" izz="0"/>
        </inertial>
        <visual>
            <origin xyz="0 0 0" rpy="0 0 0"/>
            <geometry>
                <mesh filename="package://g1_mujoco_description/meshes/inspire_hand/RH56F1_L/little_force_sensor.STL"/>
            </geometry>
            <material name="">
                <color rgba="0.25 0.25 0.25 1"/>
            </material>
        </visual>
        <collision>
            <origin xyz="0 0 0" rpy="0 0 0"/>
            <geometry>
                <mesh filename="package://g1_mujoco_description/meshes/inspire_hand/RH56F1_L/little_force_sensor.STL"/>
            </geometry>
        </collision>
    </link>
    <joint name="left_inspire_little_force_sensor_joint" type="fixed">
        <origin xyz="0.0051314 0.021582 -0.0063543" rpy="2.0609 1.4616 1.858"/>
        <parent link="left_little_2"/>
        <child link="left_inspire_little_force_sensor"/>
        <axis xyz="0 0 0"/>
    </joint>
    <link name="left_inspire_little_tip">
        <inertial>
            <origin xyz="-0.00160676343735405 -0.0143780070321105 -0.0134619377604817" rpy="0 0 0"/>
            <mass value="0"/>
            <inertia ixx="0" ixy="0" ixz="0" iyy="0" iyz="0" izz="0"/>
        </inertial>
        <visual>
            <origin xyz="0 0 0" rpy="0 0 0"/>
            <geometry>
                <mesh filename="package://g1_mujoco_description/meshes/inspire_hand/RH56F1_L/little_tip.STL"/>
            </geometry>
            <material name="">
                <color rgba="0.25 0.25 0.25 1"/>
            </material>
        </visual>
        <collision>
            <origin xyz="0 0 0" rpy="0 0 0"/>
            <geometry>
                <mesh filename="package://g1_mujoco_description/meshes/inspire_hand/RH56F1_L/little_tip.STL"/>
            </geometry>
        </collision>
    </link>
    <joint name="left_inspire_little_tip_joint" type="fixed">
        <origin xyz="0.0051203 0.032544 -0.0063511" rpy="1.554 1.4608 1.8824"/>
        <parent link="left_little_2"/>
        <child link="left_inspire_little_tip"/>
        <axis xyz="0 0 0"/>
    </joint>
    <link name="left_inspire_plam_1">
        <inertial>
            <origin xyz="-0.00132 0.00039 0.07415000000000001" rpy="0 0 0"/>
            <mass value="0.41238"/>
            <inertia ixx="0.00078835939" ixy="-8.875e-07" ixz="3.202881e-05" iyy="0.00066648352" iyz="1.4681199999999999e-06" izz="0.00026678122"/>
        </inertial>
        <visual>
            <origin xyz="0 0 0" rpy="0 0 0"/>
            <geometry>
                <mesh filename="package://g1_mujoco_description/meshes/inspire_hand/RH56F1_L/plam_1.STL"/>
            </geometry>
            <material name="">
                <color rgba="1 1 1 1"/>
            </material>
        </visual>
        <collision>
            <origin xyz="0 0 0" rpy="0 0 0"/>
            <geometry>
                <mesh filename="package://g1_mujoco_description/meshes/inspire_hand/RH56F1_L/plam_1.STL"/>
            </geometry>
        </collision>
    </link>
    <joint name="left_inspire_plam_1_joint" type="fixed">
        <origin xyz="0 0 0.0305" rpy="0 0 0"/>
        <parent link="left_inspire_base_link"/>
        <child link="left_inspire_plam_1"/>
        <axis xyz="0 0 0"/>
    </joint>
    <link name="left_inspire_plam_2">
        <inertial>
            <origin xyz="0.00738877558367422 0.00286851435787733 0.0491990009538881" rpy="0 0 0"/>
            <mass value="0.01"/>
            <inertia ixx="7.42627311403438E-05" ixy="-1.51062288185372E-06" ixz="-1.38221866903039E-06" iyy="4.54002453711238E-05" iyz="3.52845387182101E-06" izz="3.50303789099898E-05"/>
        </inertial>
        <visual>
            <origin xyz="0 0 0" rpy="0 0 0"/>
            <geometry>
                <mesh filename="package://g1_mujoco_description/meshes/inspire_hand/RH56F1_L/plam_2.STL"/>
            </geometry>
            <material name="">
                <color rgba="0.25 0.25 0.25 1"/>
            </material>
        </visual>
        <collision>
            <origin xyz="0 0 0" rpy="0 0 0"/>
            <geometry>
                <mesh filename="package://g1_mujoco_description/meshes/inspire_hand/RH56F1_L/plam_2.STL"/>
            </geometry>
        </collision>
    </link>
    <joint name="left_inspire_plam_2_joint" type="fixed">
        <origin xyz="0 0 0" rpy="0 0 0"/>
        <parent link="left_inspire_plam_1"/>
        <child link="left_inspire_plam_2"/>
        <axis xyz="0 0 0"/>
    </joint>
    <link name="left_inspire_plam_3">
        <inertial>
            <origin xyz="-0.0145080707705958 -0.00297062755371721 0.0599886430688916" rpy="0 0 0"/>
            <mass value="0.01"/>
            <inertia ixx="7.44290151295326E-05" ixy="2.11550341708188E-06" ixz="3.5267344320077E-07" iyy="4.06594932990061E-05" iyz="-3.15566621908941E-06" izz="4.24832389559144E-05"/>
        </inertial>
        <visual>
            <origin xyz="0 0 0" rpy="0 0 0"/>
            <geometry>
                <mesh filename="package://g1_mujoco_description/meshes/inspire_hand/RH56F1_L/plam_3.STL"/>
            </geometry>
            <material name="">
                <color rgba="1 1 1 1"/>
            </material>
        </visual>
        <collision>
            <origin xyz="0 0 0" rpy="0 0 0"/>
            <geometry>
                <mesh filename="package://g1_mujoco_description/meshes/inspire_hand/RH56F1_L/plam_3.STL"/>
            </geometry>
        </collision>
    </link>
    <joint name="left_inspire_plam_3_joint" type="fixed">
        <origin xyz="0 0 0" rpy="0 0 0"/>
        <parent link="left_inspire_plam_2"/>
        <child link="left_inspire_plam_3"/>
        <axis xyz="0 0 0"/>
    </joint>
    <link name="left_inspire_plam_force_sensor">
        <inertial>
            <origin xyz="0.00135083432691963 -0.00241176672948407 -0.00177409386471654" rpy="0 0 0"/>
            <mass value="0.00449423213489162"/>
            <inertia ixx="2.77343430370559E-07" ixy="9.29194202733673E-12" ixz="-1.13995686775868E-12" iyy="1.25941926345234E-06" iyz="5.96425032363731E-09" izz="1.53055306696602E-06"/>
        </inertial>
        <visual>
            <origin xyz="0 0 0" rpy="0 0 0"/>
            <geometry>
                <mesh filename="package://g1_mujoco_description/meshes/inspire_hand/RH56F1_L/plam_force_sensor.STL"/>
            </geometry>
            <material name="">
                <color rgba="0.25 0.25 0.25 1"/>
            </material>
        </visual>
        <collision>
            <origin xyz="0 0 0" rpy="0 0 0"/>
            <geometry>
                <mesh filename="package://g1_mujoco_description/meshes/inspire_hand/RH56F1_L/plam_force_sensor.STL"/>
            </geometry>
        </collision>
    </link>
    <joint name="left_inspire_plam_force_sensor_joint" type="fixed">
        <origin xyz="0.01594 -0.0013505 0.073746" rpy="1.5708 0 1.5708"/>
        <parent link="left_inspire_plam_2"/>
        <child link="left_inspire_plam_force_sensor"/>
        <axis xyz="0 0 0"/>
    </joint>
  </xacro:macro>

  <xacro:macro name="rh56f1_right_hand" params="parent mount_xyz mount_rpy">
    <joint name="right_inspire_mount_joint" type="fixed">
        <origin xyz="${mount_xyz}" rpy="${mount_rpy}"/>
        <parent link="${parent}"/>
        <child link="right_inspire_base_link"/>
    </joint>
    <link name="right_inspire_base_link">
        <inertial>
            <origin xyz="0.000631584180168987 1.55468476565051E-09 0.0185710308410627" rpy="0 0 0"/>
            <mass value="0.0793945003608915"/>
            <inertia ixx="2.73302869871105E-05" ixy="4.73396056660905E-13" ixz="2.86328005285174E-08" iyy="2.62165141408126E-05" iyz="1.90463743334758E-12" izz="3.5682432554866E-05"/>
        </inertial>
        <visual>
            <origin xyz="0 0 0" rpy="0 0 0"/>
            <geometry>
                <mesh filename="package://g1_mujoco_description/meshes/inspire_hand/RH56F1_R/base_link.STL"/>
            </geometry>
            <material name="">
                <color rgba="1 1 1 1"/>
            </material>
        </visual>
        <collision>
            <origin xyz="0 0 0" rpy="0 0 0"/>
            <geometry>
                <mesh filename="package://g1_mujoco_description/meshes/inspire_hand/RH56F1_R/base_link.STL"/>
            </geometry>
        </collision>
    </link>
    <link name="right_inspire_plam_1">
        <inertial>
            <origin xyz="-0.00132 0.00039 0.07415000000000001" rpy="0 0 0"/>
            <mass value="0.41238"/>
            <inertia ixx="0.00078835939" ixy="8.875e-07" ixz="3.202881e-05" iyy="0.00066648352" iyz="-1.4681199999999999e-06" izz="0.00026678122"/>
        </inertial>
        <visual>
            <origin xyz="0 0 0" rpy="0 0 0"/>
            <geometry>
                <mesh filename="package://g1_mujoco_description/meshes/inspire_hand/RH56F1_R/plam_1.STL"/>
            </geometry>
            <material name="">
                <color rgba="0.866666666666667 0.866666666666667 0.890196078431372 1"/>
            </material>
        </visual>
        <collision>
            <origin xyz="0 0 0" rpy="0 0 0"/>
            <geometry>
                <mesh filename="package://g1_mujoco_description/meshes/inspire_hand/RH56F1_R/plam_1.STL"/>
            </geometry>
        </collision>
    </link>
    <joint name="right_inspire_plam_1_joint" type="fixed">
        <origin xyz="0 0 0.0305" rpy="0 0 0"/>
        <parent link="right_inspire_base_link"/>
        <child link="right_inspire_plam_1"/>
        <axis xyz="0 0 0"/>
    </joint>
    <link name="right_inspire_plam_2">
        <inertial>
            <origin xyz="0.00780742986700294 -0.00181684242732992 0.0484726926194218" rpy="0 0 0"/>
            <mass value="0.01"/>
            <inertia ixx="7.53775883572448E-05" ixy="1.67198206435067E-06" ixz="-1.35138361804759E-06" iyy="4.62768852730386E-05" iyz="-3.66656859035162E-06" izz="3.55364070799627E-05"/>
        </inertial>
        <visual>
            <origin xyz="0 0 0" rpy="0 0 0"/>
            <geometry>
                <mesh filename="package://g1_mujoco_description/meshes/inspire_hand/RH56F1_R/plam_2.STL"/>
            </geometry>
            <material name="">
                <color rgba="0.25 0.25 0.25 1"/>
            </material>
        </visual>
        <collision>
            <origin xyz="0 0 0" rpy="0 0 0"/>
            <geometry>
                <mesh filename="package://g1_mujoco_description/meshes/inspire_hand/RH56F1_R/plam_2.STL"/>
            </geometry>
        </collision>
    </link>
    <joint name="right_inspire_plam_2_joint" type="fixed">
        <origin xyz="0 0 0" rpy="0 0 0"/>
        <parent link="right_inspire_plam_1"/>
        <child link="right_inspire_plam_2"/>
        <axis xyz="0 0 0"/>
    </joint>
    <link name="right_inspire_plam_3">
        <inertial>
            <origin xyz="-0.0145087315400233 0.00297298156011864 0.0599801851672911" rpy="0 0 0"/>
            <mass value="0.01"/>
            <inertia ixx="7.44229190374554E-05" ixy="-2.11457285174435E-06" ixz="3.53419391577662E-07" iyy="4.06574859268604E-05" iyz="3.15838633047347E-06" izz="4.24785219389853E-05"/>
        </inertial>
        <visual>
            <origin xyz="0 0 0" rpy="0 0 0"/>
            <geometry>
                <mesh filename="package://g1_mujoco_description/meshes/inspire_hand/RH56F1_R/plam_3.STL"/>
            </geometry>
            <material name="">
                <color rgba="1 1 1 1"/>
            </material>
        </visual>
        <collision>
            <origin xyz="0 0 0" rpy="0 0 0"/>
            <geometry>
                <mesh filename="package://g1_mujoco_description/meshes/inspire_hand/RH56F1_R/plam_3.STL"/>
            </geometry>
        </collision>
    </link>
    <joint name="right_inspire_plam_3_jont" type="fixed">
        <origin xyz="0 0 0" rpy="0 0 0"/>
        <parent link="right_inspire_plam_2"/>
        <child link="right_inspire_plam_3"/>
        <axis xyz="0 0 0"/>
    </joint>
    <link name="right_inspire_plam_force_sensor">
        <inertial>
            <origin xyz="0.00135015380328561 -0.00241176259562209 -0.00177409297911233" rpy="0 0 0"/>
            <mass value="0.00449423927061171"/>
            <inertia ixx="2.77343347350042E-07" ixy="-5.59517451189968E-13" ixz="2.86825536833881E-13" iyy="1.25942537762186E-06" iyz="5.96429255234865E-09" izz="1.53055908452317E-06"/>
        </inertial>
        <visual>
            <origin xyz="0 0 0" rpy="0 0 0"/>
            <geometry>
                <mesh filename="package://g1_mujoco_description/meshes/inspire_hand/RH56F1_R/plam_force_sensor.STL"/>
            </geometry>
            <material name="">
                <color rgba="0.298039215686275 0.298039215686275 0.298039215686275 1"/>
            </material>
        </visual>
        <collision>
            <origin xyz="0 0 0" rpy="0 0 0"/>
            <geometry>
                <mesh filename="package://g1_mujoco_description/meshes/inspire_hand/RH56F1_R/plam_force_sensor.STL"/>
            </geometry>
        </collision>
    </link>
    <joint name="right_inspire_plam_force_sensor_joint" type="fixed">
        <origin xyz="0.0159401947506102 -0.00135045394126701 0.0737460952299602" rpy="1.5707963267949 0 1.5707963267949"/>
        <parent link="right_inspire_plam_2"/>
        <child link="right_inspire_plam_force_sensor"/>
        <axis xyz="0 0 0"/>
    </joint>
    <link name="right_thumb_1">
        <inertial>
            <origin xyz="-0.00015 0.00544 -0.0048200000000000005" rpy="0 0 0"/>
            <mass value="0.016800000000000002"/>
            <inertia ixx="7.3387e-07" ixy="-1.436e-08" ixz="-1.11e-09" iyy="2.7925e-07" iyz="-3.296e-08" izz="5.8189e-07"/>
        </inertial>
        <visual>
            <origin xyz="0 0 0" rpy="0 0 0"/>
            <geometry>
                <mesh filename="package://g1_mujoco_description/meshes/inspire_hand/RH56F1_R/right_thumb_1.STL"/>
            </geometry>
            <material name="">
                <color rgba="1 1 1 1"/>
            </material>
        </visual>
        <collision>
            <origin xyz="0 0 0" rpy="0 0 0"/>
            <geometry>
                <mesh filename="package://g1_mujoco_description/meshes/inspire_hand/RH56F1_R/right_thumb_1.STL"/>
            </geometry>
        </collision>
    </link>
    <joint name="right_thumb_1_joint" type="revolute">
        <origin xyz="0.01836 0.027241 0.070511" rpy="0 0 0"/>
        <parent link="right_inspire_base_link"/>
        <child link="right_thumb_1"/>
        <axis xyz="8.7274E-05 0 -1"/>
        <limit lower="0" upper="2.0943951023931953" effort="1" velocity="2"/>
    </joint>
    <link name="right_thumb_2">
        <inertial>
            <origin xyz="-0.0238 0.01042 0.00478" rpy="0 0 0"/>
            <mass value="0.06526"/>
            <inertia ixx="1.378224e-05" ixy="5.95663e-06" ixz="-1.9799999999999998e-09" iyy="1.1840129999999999e-05" iyz="7.070000000000001e-09" izz="2.249189e-05"/>
        </inertial>
        <visual>
            <origin xyz="0 0 0" rpy="0 0 0"/>
            <geometry>
                <mesh filename="package://g1_mujoco_description/meshes/inspire_hand/RH56F1_R/right_thumb_2.STL"/>
            </geometry>
            <material name="">
                <color rgba="0.25 0.25 0.25 1"/>
            </material>
        </visual>
        <collision>
            <origin xyz="0 0 0" rpy="0 0 0"/>
            <geometry>
                <mesh filename="package://g1_mujoco_description/meshes/inspire_hand/RH56F1_R/right_thumb_2.STL"/>
            </geometry>
        </collision>
    </link>
    <joint name="right_thumb_2_joint" type="revolute">
        <origin xyz="0.0047995 0.013396 -0.0052536" rpy="1.5707 0 -1.5708"/>
        <parent link="right_thumb_1"/>
        <child link="right_thumb_2"/>
        <axis xyz="0 0 -1"/>
        <limit lower="0" upper="0.4745550236172582" effort="1" velocity="2"/>
    </joint>
    <link name="right_thumb_3">
        <inertial>
            <origin xyz="-0.01255 0.00331 0.00799" rpy="0 0 0"/>
            <mass value="0.01333"/>
            <inertia ixx="1.41987e-06" ixy="1.4979e-07" ixz="-6.3e-10" iyy="1.18482e-06" iyz="1.76e-09" izz="1.6920999999999999e-06"/>
        </inertial>
        <visual>
            <origin xyz="0 0 0" rpy="0 0 0"/>
            <geometry>
                <mesh filename="package://g1_mujoco_description/meshes/inspire_hand/RH56F1_R/right_thumb_3.STL"/>
            </geometry>
            <material name="">
                <color rgba="0.25 0.25 0.25 1"/>
            </material>
        </visual>
        <collision>
            <origin xyz="0 0 0" rpy="0 0 0"/>
            <geometry>
                <mesh filename="package://g1_mujoco_description/meshes/inspire_hand/RH56F1_R/right_thumb_3.STL"/>
            </geometry>
        </collision>
    </link>
    <joint name="right_thumb_3_joint" type="revolute">
        <origin xyz="-0.029155 0.03869 -0.0032" rpy="0 0 0"/>
        <parent link="right_thumb_2"/>
        <child link="right_thumb_3"/>
        <axis xyz="0 0 -1"/>
        <limit lower="0" upper="3.14" effort="1" velocity="2"/>
        <mimic joint="right_thumb_2_joint" multiplier="1.2953" offset="0"/>
    </joint>
    <link name="right_thumb_4">
        <inertial>
            <origin xyz="-0.010199999999999999 0.00886 0.0067" rpy="0 0 0"/>
            <mass value="0.011439999999999999"/>
            <inertia ixx="9.4221e-07" ixy="1.6288e-07" ixz="-0.0" iyy="3.9966e-07" iyz="-0.0" izz="9.478099999999999e-07"/>
        </inertial>
        <visual>
            <origin xyz="0 0 0" rpy="0 0 0"/>
            <geometry>
                <mesh filename="package://g1_mujoco_description/meshes/inspire_hand/RH56F1_R/right_thumb_4.STL"/>
            </geometry>
            <material name="">
                <color rgba="0.25 0.25 0.25 1"/>
            </material>
        </visual>
        <collision>
            <origin xyz="0 0 0" rpy="0 0 0"/>
            <geometry>
                <mesh filename="package://g1_mujoco_description/meshes/inspire_hand/RH56F1_R/right_thumb_4.STL"/>
            </geometry>
        </collision>
    </link>
    <joint name="right_thumb_4_joint" type="revolute">
        <origin xyz="-0.01441 0.014648 0.0013" rpy="0 0 0"/>
        <parent link="right_thumb_3"/>
        <child link="right_thumb_4"/>
        <axis xyz="0 0 -1"/>
        <limit lower="0" upper="3.14" effort="1" velocity="2"/>
        <mimic joint="right_thumb_3_joint" multiplier="0.8962" offset="0"/>
    </joint>
    <link name="right_inspire_thumb_force_sensor">
        <inertial>
            <origin xyz="0.0048965432924319 0.000707788830417878 -0.00883745365301308" rpy="0 0 0"/>
            <mass value="0"/>
            <inertia ixx="0" ixy="0" ixz="0" iyy="0" iyz="0" izz="0"/>
        </inertial>
        <visual>
            <origin xyz="0 0 0" rpy="0 0 0"/>
            <geometry>
                <mesh filename="package://g1_mujoco_description/meshes/inspire_hand/RH56F1_R/thumb_force_sensor.STL"/>
            </geometry>
            <material name="">
                <color rgba="0.25 0.25 0.25 1"/>
            </material>
        </visual>
        <collision>
            <origin xyz="0 0 0" rpy="0 0 0"/>
            <geometry>
                <mesh filename="package://g1_mujoco_description/meshes/inspire_hand/RH56F1_R/thumb_force_sensor.STL"/>
            </geometry>
        </collision>
    </link>
    <joint name="right_inspire_thumb_force_sensor_joint" type="fixed">
        <origin xyz="-0.0082761 0.019128 0.0068" rpy="-1.6222 -0.051489 -0.78543"/>
        <parent link="right_thumb_4"/>
        <child link="right_inspire_thumb_force_sensor"/>
        <axis xyz="0 0 0"/>
    </joint>
    <link name="right_inspire_thumb_tip">
        <inertial>
            <origin xyz="3.77562735170631E-05 -0.0101703967740828 -0.0136494381069971" rpy="0 0 0"/>
            <mass value="0"/>
            <inertia ixx="0" ixy="0" ixz="0" iyy="0" iyz="0" izz="0"/>
        </inertial>
        <visual>
            <origin xyz="0 0 0" rpy="0 0 0"/>
            <geometry>
                <mesh filename="package://g1_mujoco_description/meshes/inspire_hand/RH56F1_R/thumb_tip.STL"/>
            </geometry>
            <material name="">
                <color rgba="0.25 0.25 0.25 1"/>
            </material>
        </visual>
        <collision>
            <origin xyz="0 0 0" rpy="0 0 0"/>
            <geometry>
                <mesh filename="package://g1_mujoco_description/meshes/inspire_hand/RH56F1_R/thumb_tip.STL"/>
            </geometry>
        </collision>
    </link>
    <joint name="right_inspire_thumb_tip_joint" type="fixed">
        <origin xyz="-0.017405 0.025196 0.0068001" rpy="-1.2971 1.5647 0.01425"/>
        <parent link="right_thumb_4"/>
        <child link="right_inspire_thumb_tip"/>
        <axis xyz="0 0 0"/>
    </joint>
    <link name="right_index_1">
        <inertial>
            <origin xyz="0.00046 0.01509 0.0060999999999999995" rpy="0 0 0"/>
            <mass value="0.01111"/>
            <inertia ixx="2.04599e-06" ixy="-3.703e-08" ixz="1.77e-09" iyy="5.4029e-07" iyz="9.149e-08" izz="2.0895e-06"/>
        </inertial>
        <visual>
            <origin xyz="0 0 0" rpy="0 0 0"/>
            <geometry>
                <mesh filename="package://g1_mujoco_description/meshes/inspire_hand/RH56F1_R/right_index_1.STL"/>
            </geometry>
            <material name="">
                <color rgba="0.25 0.25 0.25 1"/>
            </material>
        </visual>
        <collision>
            <origin xyz="0 0 0" rpy="0 0 0"/>
            <geometry>
                <mesh filename="package://g1_mujoco_description/meshes/inspire_hand/RH56F1_R/right_index_1.STL"/>
            </geometry>
        </collision>
    </link>
    <joint name="right_index_1_joint" type="revolute">
        <origin xyz="0.00070751 0.034376 0.13554" rpy="1.5097 0 0"/>
        <parent link="right_inspire_base_link"/>
        <child link="right_index_1"/>
        <axis xyz="0 0 -1"/>
        <limit lower="0" upper="1.5285593588966337" effort="1" velocity="2"/>
    </joint>
    <link name="right_index_2">
        <inertial>
            <origin xyz="-0.00436 0.01623 0.005019999999999999" rpy="0 0 0"/>
            <mass value="0.0103"/>
            <inertia ixx="1.5669000000000002e-06" ixy="-2.2414e-07" ixz="1.3699999999999999e-08" iyy="2.9717e-07" iyz="7.84e-08" izz="1.5746300000000001e-06"/>
        </inertial>
        <visual>
            <origin xyz="0 0 0" rpy="0 0 0"/>
            <geometry>
                <mesh filename="package://g1_mujoco_description/meshes/inspire_hand/RH56F1_R/right_index_2.STL"/>
            </geometry>
            <material name="">
                <color rgba="0.25 0.25 0.25 1"/>
            </material>
        </visual>
        <collision>
            <origin xyz="0 0 0" rpy="0 0 0"/>
            <geometry>
                <mesh filename="package://g1_mujoco_description/meshes/inspire_hand/RH56F1_R/right_index_2.STL"/>
            </geometry>
        </collision>
    </link>
    <joint name="right_index_2_joint" type="revolute">
        <origin xyz="0.0031056 0.032854 0.001" rpy="0 0 0"/>
        <parent link="right_index_1"/>
        <child link="right_index_2"/>
        <axis xyz="0 0 -1"/>
        <limit lower="0" upper="3.14" effort="1" velocity="2"/>
        <mimic joint="right_index_1_joint" multiplier="1.1545" offset="0"/>
    </joint>
    <link name="right_inspire_index_force_sensor">
        <inertial>
            <origin xyz="-0.000411923019764227 -0.0123118470405642 -0.00640361541021662" rpy="0 0 0"/>
            <mass value="0"/>
            <inertia ixx="0" ixy="0" ixz="0" iyy="0" iyz="0" izz="0"/>
        </inertial>
        <visual>
            <origin xyz="0 0 0" rpy="0 0 0"/>
            <geometry>
                <mesh filename="package://g1_mujoco_description/meshes/inspire_hand/RH56F1_R/index_force_sensor.STL"/>
            </geometry>
            <material name="">
                <color rgba="0.25 0.25 0.25 1"/>
            </material>
        </visual>
        <collision>
            <origin xyz="0 0 0" rpy="0 0 0"/>
            <geometry>
                <mesh filename="package://g1_mujoco_description/meshes/inspire_hand/RH56F1_R/index_force_sensor.STL"/>
            </geometry>
        </collision>
    </link>
    <joint name="right_inspire_index_force_sensor_joint" type="fixed">
        <origin xyz="0.005139 0.028671 0.0059996" rpy="2.2782 1.4918 2.0953"/>
        <parent link="right_index_2"/>
        <child link="right_inspire_index_force_sensor"/>
        <axis xyz="0 0 0"/>
    </joint>
    <link name="right_inspire_index_tip">
        <inertial>
            <origin xyz="-0.00116882659469011 -0.0177404684378123 -0.0152714634926817" rpy="0 0 0"/>
            <mass value="0"/>
            <inertia ixx="0" ixy="0" ixz="0" iyy="0" iyz="0" izz="0"/>
        </inertial>
        <visual>
            <origin xyz="0 0 0" rpy="0 0 0"/>
            <geometry>
                <mesh filename="package://g1_mujoco_description/meshes/inspire_hand/RH56F1_R/index_tip.STL"/>
            </geometry>
            <material name="">
                <color rgba="0.25 0.25 0.25 1"/>
            </material>
        </visual>
        <collision>
            <origin xyz="0 0 0" rpy="0 0 0"/>
            <geometry>
                <mesh filename="package://g1_mujoco_description/meshes/inspire_hand/RH56F1_R/index_tip.STL"/>
            </geometry>
        </collision>
    </link>
    <joint name="right_inspire_index_tip_joint" type="fixed">
        <origin xyz="0.0049188 0.039631 0.006" rpy="1.5446 1.5064 1.892"/>
        <parent link="right_index_2"/>
        <child link="right_inspire_index_tip"/>
        <axis xyz="0 0 0"/>
    </joint>
    <link name="right_middle_1">
        <inertial>
            <origin xyz="0.00046 0.01468 0.00701" rpy="0 0 0"/>
            <mass value="0.01111"/>
            <inertia ixx="2.04599e-06" ixy="-3.707e-08" ixz="-4.9e-10" iyy="5.3491e-07" iyz="-3.6e-09" izz="2.09487e-06"/>
        </inertial>
        <visual>
            <origin xyz="0 0 0" rpy="0 0 0"/>
            <geometry>
                <mesh filename="package://g1_mujoco_description/meshes/inspire_hand/RH56F1_R/right_middle_1.STL"/>
            </geometry>
            <material name="">
                <color rgba="0.25 0.25 0.25 1"/>
            </material>
        </visual>
        <collision>
            <origin xyz="0 0 0" rpy="0 0 0"/>
            <geometry>
                <mesh filename="package://g1_mujoco_description/meshes/inspire_hand/RH56F1_R/right_middle_1.STL"/>
            </geometry>
        </collision>
    </link>
    <joint name="right_middle_1_joint" type="revolute">
        <origin xyz="0.00070746 0.015767 0.13648" rpy="1.5708 0 0"/>
        <parent link="right_inspire_base_link"/>
        <child link="right_middle_1"/>
        <axis xyz="0 0 -1"/>
        <limit lower="0" upper="1.5285593588966337" effort="1" velocity="2"/>
    </joint>
    <link name="right_middle_2">
        <inertial>
            <origin xyz="-0.004019999999999999 0.01731 0.006" rpy="0 0 0"/>
            <mass value="0.01122"/>
            <inertia ixx="1.92755e-06" ixy="-2.9305e-07" ixz="-1.0000000000000001e-11" iyy="3.2973000000000003e-07" iyz="-1.0000000000000001e-11" izz="1.95229e-06"/>
        </inertial>
        <visual>
            <origin xyz="0 0 0" rpy="0 0 0"/>
            <geometry>
                <mesh filename="package://g1_mujoco_description/meshes/inspire_hand/RH56F1_R/right_middle_2.STL"/>
            </geometry>
            <material name="">
                <color rgba="0.25 0.25 0.25 1"/>
            </material>
        </visual>
        <collision>
            <origin xyz="0 0 0" rpy="0 0 0"/>
            <geometry>
                <mesh filename="package://g1_mujoco_description/meshes/inspire_hand/RH56F1_R/right_middle_2.STL"/>
            </geometry>
        </collision>
    </link>
    <joint name="right_middle_2_joint" type="revolute">
        <origin xyz="0.0031056 0.032854 0.001" rpy="0 0 0"/>
        <parent link="right_middle_1"/>
        <child link="right_middle_2"/>
        <axis xyz="0 0 -1"/>
        <limit lower="0" upper="3.14" effort="1" velocity="2"/>
        <mimic joint="right_middle_1_joint" multiplier="1.1545" offset="0"/>
    </joint>
    <link name="right_inspire_middle_force_sensor">
        <inertial>
            <origin xyz="0.000471532938695406 -0.0138846665754712 -0.0063422335367961" rpy="0 0 0"/>
            <mass value="0"/>
            <inertia ixx="0" ixy="0" ixz="0" iyy="0" iyz="0" izz="0"/>
        </inertial>
        <visual>
            <origin xyz="0 0 0" rpy="0 0 0"/>
            <geometry>
                <mesh filename="package://g1_mujoco_description/meshes/inspire_hand/RH56F1_R/middle_force_sensor.STL"/>
            </geometry>
            <material name="">
                <color rgba="0.25 0.25 0.25 1"/>
            </material>
        </visual>
        <collision>
            <origin xyz="0 0 0" rpy="0 0 0"/>
            <geometry>
                <mesh filename="package://g1_mujoco_description/meshes/inspire_hand/RH56F1_R/middle_force_sensor.STL"/>
            </geometry>
        </collision>
    </link>
    <joint name="right_inspire_middle_force_sensor_joint" type="fixed">
        <origin xyz="0.0059655 0.031551 0.0060998" rpy="-2.9405 1.5184 3.1416"/>
        <parent link="right_middle_2"/>
        <child link="right_inspire_middle_force_sensor"/>
        <axis xyz="0 0 0"/>
    </joint>
    <link name="right_inspire_middle_tip">
        <inertial>
            <origin xyz="-1.56032137985686E-05 -0.0191696833676399 -0.0160122884402975" rpy="0 0 0"/>
            <mass value="0"/>
            <inertia ixx="0" ixy="0" ixz="0" iyy="0" iyz="0" izz="0"/>
        </inertial>
        <visual>
            <origin xyz="0 0 0" rpy="0 0 0"/>
            <geometry>
                <mesh filename="package://g1_mujoco_description/meshes/inspire_hand/RH56F1_R/middle_tip.STL"/>
            </geometry>
            <material name="">
                <color rgba="0.25 0.25 0.25 1"/>
            </material>
        </visual>
        <collision>
            <origin xyz="0 0 0" rpy="0 0 0"/>
            <geometry>
                <mesh filename="package://g1_mujoco_description/meshes/inspire_hand/RH56F1_R/middle_tip.STL"/>
            </geometry>
        </collision>
    </link>
    <joint name="right_inspire_middle_tip_joint" type="fixed">
        <origin xyz="0.0059647 0.042512 0.0060998" rpy="-0.3273 1.5691 0"/>
        <parent link="right_middle_2"/>
        <child link="right_inspire_middle_tip"/>
        <axis xyz="0 0 0"/>
    </joint>
    <link name="right_ring_1">
        <inertial>
            <origin xyz="0.00046 0.0143 0.00777" rpy="0 0 0"/>
            <mass value="0.01111"/>
            <inertia ixx="2.04599e-06" ixy="-3.699e-08" ixz="-2.43e-09" iyy="5.395599999999999e-07" iyz="-8.511e-08" izz="2.09023e-06"/>
        </inertial>
        <visual>
            <origin xyz="0 0 0" rpy="0 0 0"/>
            <geometry>
                <mesh filename="package://g1_mujoco_description/meshes/inspire_hand/RH56F1_R/right_ring_1.STL"/>
            </geometry>
            <material name="">
                <color rgba="0.25 0.25 0.25 1"/>
            </material>
        </visual>
        <collision>
            <origin xyz="0 0 0" rpy="0 0 0"/>
            <geometry>
                <mesh filename="package://g1_mujoco_description/meshes/inspire_hand/RH56F1_R/right_ring_1.STL"/>
            </geometry>
        </collision>
    </link>
    <joint name="right_ring_1_joint" type="revolute">
        <origin xyz="0.00070746 -0.0030876 0.13643" rpy="1.6232 0 0"/>
        <parent link="right_inspire_base_link"/>
        <child link="right_ring_1"/>
        <axis xyz="0 0 -1"/>
        <limit lower="0" upper="1.5285593588966337" effort="1" velocity="2"/>
    </joint>
    <link name="right_ring_2">
        <inertial>
            <origin xyz="-0.00436 0.015560000000000001 0.0068200000000000005" rpy="0 0 0"/>
            <mass value="0.0103"/>
            <inertia ixx="1.5669000000000002e-06" ixy="-2.2425e-07" ixz="-1.1759999999999999e-08" iyy="2.959e-07" iyz="-6.729e-08" izz="1.5758900000000002e-06"/>
        </inertial>
        <visual>
            <origin xyz="0 0 0" rpy="0 0 0"/>
            <geometry>
                <mesh filename="package://g1_mujoco_description/meshes/inspire_hand/RH56F1_R/right_ring_2.STL"/>
            </geometry>
            <material name="">
                <color rgba="0.25 0.25 0.25 1"/>
            </material>
        </visual>
        <collision>
            <origin xyz="0 0 0" rpy="0 0 0"/>
            <geometry>
                <mesh filename="package://g1_mujoco_description/meshes/inspire_hand/RH56F1_R/right_ring_2.STL"/>
            </geometry>
        </collision>
    </link>
    <joint name="right_ring_2_joint" type="revolute">
        <origin xyz="0.0031056 0.032854 0.001" rpy="0 0 0"/>
        <parent link="right_ring_1"/>
        <child link="right_ring_2"/>
        <axis xyz="0 0 -1"/>
        <limit lower="0" upper="3.14" effort="1" velocity="2"/>
        <mimic joint="right_ring_1_joint" multiplier="1.1545" offset="0"/>
    </joint>
    <link name="right_inspire_ring_force_sensor">
        <inertial>
            <origin xyz="0.00109767398054146 -0.0122697321740606 -0.00640361768517552" rpy="0 0 0"/>
            <mass value="0"/>
            <inertia ixx="0" ixy="0" ixz="0" iyy="0" iyz="0" izz="0"/>
        </inertial>
        <visual>
            <origin xyz="0 0 0" rpy="0 0 0"/>
            <geometry>
                <mesh filename="package://g1_mujoco_description/meshes/inspire_hand/RH56F1_R/ring_force_sensor.STL"/>
            </geometry>
            <material name="">
                <color rgba="0.25 0.25 0.25 1"/>
            </material>
        </visual>
        <collision>
            <origin xyz="0 0 0" rpy="0 0 0"/>
            <geometry>
                <mesh filename="package://g1_mujoco_description/meshes/inspire_hand/RH56F1_R/ring_force_sensor.STL"/>
            </geometry>
        </collision>
    </link>
    <joint name="right_inspire_ring_force_sensor_joint" type="fixed">
        <origin xyz="0.005139 0.028671 0.0059996" rpy="-2.2589 1.4899 -2.4386"/>
        <parent link="right_ring_2"/>
        <child link="right_inspire_ring_force_sensor"/>
        <axis xyz="0 0 0"/>
    </joint>
    <link name="right_inspire_ring_tip">
        <inertial>
            <origin xyz="0.000974578618407327 -0.0177521976538281 -0.015271465020787" rpy="0 0 0"/>
            <mass value="0"/>
            <inertia ixx="0" ixy="0" ixz="0" iyy="0" iyz="0" izz="0"/>
        </inertial>
        <visual>
            <origin xyz="0 0 0" rpy="0 0 0"/>
            <geometry>
                <mesh filename="package://g1_mujoco_description/meshes/inspire_hand/RH56F1_R/ring_tip.STL"/>
            </geometry>
            <material name="">
                <color rgba="0.25 0.25 0.25 1"/>
            </material>
        </visual>
        <collision>
            <origin xyz="0 0 0" rpy="0 0 0"/>
            <geometry>
                <mesh filename="package://g1_mujoco_description/meshes/inspire_hand/RH56F1_R/ring_tip.STL"/>
            </geometry>
        </collision>
    </link>
    <joint name="right_inspire_ring_tip_joint" type="fixed">
        <origin xyz="0.0049188 0.039631 0.006" rpy="-1.5409 1.5145 -1.1936"/>
        <parent link="right_ring_2"/>
        <child link="right_inspire_ring_tip"/>
        <axis xyz="0 0 0"/>
    </joint>
    <link name="right_little_1">
        <inertial>
            <origin xyz="0.00046 0.013869999999999999 0.0085" rpy="0 0 0"/>
            <mass value="0.01111"/>
            <inertia ixx="2.04599e-06" ixy="-3.6810000000000003e-08" ixz="-4.360000000000001e-09" iyy="5.527e-07" iyz="-1.6568e-07" izz="2.07708e-06"/>
        </inertial>
        <visual>
            <origin xyz="0 0 0" rpy="0 0 0"/>
            <geometry>
                <mesh filename="package://g1_mujoco_description/meshes/inspire_hand/RH56F1_R/right_little_1.STL"/>
            </geometry>
            <material name="">
                <color rgba="0.25 0.25 0.25 1"/>
            </material>
        </visual>
        <collision>
            <origin xyz="0 0 0" rpy="0 0 0"/>
            <geometry>
                <mesh filename="package://g1_mujoco_description/meshes/inspire_hand/RH56F1_R/right_little_1.STL"/>
            </geometry>
        </collision>
    </link>
    <joint name="right_little_1_joint" type="revolute">
        <origin xyz="0.00070753 -0.021451 0.13527" rpy="1.6755 0 0"/>
        <parent link="right_inspire_base_link"/>
        <child link="right_little_1"/>
        <axis xyz="0 0 -1"/>
        <limit lower="0" upper="1.5285593588966337" effort="1" velocity="2"/>
    </joint>
    <link name="right_little_2">
        <inertial>
            <origin xyz="-0.004070000000000001 0.01192 0.00728" rpy="0 0 0"/>
            <mass value="0.00839"/>
            <inertia ixx="9.3539e-07" ixy="-1.6843e-07" ixz="-1.7670000000000002e-08" iyy="2.4681e-07" iyz="-7.359e-08" izz="9.379400000000001e-07"/>
        </inertial>
        <visual>
            <origin xyz="0 0 0" rpy="0 0 0"/>
            <geometry>
                <mesh filename="package://g1_mujoco_description/meshes/inspire_hand/RH56F1_R/right_little_2.STL"/>
            </geometry>
            <material name="">
                <color rgba="0.25 0.25 0.25 1"/>
            </material>
        </visual>
        <collision>
            <origin xyz="0 0 0" rpy="0 0 0"/>
            <geometry>
                <mesh filename="package://g1_mujoco_description/meshes/inspire_hand/RH56F1_R/right_little_2.STL"/>
            </geometry>
        </collision>
    </link>
    <joint name="right_little_2_joint" type="revolute">
        <origin xyz="0.0031057 0.032854 0.001" rpy="0 0 0"/>
        <parent link="right_little_1"/>
        <child link="right_little_2"/>
        <axis xyz="0 0 -1"/>
        <limit lower="0" upper="3.14" effort="1" velocity="2"/>
        <mimic joint="right_little_1_joint" multiplier="1.1545" offset="0"/>
    </joint>
    <link name="right_inspire_little_force_sensor">
        <inertial>
            <origin xyz="0.00132747018137316 -0.00844356465788672 -0.00651118992676019" rpy="0 0 0"/>
            <mass value="0"/>
            <inertia ixx="0" ixy="0" ixz="0" iyy="0" iyz="0" izz="0"/>
        </inertial>
        <visual>
            <origin xyz="0 0 0" rpy="0 0 0"/>
            <geometry>
                <mesh filename="package://g1_mujoco_description/meshes/inspire_hand/RH56F1_R/little_force_sensor.STL"/>
            </geometry>
            <material name="">
                <color rgba="0.25 0.25 0.25 1"/>
            </material>
        </visual>
        <collision>
            <origin xyz="0 0 0" rpy="0 0 0"/>
            <geometry>
                <mesh filename="package://g1_mujoco_description/meshes/inspire_hand/RH56F1_R/little_force_sensor.STL"/>
            </geometry>
        </collision>
    </link>
    <joint name="right_inspire_little_force_sensor_joint" type="fixed">
        <origin xyz="0.0051314 0.021582 0.0059959" rpy="-1.9859 1.443 -2.1833"/>
        <parent link="right_little_2"/>
        <child link="right_inspire_little_force_sensor"/>
        <axis xyz="0 0 0"/>
    </joint>
    <link name="right_inspire_little_tip">
        <inertial>
            <origin xyz="0.00157850769633822 -0.0143797245335056 -0.0134611237924734" rpy="0 0 0"/>
            <mass value="0"/>
            <inertia ixx="0" ixy="0" ixz="0" iyy="0" iyz="0" izz="0"/>
        </inertial>
        <visual>
            <origin xyz="0 0 0" rpy="0 0 0"/>
            <geometry>
                <mesh filename="package://g1_mujoco_description/meshes/inspire_hand/RH56F1_R/little_tip.STL"/>
            </geometry>
            <material name="">
                <color rgba="0.25 0.25 0.25 1"/>
            </material>
        </visual>
        <collision>
            <origin xyz="0 0 0" rpy="0 0 0"/>
            <geometry>
                <mesh filename="package://g1_mujoco_description/meshes/inspire_hand/RH56F1_R/little_tip.STL"/>
            </geometry>
        </collision>
    </link>
    <joint name="right_inspire_little_tip_joint" type="fixed">
        <origin xyz="0.0051203 0.032544 0.0059927" rpy="-1.5577 1.4597 -1.2296"/>
        <parent link="right_little_2"/>
        <child link="right_inspire_little_tip"/>
        <axis xyz="0 0 0"/>
    </joint>
  </xacro:macro>
</robot>
