<?xml version='1.0' encoding='utf-8'?>
<robot name="RBY1_UB">
  <link name="base">
    <inertial>
      <mass value="1.96845884" />
      <origin rpy="0 0 0" xyz="0.00030850 0.00328099 0.06173915" />
      <inertia ixx="0.01692619" ixy="0.00000207" ixz="0.00002146" iyy="0.00852919" iyz="0.00038087" izz="0.01330217" />
    </inertial>
    <visual>
      <geometry>
        <mesh filename="package://rby1_mujoco_description/meshes/rby1ub/UB_LINK_BASE.dae" />
      </geometry>
    </visual>
  </link>
  <link name="link_torso_hp">
    <inertial>
      <mass value="8.52506911" />
      <origin rpy="0 0 0" xyz="-0.00286246 -0.01952257 0.02364760" />
      <inertia ixx="0.03842169" ixy="0.00047168" ixz="0.00215015" iyy="0.03948014" iyz="-0.00377178" izz="0.02710491" />
    </inertial>
    <visual>
      <geometry>
        <mesh filename="package://rby1_mujoco_description/meshes/rby1ub/UB_LINK_HP.dae" />
      </geometry>
    </visual>
    <collision>
      <origin xyz="-0.070000 0 0.038500" rpy="0 1.5708 0" />
      <geometry>
        <cylinder radius="0.105" length="0.2" />
      </geometry>
    </collision>
  </link>
  <link name="link_torso_5">
    <inertial>
      <mass value="12.59012341" />
      <origin rpy="0 0 0" xyz="-0.01338376 0.00025621 -0.03272487" />
      <inertia ixx="0.21375525" ixy="0.00051520" ixz="0.00880124" iyy="0.16562090" iyz="-0.00023995" izz="0.13308879" />
    </inertial>
    <visual>
      <geometry>
        <mesh filename="package://rby1_mujoco_description/meshes/rby1ub/LINK_6.dae" />
      </geometry>
    </visual>
    <collision>
      <origin xyz="0 0 0.0075" rpy="0 0 0" />
      <geometry>
        <cylinder radius="0.155" length="0.1350" />
      </geometry>
    </collision>
  </link>
  <link name="link_right_arm_0">
    <inertial>
      <mass value="1.26164242" />
      <origin rpy="0 0 0" xyz="-0.00316662 0.03437181 -0.00000030" />
      <inertia ixx="0.00230621" ixy="0.00039024" ixz="-0.00000256" iyy="0.00426418" iyz="0.00000118" izz="0.00432156" />
    </inertial>
    <visual>
      <geometry>
        <mesh filename="package://rby1_mujoco_description/meshes/rby1ub/LINK_7.dae" />
      </geometry>
    </visual>
    <collision>
      <origin xyz="-0.015 0.018 -0.008" rpy="0 1.5708 0" />
      <geometry>
        <cylinder radius="0.075" length="0.0700" />
      </geometry>
    </collision>
  </link>
  <link name="link_right_arm_1">
    <inertial>
      <mass value="2.27287031" />
      <origin rpy="0 0 0" xyz="-0.00307855 -0.00124741 -0.01294324" />
      <inertia ixx="0.00388490" ixy="-0.00001477" ixz="0.00011465" iyy="0.00447034" iyz="-0.00010023" izz="0.00288341" />
    </inertial>
    <visual>
      <geometry>
        <mesh filename="package://rby1_mujoco_description/meshes/rby1ub/LINK_8.dae" />
      </geometry>
    </visual>
    <collision>
      <origin xyz="0 0 -0.1000" rpy="0 0 0" />
      <geometry>
        <cylinder radius="0.05" length="0.2" />
      </geometry>
    </collision>
  </link>
  <link name="link_right_arm_2">
    <inertial>
      <mass value="2.46909439" />
      <origin rpy="0 0 0" xyz="0.00115434 -0.00196635 -0.16192524" />
      <inertia ixx="0.00980269" ixy="0.00005871" ixz="0.00051888" iyy="0.00924560" iyz="-0.00045932" izz="0.00329867" />
    </inertial>
    <visual>
      <geometry>
        <mesh filename="package://rby1_mujoco_description/meshes/rby1ub/LINK_9.dae" />
      </geometry>
    </visual>
    <collision>
      <origin xyz="0.0260 0 -0.2760" rpy="1.5708 0 0" />
      <geometry>
        <cylinder radius="0.05" length="0.080000" />
      </geometry>
    </collision>
  </link>
  <link name="link_right_arm_3">
    <inertial>
      <mass value="2.26099493" />
      <origin rpy="0 0 0" xyz="-0.01603135 -0.00692891 -0.04549811" />
      <inertia ixx="0.00822606" ixy="0.00027620" ixz="-0.00156570" iyy="0.00844870" iyz="0.00076157" izz="0.00236614" />
    </inertial>
    <visual>
      <geometry>
        <mesh filename="package://rby1_mujoco_description/meshes/rby1ub/LINK_10.dae" />
      </geometry>
    </visual>
    <collision>
      <origin xyz="-0.0310 0 -0.1075" rpy="0 0 0" />
      <geometry>
        <cylinder radius="0.04" length="0.1150" />
      </geometry>
    </collision>
  </link>
  <link name="link_right_arm_4">
    <inertial>
      <mass value="0.42508710" />
      <origin rpy="0 0 0" xyz="-0.00000011 -0.02696036 0.06182110" />
      <inertia ixx="0.00082466" ixy="0.0" ixz="0.0" iyy="0.00075398" iyz="-0.00025338" izz="0.00039794" />
    </inertial>
    <visual>
      <geometry>
        <mesh filename="package://rby1_mujoco_description/meshes/rby1ub/LINK_11.dae" />
      </geometry>
    </visual>
    <collision>
      <origin xyz="0 -0.038 0.0175" rpy="0 0 0" />
      <geometry>
        <cylinder radius="0.035" length="0.095" />
      </geometry>
    </collision>
  </link>
  <link name="link_right_arm_5">
    <inertial>
      <mass value="1.59194395" />
      <origin rpy="0 0 0" xyz="0.00318034 -0.00532264 -0.02809655" />
      <inertia ixx="0.00256054" ixy="-0.00002344" ixz="-0.00001563" iyy="0.00257233" iyz="0.00021608" izz="0.00156092" />
    </inertial>
    <visual>
      <geometry>
        <mesh filename="package://rby1_mujoco_description/meshes/rby1ub/LINK_12.dae" />
      </geometry>
    </visual>
    <collision>
      <origin xyz="0 0 -0.1" rpy="0 0 0" />
      <geometry>
        <cylinder radius="0.075" length="0.25" />
      </geometry>
    </collision>
  </link>
  <link name="link_right_arm_6">
    <inertial>
      <mass value="0.21137279" />
      <origin rpy="0 0 0" xyz="0.00066810 -0.00031708 -0.09636043" />
      <inertia ixx="0.00013511" ixy="-0.00000242" ixz="-0.00000102" iyy="0.00014453" iyz="0.00000094" izz="0.00025431" />
    </inertial>
    <visual>
      <geometry>
        <mesh filename="package://rby1_mujoco_description/meshes/rby1ub/LINK_13.dae" />
      </geometry>
    </visual>
  </link>
  <link name="link_left_arm_0">
    <inertial>
      <mass value="1.26164242" />
      <origin rpy="0 0 0" xyz="-0.00316662 -0.03437151 0.00000242" />
      <inertia ixx="0.00230624" ixy="-0.00039022" ixz="0.00000269" iyy="0.00426418" iyz="0.00000108" izz="0.00432159" />
    </inertial>
    <visual>
      <geometry>
        <mesh filename="package://rby1_mujoco_description/meshes/rby1ub/LINK_14.dae" />
      </geometry>
    </visual>
    <collision>
      <origin xyz="-0.015 -0.018 -0.008" rpy="0 1.5708 0" />
      <geometry>
        <cylinder radius="0.075" length="0.0700" />
      </geometry>
    </collision>
  </link>
  <link name="link_left_arm_1">
    <inertial>
      <mass value="1.88138658" />
      <origin rpy="0 0 0" xyz="-0.00183470 0.00040596 -0.01008733" />
      <inertia ixx="0.00295838" ixy="-0.00001176" ixz="0.00006949" iyy="0.00355208" iyz="0.00004467" izz="0.00230558" />
    </inertial>
    <visual>
      <geometry>
        <mesh filename="package://rby1_mujoco_description/meshes/rby1ub/LINK_15.dae" />
      </geometry>
    </visual>
    <collision>
      <origin xyz="0 0 -0.1000" rpy="0 0 0" />
      <geometry>
        <cylinder radius="0.050" length="0.2000" />
      </geometry>
    </collision>
  </link>
  <link name="link_left_arm_2">
    <inertial>
      <mass value="2.35634437" />
      <origin rpy="0 0 0" xyz="0.00066086 -0.00038583 -0.15742972" />
      <inertia ixx="0.00842712" ixy="0.00000247" ixz="0.00036948" iyy="0.00802311" iyz="-0.00006550" izz="0.00295678" />
    </inertial>
    <visual>
      <geometry>
        <mesh filename="package://rby1_mujoco_description/meshes/rby1ub/LINK_16.dae" />
      </geometry>
    </visual>
    <collision>
      <origin xyz="0.0260 0 -0.2760" rpy="1.5708 0 0" />
      <geometry>
        <cylinder radius="0.05" length="0.080000" />
      </geometry>
    </collision>
  </link>
  <link name="link_left_arm_3">
    <inertial>
      <mass value="2.00905891" />
      <origin rpy="0 0 0" xyz="-0.01565298 0.00793126 -0.04997943" />
      <inertia ixx="0.00756474" ixy="-0.00026771" ixz="-0.00155419" iyy="0.00772758" iyz="-0.00084364" izz="0.00199754" />
    </inertial>
    <visual>
      <geometry>
        <mesh filename="package://rby1_mujoco_description/meshes/rby1ub/LINK_17.dae" />
      </geometry>
    </visual>
    <collision>
      <origin xyz="-0.0310 0 -0.1075" rpy="0 0 0" />
      <geometry>
        <cylinder radius="0.04" length="0.1150" />
      </geometry>
    </collision>
  </link>
  <link name="link_left_arm_4">
    <inertial>
      <mass value="0.42508710" />
      <origin rpy="0 0 0" xyz="0.00000011 0.02696036 0.06182110" />
      <inertia ixx="0.00082466" ixy="0.0" ixz="0.0" iyy="0.00075398" iyz="0.00025338" izz="0.00039794" />
    </inertial>
    <visual>
      <geometry>
        <mesh filename="package://rby1_mujoco_description/meshes/rby1ub/LINK_18.dae" />
      </geometry>
    </visual>
    <collision>
      <origin xyz="0 0.038000 0.017500" rpy="0 0 0" />
      <geometry>
        <cylinder radius="0.035" length="0.095000" />
      </geometry>
    </collision>
  </link>
  <link name="link_left_arm_5">
    <inertial>
      <mass value="1.44264795" />
      <origin rpy="0 0 0" xyz="0.00340082 0.00576824 -0.02507309" />
      <inertia ixx="0.00233577" ixy="0.00003048" ixz="-0.00001191" iyy="0.00232580" iyz="-0.00019491" izz="0.00138375" />
    </inertial>
    <visual>
      <geometry>
        <mesh filename="package://rby1_mujoco_description/meshes/rby1ub/LINK_19.dae" />
      </geometry>
    </visual>
    <collision>
      <origin xyz="0 0 -0.1" rpy="0 0 0" />
      <geometry>
        <cylinder radius="0.075" length="0.25" />
      </geometry>
    </collision>
  </link>
  <link name="link_left_arm_6">
    <inertial>
      <mass value="0.21137279" />
      <origin rpy="0 0 0" xyz="-0.00066810 0.00031708 -0.09636043" />
      <inertia ixx="0.00013511" ixy="-0.00000242" ixz="0.00000102" iyy="0.00014453" iyz="-0.00000094" izz="0.00025431" />
    </inertial>
    <visual>
      <geometry>
        <mesh filename="package://rby1_mujoco_description/meshes/rby1ub/LINK_20.dae" />
      </geometry>
    </visual>
  </link>
  <link name="FT_sensor_R">
    <inertial>
      <mass value="0.49078507" />
      <origin rpy="0 0 0" xyz="0.00010423 0.00108019 -0.01880676" />
      <inertia ixx="0.00028587" ixy="-0.00000146" ixz="-0.00000026" iyy="0.00030459" iyz="-0.00000772" izz="0.00036377" />
    </inertial>
    <visual>
      <geometry>
        <mesh filename="package://rby1_mujoco_description/meshes/rby1ub/FT_SENSOR_R.dae" />
      </geometry>
    </visual>
  </link>
  <link name="FT_sensor_L">
    <inertial>
      <mass value="0.49078507" />
      <origin rpy="0 0 0" xyz="-0.00010423 -0.00108019 -0.01880676" />
      <inertia ixx="0.00028587" ixy="-0.00000146" ixz="0.00000026" iyy="0.00030459" iyz="0.00000772" izz="0.00036377" />
    </inertial>
    <visual>
      <geometry>
        <mesh filename="package://rby1_mujoco_description/meshes/rby1ub/FT_SENSOR_L.dae" />
      </geometry>
    </visual>
  </link>
  <link name="ee_right">
    <inertial>
      <mass value="0.46704998" />
      <origin rpy="0 0 0" xyz="0.00212703 0.00000615 -0.04287176" />
      <inertia ixx="0.00032067" ixy="0.00002383" ixz="-0.00000785" iyy="0.00059559" iyz="-0.00000007" izz="0.00052732" />
    </inertial>
    <visual>
      <geometry>
        <mesh filename="package://rby1_mujoco_description/meshes/rby1ub/EE_BODY.dae" />
      </geometry>
    </visual>
  </link>
  <link name="ee_finger_r1">
    <inertial>
      <mass value="0.03326999" />
      <origin rpy="0 0 0" xyz="0.00278346 -0.00000329 -0.02570112" />
      <inertia ixx="0.00001231" ixy="0.0" ixz="-0.00000042" iyy="0.00001066" iyz="0.0" izz="0.00000224" />
    </inertial>
    <visual>
      <geometry>
        <mesh filename="package://rby1_mujoco_description/meshes/rby1ub/EE_FINGER.dae" />
      </geometry>
    </visual>
  </link>
  <link name="ee_finger_r2">
    <inertial>
      <mass value="0.03326999" />
      <origin rpy="0 0 0" xyz="0.00278346 -0.00000329 -0.02570112" />
      <inertia ixx="0.00001231" ixy="0.0" ixz="-0.00000042" iyy="0.00001066" iyz="0.0" izz="0.00000224" />
    </inertial>
    <visual>
      <geometry>
        <mesh filename="package://rby1_mujoco_description/meshes/rby1ub/EE_FINGER.dae" />
      </geometry>
    </visual>
  </link>
  <link name="ee_left">
    <inertial>
      <mass value="0.46704998" />
      <origin rpy="0 0 0" xyz="0.00212703 0.00000615 -0.04287176" />
      <inertia ixx="0.00032067" ixy="0.00002383" ixz="-0.00000785" iyy="0.00059559" iyz="-0.00000007" izz="0.00052732" />
    </inertial>
    <visual>
      <geometry>
        <mesh filename="package://rby1_mujoco_description/meshes/rby1ub/EE_BODY.dae" />
      </geometry>
    </visual>
  </link>
  <link name="ee_finger_l1">
    <inertial>
      <mass value="0.03326999" />
      <origin rpy="0 0 0" xyz="0.00278346 -0.00000329 -0.02570112" />
      <inertia ixx="0.00001231" ixy="0.0" ixz="-0.00000042" iyy="0.00001066" iyz="0.0" izz="0.00000224" />
    </inertial>
    <visual>
      <geometry>
        <mesh filename="package://rby1_mujoco_description/meshes/rby1ub/EE_FINGER.dae" />
      </geometry>
    </visual>
  </link>
  <link name="ee_finger_l2">
    <inertial>
      <mass value="0.03326999" />
      <origin rpy="0 0 0" xyz="0.00278346 -0.00000329 -0.02570112" />
      <inertia ixx="0.00001231" ixy="0.0" ixz="-0.00000042" iyy="0.00001066" iyz="0.0" izz="0.00000224" />
    </inertial>
    <visual>
      <geometry>
        <mesh filename="package://rby1_mujoco_description/meshes/rby1ub/EE_FINGER.dae" />
      </geometry>
    </visual>
  </link>
  <link name="link_head_0">
    <inertial>
      <mass value="0.07582110" />
      <origin rpy="0 0 0" xyz="-0.00800549 0.0 -0.01100308" />
      <inertia ixx="0.00003307" ixy="0.0" ixz="-0.00000290" iyy="0.00002209" iyz="0.0" izz="0.00003796" />
    </inertial>
    <visual>
      <geometry>
        <mesh filename="package://rby1_mujoco_description/meshes/rby1ub/PAN_TILT_1.dae" />
      </geometry>
    </visual>
  </link>
  <link name="link_head_1">
    <inertial>
      <mass value="0.07450580" />
      <origin rpy="0 0 0" xyz="-0.01150679 -0.00114270 -0.00031579" />
      <inertia ixx="0.00001850" ixy="-0.00000035" ixz="0.00000203" iyy="0.00002451" iyz="-0.00000010" izz="0.00002062" />
    </inertial>
    <visual>
      <geometry>
        <mesh filename="package://rby1_mujoco_description/meshes/rby1ub/PAN_TILT_2.dae" />
      </geometry>
    </visual>
  </link>
  <link name="link_head_2">
    <inertial>
      <mass value="0.03585374" />
      <origin rpy="0 0 0" xyz="-0.00081966 0.00099024 0.02283704" />
      <inertia ixx="0.00002046" ixy="0.00000001" ixz="-0.00000027" iyy="0.00001044" iyz="0.00000076" izz="0.00001291" />
    </inertial>
    <visual>
      <geometry>
        <mesh filename="package://rby1_mujoco_description/meshes/rby1ub/PAN_TILT_3.dae" />
      </geometry>
    </visual>
  </link>
  <joint name="torso_hp" type="revolute">
    <parent link="base" />
    <child link="link_torso_hp" />
    <origin rpy="0.0 0.0 0.0" xyz="0.0 0.0 0.153" />
    <axis xyz="0 1 0" />
    <limit effort="250.0" acceleration="5.0" velocity="2.09439510" lower="-1.570796327" upper="1.570796327" />
  </joint>
  <joint name="torso_5" type="revolute">
    <parent link="link_torso_hp" />
    <child link="link_torso_5" />
    <origin rpy="0.0 0.0 0.0" xyz="0.0 0.0 0.332326548" />
    <axis xyz="0 0 1" />
    <limit effort="120.0" acceleration="5.0" velocity="3.141592654" lower="-2.35619449" upper="2.35619449" />
  </joint>
  <joint name="right_arm_0" type="revolute">
    <parent link="link_torso_5" />
    <child link="link_right_arm_0" />
    <origin rpy="0.0 0.0 0.0" xyz="0.0 -0.220 0.080073451539 " />
    <axis xyz="0.0 0.93969262 -0.34202014" />
    <limit effort="70.0" acceleration="10.0" velocity="3.141592654" lower="-3.141592654" upper="3.141592654" />
  </joint>
  <joint name="right_arm_1" type="revolute">
    <parent link="link_right_arm_0" />
    <child link="link_right_arm_1" />
    <origin rpy="0.0 0.0 0.0" xyz="0.0 0.0 0.0" />
    <axis xyz="1 0 0" />
    <limit effort="70.0" acceleration="10.0" velocity="3.141592654" lower="-3.141592654" upper="0.017453293" />
  </joint>
  <joint name="right_arm_2" type="revolute">
    <parent link="link_right_arm_1" />
    <child link="link_right_arm_2" />
    <origin rpy="0.0 0.0 0.0" xyz="0.0 0.0 0.0" />
    <axis xyz="0 0 1" />
    <limit effort="70.0" acceleration="10.0" velocity="3.141592654" lower="-3.141592654" upper="3.141592654" />
  </joint>
  <joint name="right_arm_3" type="revolute">
    <parent link="link_right_arm_2" />
    <child link="link_right_arm_3" />
    <origin rpy="0.0 0.0 0.0" xyz="0.031 0.0 -0.276" />
    <axis xyz="0 1 0" />
    <limit effort="40.0" acceleration="10.0" velocity="3.141592654" lower="-2.617993878" upper="0.017453293" />
  </joint>
  <joint name="right_arm_4" type="revolute">
    <parent link="link_right_arm_3" />
    <child link="link_right_arm_4" />
    <origin rpy="0.0 0.0 0.0" xyz="-0.031 0.0 -0.256" />
    <axis xyz="0 0 1" />
    <limit effort="10.0" acceleration="10.0" velocity="6.283185308" lower="-3.141592654" upper="3.141592654" />
  </joint>
  <joint name="right_arm_5" type="revolute">
    <parent link="link_right_arm_4" />
    <child link="link_right_arm_5" />
    <origin rpy="0.0 0.0 0.0" xyz="0.0 0.0 0.0" />
    <axis xyz="0 1 0" />
    <limit effort="10.0" acceleration="10.0" velocity="6.283185308" lower="-1.570796327" upper="1.919862177" />
  </joint>
  <joint name="right_arm_6" type="revolute">
    <parent link="link_right_arm_5" />
    <child link="link_right_arm_6" />
    <origin rpy="0.0 0.0 0.0" xyz="0.0 0.0 0.0" />
    <axis xyz="0 0 1" />
    <limit effort="8.0" acceleration="10.0" velocity="2.094395102" lower="-2.705260340" upper="2.705260340" />
  </joint>
  <joint name="left_arm_0" type="revolute">
    <parent link="link_torso_5" />
    <child link="link_left_arm_0" />
    <origin rpy="0.0 0.0 0.0" xyz="0.0 0.220 0.080073452 " />
    <axis xyz="0.0 0.93969262 0.34202014" />
    <limit effort="70.0" acceleration="10.0" velocity="3.141592654" lower="-3.141592654" upper="3.141592654" />
  </joint>
  <joint name="left_arm_1" type="revolute">
    <parent link="link_left_arm_0" />
    <child link="link_left_arm_1" />
    <origin rpy="0.0 0.0 0.0" xyz="0.0 0.0 0.0" />
    <axis xyz="1 0 0" />
    <limit effort="70.0" acceleration="10.0" velocity="3.141592654" lower="-0.017453293" upper="3.141592654" />
  </joint>
  <joint name="left_arm_2" type="revolute">
    <parent link="link_left_arm_1" />
    <child link="link_left_arm_2" />
    <origin rpy="0.0 0.0 0.0" xyz="0.0 0.0 0.0" />
    <axis xyz="0 0 1" />
    <limit effort="70.0" acceleration="10.0" velocity="3.141592654" lower="-3.141592654" upper="3.141592654" />
  </joint>
  <joint name="left_arm_3" type="revolute">
    <parent link="link_left_arm_2" />
    <child link="link_left_arm_3" />
    <origin rpy="0.0 0.0 0.0" xyz="0.031 0.0 -0.276" />
    <axis xyz="0 1 0" />
    <limit effort="40.0" acceleration="10.0" velocity="3.141592654" lower="-2.617993878" upper="0.017453293" />
  </joint>
  <joint name="left_arm_4" type="revolute">
    <parent link="link_left_arm_3" />
    <child link="link_left_arm_4" />
    <origin rpy="0.0 0.0 0.0" xyz="-0.031 0.0 -0.256" />
    <axis xyz="0 0 1" />
    <limit effort="10.0" acceleration="10.0" velocity="6.283185308" lower="-3.141592654" upper="3.141592654" />
  </joint>
  <joint name="left_arm_5" type="revolute">
    <parent link="link_left_arm_4" />
    <child link="link_left_arm_5" />
    <origin rpy="0.0 0.0 0.0" xyz="0.0 0.0 0.0" />
    <axis xyz="0 1 0" />
    <limit effort="10.0" acceleration="10.0" velocity="6.283185308" lower="-1.570796327" upper="1.919862177" />
  </joint>
  <joint name="left_arm_6" type="revolute">
    <parent link="link_left_arm_5" />
    <child link="link_left_arm_6" />
    <origin rpy="0.0 0.0 0.0" xyz="0.0 0.0 0.0" />
    <axis xyz="0 0 1" />
    <limit effort="8.0" acceleration="10.0" velocity="2.094395102" lower="-2.705260340" upper="2.705260340" />
  </joint>
  <joint name="tool_right" type="fixed">
    <parent link="link_right_arm_6" />
    <child link="FT_sensor_R" />
    <origin rpy="0.0 0.0 0.0" xyz="0.0 0.0 -0.1087" />
    <axis xyz="0 0 1" />
  </joint>
  <joint name="FT_Sensor_END_right" type="fixed">
    <parent link="FT_sensor_R" />
    <child link="ee_right" />
    <origin rpy="0.0 0.0 0.0" xyz="0.0 0.0 -0.0461" />
    <axis xyz="0 0 1" />
  </joint>
  <joint name="gripper_finger_r1" type="prismatic" in_model_type="fixed">
    <parent link="ee_right" />
    <child link="ee_finger_r1" />
    <origin rpy="0.0 0.0 0.0" xyz="0.003 0.0 -0.073" />
    <axis xyz="-1 0 0" />
    <limit effort="1000" velocity="0.05" lower="-0.05" upper="0" />
  </joint>
  <joint name="gripper_finger_r2" type="prismatic" in_model_type="fixed">
    <parent link="ee_right" />
    <child link="ee_finger_r2" />
    <origin rpy="0.0 0.0 3.1415926535" xyz="-0.003 0.0 -0.073" />
    <axis xyz="1 0 0" />
    <limit effort="1000" velocity="0.05" lower="0" upper="0.05" />
  </joint>
  <joint name="tool_left" type="fixed">
    <parent link="link_left_arm_6" />
    <child link="FT_sensor_L" />
    <origin rpy="0.0 0.0 0" xyz="0.0 0.0 -0.1087" />
    <axis xyz="0 0 1" />
  </joint>
  <joint name="FT_Sensor_END_left" type="fixed">
    <parent link="FT_sensor_L" />
    <child link="ee_left" />
    <origin rpy="0.0 0.0 0.0" xyz="0.0 0.0 -0.0461" />
    <axis xyz="0 0 1" />
  </joint>
  <joint name="gripper_finger_l1" type="prismatic" in_model_type="fixed">
    <parent link="ee_left" />
    <child link="ee_finger_l1" />
    <origin rpy="0.0 0.0 0.0" xyz="0.003 0.0 -0.073" />
    <axis xyz="-1 0 0" />
    <limit effort="1000" velocity="0.05" lower="-0.05" upper="0" />
  </joint>
  <joint name="gripper_finger_l2" type="prismatic" in_model_type="fixed">
    <parent link="ee_left" />
    <child link="ee_finger_l2" />
    <origin rpy="0.0 0.0 3.1415926535" xyz="-0.003 0.0 -0.073" />
    <axis xyz="1 0 0" />
    <limit effort="1000" velocity="0.05" lower="0" upper="0.05" />
  </joint>
  <joint name="head_base" type="fixed">
    <parent link="link_torso_5" />
    <child link="link_head_0" />
    <origin rpy="0.0 0.0 0.0" xyz="0.022 0.0 0.120073451525" />
    <axis xyz="0 0 1" />
  </joint>
  <joint name="head_0" type="revolute">
    <parent link="link_head_0" />
    <child link="link_head_1" />
    <origin rpy="0.0 0.0 0.0" xyz="0.0 0.0 0.02" />
    <axis xyz="0 0 1" />
    <limit effort="1000" velocity="3.14" lower="-0.523" upper="0.523" />
  </joint>
  <joint name="head_1" type="revolute">
    <parent link="link_head_1" />
    <child link="link_head_2" />
    <origin rpy="0.0 0.0 0.0" xyz="0.0 0.0 0.0" />
    <axis xyz="0 1 0" />
    <limit effort="1000" velocity="3.14" lower="-0.35" upper="1.57" />
  </joint>
</robot>